Workbook
Name ANNI: COPIA!$AN$1:$AN$2
Name AVERE: COPIA!$BE$3:$BE$500
Name avere_grezzo: COPIA!$FC$3:$FC$400
Name CLASSIFICAZIONE: COPIA!$AD$3:$AD$230
Name CODICE: COPIA!$Z$3:$Z$230
Name conti_aperti: OFFSET(COPIA!$CV$2,,,COPIA!$CX$2+1,)
Name DARE: COPIA!$BD$3:$BD$500
Name dare_grezzo: COPIA!$FB$3:$FB$400
Name DATA: COPIA!$BA$3:$BA$500
Name data_grezzo: COPIA!$EY$3:$EY$400
Name den_grezzo: COPIA!$EZ$3:$EZ$400
Name DENOMINAZIONE: COPIA!$AA$3:$AA$230
Name DENOMINAZIONE_GIORNALE: COPIA!$BB$3:$BB$500
Name DESCRIZIONE: COPIA!$BC$3:$BC$500
Name DESTINAZIONE: COPIA!$AE$3:$AE$230
Name ECCEDENZA: COPIA!$AC$3:$AC$230
Name elenco_aperti: OFFSET(COPIA!$CV$2,,,COPIA!$CX$2+1,)
Name FILTRO_CELLA: COPIA!$EP$1:$EP$2
Name FINE_A_PC: COPIA!$EX$2
Name FINE_AC: COPIA!$FC$1
Name GIORNALE: COPIA!$AZ$3:$BE$500
Name giornale_grezzo: COPIA!$EY$3:$FC$400
Name GIORNI: COPIA!$J$4:$J$34
Name INIZIO_A_PC: COPIA!$EY$2
Name INIZIO_AC: COPIA!$FC$2
Name LIBRO_GIORNALE: COPIA!$AZ$3:$BF$500
Name MENU__TENDINA: OFFSET(COPIA!$DI$3,,,COPIA!$DH$1)
Name MENU_TENDINA: OFFSET(COPIA!$M$3,,,COPIA!$P$1)
Name MESI: COPIA!$J$4:$J$15
Name nascondi_righe: COPIA!$EX$102:$EX$400
Name NATURA: COPIA!$AB$3:$AB$230
Name Num._riga: COPIA!$AZ$3:$AZ$500
Name office365: COPIA!$K$3:$K$250
Name PIANO_DEI_CONTI: COPIA!$Z$3:$AI$230
Name PROGRESSIVO: COPIA!$EL$3:$EL$500
Name RAGRUPPAMENTO: COPIA!$AF$3:$AF$230
Name rettifiche: OFFSET(COPIA!$IR$3,,,COPIA!$IQ$1,1)
Name RIGHE_PROSPETTI: COPIA!$JM$3:$JM$33
Name saldi: OFFSET(COPIA!$GW$3,,,COPIA!$GW$1,1)
Name VALORI_INIZIALI: VALORI_INIZIALI!$B$8:$I$75

Sheet PIANO_DEI_CONTI
A1: PIANO DEI CONTI
A2: Inserire una X per filtrare i conti in relazione al livello di svolgimento del programma | F2: LIVELLO DI PROGRESSIONE DEL PROGRAMMA | I2: RINOMINARE I CONTI
F3: C - SCRITTURE DI ASSESTAMENTO | I3: 1.BANCA X C/C - 2.BANCA Y C/C - 3. CEDENTE C/CESSIONE
A5: QUADRO DEI CONTI DI UN'IMPRESA INDIVIDUALE - DAL FASCICOLO ALLEGATO AL LIBRO DI TESTO FUTURO IMPRESA SMART 3 - TE213FA - TRAMONTANA
A6: Assegnazione dei conti alle macroaree | D6: Codice | E6: DENOMINAZIONE DEL CONTO | F6: NATURA | G6: ECCEDENZA | H6: CLASSIFICAZIONE | I6: DESTINAZIONE
A7: A | B7: B | C7: C | D7: =IF(COPIA!A3=0,"",COPIA!A3) -> 01.00 | E7: =IF(COPIA!B3=0,"",COPIA!B3) -> IMMOBILIZZAZIONI IMMATERIALI | F7: =IF(COPIA!C3=0,"",COPIA!C3) | G7: =IF(COPIA!D3=0,"",COPIA!D3) | H7: =IF(COPIA!E3=0,"",IF(COPIA!B3="FONDO SVALUTAZIONE CREDITI","RETTIFICA CREDITI",COPIA!E3)) | I7: =IF(COPIA!F3=0,"",COPIA!F3) | M7: 1
A8: x | B8: x | C8: x | D8: =IF(COPIA!A4=0,"",COPIA!A4) -> 01.01 | E8: =IF(COPIA!B4=0,"",COPIA!B4) -> COSTI DI IMPIANTO | F8: =IF(COPIA!C4=0,"",COPIA!C4) -> E | G8: =IF(COPIA!D4=0,"",COPIA!D4) -> D | H8: =IF(COPIA!E4=0,"",IF(COPIA!B4="FONDO SVALUTAZIONE CREDITI","RETTIFICA CREDITI",COPIA!E4)) -> COSTI PLURIENNALI | I8: =IF(COPIA!F4=0,"",COPIA!F4) -> SP DARE | M8: 2
A9: x | B9: x | C9: x | D9: =IF(COPIA!A5=0,"",COPIA!A5) -> 01.03 | E9: =IF(COPIA!B5=0,"",COPIA!B5) -> BREVETTI | F9: =IF(COPIA!C5=0,"",COPIA!C5) -> E | G9: =IF(COPIA!D5=0,"",COPIA!D5) -> D | H9: =IF(COPIA!E5=0,"",IF(COPIA!B5="FONDO SVALUTAZIONE CREDITI","RETTIFICA CREDITI",COPIA!E5)) -> COSTI PLURIENNALI | I9: =IF(COPIA!F5=0,"",COPIA!F5) -> SP DARE | M9: 3
A10: x | B10: x | C10: x | D10: =IF(COPIA!A6=0,"",COPIA!A6) -> 01.04 | E10: =IF(COPIA!B6=0,"",COPIA!B6) -> SOFTWARE | F10: =IF(COPIA!C6=0,"",COPIA!C6) -> E | G10: =IF(COPIA!D6=0,"",COPIA!D6) -> D | H10: =IF(COPIA!E6=0,"",IF(COPIA!B6="FONDO SVALUTAZIONE CREDITI","RETTIFICA CREDITI",COPIA!E6)) -> COSTI PLURIENNALI | I10: =IF(COPIA!F6=0,"",COPIA!F6) -> SP DARE
C11: x | D11: =IF(COPIA!A7=0,"",COPIA!A7) -> 01.05 | E11: =IF(COPIA!B7=0,"",COPIA!B7) -> AVVIAMENTO | F11: =IF(COPIA!C7=0,"",COPIA!C7) -> E | G11: =IF(COPIA!D7=0,"",COPIA!D7) -> D | H11: =IF(COPIA!E7=0,"",IF(COPIA!B7="FONDO SVALUTAZIONE CREDITI","RETTIFICA CREDITI",COPIA!E7)) -> COSTI PLURIENNALI | I11: =IF(COPIA!F7=0,"",COPIA!F7) -> SP DARE
C12: x | D12: =IF(COPIA!A8=0,"",COPIA!A8) -> 01.11 | E12: =IF(COPIA!B8=0,"",COPIA!B8) -> FONDO AMMORTAMENTO COSTI DI IMPIANTO | F12: =IF(COPIA!C8=0,"",COPIA!C8) -> E | G12: =IF(COPIA!D8=0,"",COPIA!D8) -> A | H12: =IF(COPIA!E8=0,"",IF(COPIA!B8="FONDO SVALUTAZIONE CREDITI","RETTIFICA CREDITI",COPIA!E8)) -> RETTIFICHE COSTI PLURIENNALI | I12: =IF(COPIA!F8=0,"",COPIA!F8) -> SP AVERE
B13: x | C13: x | D13: =IF(COPIA!A9=0,"",COPIA!A9) -> 01.13 | E13: =IF(COPIA!B9=0,"",COPIA!B9) -> FONDO AMMORTAMENTO BREVETTI | F13: =IF(COPIA!C9=0,"",COPIA!C9) -> E | G13: =IF(COPIA!D9=0,"",COPIA!D9) -> A | H13: =IF(COPIA!E9=0,"",IF(COPIA!B9="FONDO SVALUTAZIONE CREDITI","RETTIFICA CREDITI",COPIA!E9)) -> RETTIFICHE COSTI PLURIENNALI | I13: =IF(COPIA!F9=0,"",COPIA!F9) -> SP AVERE
B14: x | C14: x | D14: =IF(COPIA!A10=0,"",COPIA!A10) -> 01.14 | E14: =IF(COPIA!B10=0,"",COPIA!B10) -> FONDO AMMORTAMENTO SOFTWARE | F14: =IF(COPIA!C10=0,"",COPIA!C10) -> E | G14: =IF(COPIA!D10=0,"",COPIA!D10) -> A | H14: =IF(COPIA!E10=0,"",IF(COPIA!B10="FONDO SVALUTAZIONE CREDITI","RETTIFICA CREDITI",COPIA!E10)) -> RETTIFICHE COSTI PLURIENNALI | I14: =IF(COPIA!F10=0,"",COPIA!F10) -> SP AVERE
C15: x | D15: =IF(COPIA!A11=0,"",COPIA!A11) -> 01.15 | E15: =IF(COPIA!B11=0,"",COPIA!B11) -> FONDO AMMORTAMENTO AVVIAMENTO | F15: =IF(COPIA!C11=0,"",COPIA!C11) -> E | G15: =IF(COPIA!D11=0,"",COPIA!D11) -> A | H15: =IF(COPIA!E11=0,"",IF(COPIA!B11="FONDO SVALUTAZIONE CREDITI","RETTIFICA CREDITI",COPIA!E11)) -> RETTIFICHE COSTI PLURIENNALI | I15: =IF(COPIA!F11=0,"",COPIA!F11) -> SP AVERE
A16: x | B16: x | C16: x | D16: =IF(COPIA!A12=0,"",COPIA!A12) -> 01.20 | E16: =IF(COPIA!B12=0,"",COPIA!B12) -> FORNITORI IMMOBILIZZ. IMMATERIALI C/ACCONTI | F16: =IF(COPIA!C12=0,"",COPIA!C12) -> F | G16: =IF(COPIA!D12=0,"",COPIA!D12) -> D | H16: =IF(COPIA!E12=0,"",IF(COPIA!B12="FONDO SVALUTAZIONE CREDITI","RETTIFICA CREDITI",COPIA!E12)) -> CREDITI | I16: =IF(COPIA!F12=0,"",COPIA!F12) -> SP DARE
D17: =IF(COPIA!A13=0,"",COPIA!A13) -> 02.00 | E17: =IF(COPIA!B13=0,"",COPIA!B13) -> IMMOBILIZZAZIONI MATERIALI | F17: =IF(COPIA!C13=0,"",COPIA!C13) | G17: =IF(COPIA!D13=0,"",COPIA!D13) | H17: =IF(COPIA!E13=0,"",IF(COPIA!B13="FONDO SVALUTAZIONE CREDITI","RETTIFICA CREDITI",COPIA!E13)) | I17: =IF(COPIA!F13=0,"",COPIA!F13)
A18: x | B18: x | C18: x | D18: =IF(COPIA!A14=0,"",COPIA!A14) -> 02.01 | E18: =IF(COPIA!B14=0,"",COPIA!B14) -> FABBRICATI | F18: =IF(COPIA!C14=0,"",COPIA!C14) -> E | G18: =IF(COPIA!D14=0,"",COPIA!D14) -> D | H18: =IF(COPIA!E14=0,"",IF(COPIA!B14="FONDO SVALUTAZIONE CREDITI","RETTIFICA CREDITI",COPIA!E14)) -> COSTI PLURIENNALI | I18: =IF(COPIA!F14=0,"",COPIA!F14) -> SP DARE
A19: x | B19: x | C19: x | D19: =IF(COPIA!A15=0,"",COPIA!A15) -> 02.02 | E19: =IF(COPIA!B15=0,"",COPIA!B15) -> IMPIANTI E MACCHINARI | F19: =IF(COPIA!C15=0,"",COPIA!C15) -> E | G19: =IF(COPIA!D15=0,"",COPIA!D15) -> D | H19: =IF(COPIA!E15=0,"",IF(COPIA!B15="FONDO SVALUTAZIONE CREDITI","RETTIFICA CREDITI",COPIA!E15)) -> COSTI PLURIENNALI | I19: =IF(COPIA!F15=0,"",COPIA!F15) -> SP DARE
A20: x | B20: x | C20: x | D20: =IF(COPIA!A16=0,"",COPIA!A16) -> 02.04 | E20: =IF(COPIA!B16=0,"",COPIA!B16) -> ATTREZZATURE COMMERCIALI | F20: =IF(COPIA!C16=0,"",COPIA!C16) -> E | G20: =IF(COPIA!D16=0,"",COPIA!D16) -> D | H20: =IF(COPIA!E16=0,"",IF(COPIA!B16="FONDO SVALUTAZIONE CREDITI","RETTIFICA CREDITI",COPIA!E16)) -> COSTI PLURIENNALI | I20: =IF(COPIA!F16=0,"",COPIA!F16) -> SP DARE
A21: x | B21: x | C21: x | D21: =IF(COPIA!A17=0,"",COPIA!A17) -> 02.05 | E21: =IF(COPIA!B17=0,"",COPIA!B17) -> MACCHINE D'UFFICIO | F21: =IF(COPIA!C17=0,"",COPIA!C17) -> E | G21: =IF(COPIA!D17=0,"",COPIA!D17) -> D | H21: =IF(COPIA!E17=0,"",IF(COPIA!B17="FONDO SVALUTAZIONE CREDITI","RETTIFICA CREDITI",COPIA!E17)) -> COSTI PLURIENNALI | I21: =IF(COPIA!F17=0,"",COPIA!F17) -> SP DARE
A22: x | B22: x | C22: x | D22: =IF(COPIA!A18=0,"",COPIA!A18) -> 02.06 | E22: =IF(COPIA!B18=0,"",COPIA!B18) -> ARREDAMENTO | F22: =IF(COPIA!C18=0,"",COPIA!C18) -> E | G22: =IF(COPIA!D18=0,"",COPIA!D18) -> D | H22: =IF(COPIA!E18=0,"",IF(COPIA!B18="FONDO SVALUTAZIONE CREDITI","RETTIFICA CREDITI",COPIA!E18)) -> COSTI PLURIENNALI | I22: =IF(COPIA!F18=0,"",COPIA!F18) -> SP DARE
A23: x | B23: x | C23: x | D23: =IF(COPIA!A19=0,"",COPIA!A19) -> 02.07 | E23: =IF(COPIA!B19=0,"",COPIA!B19) -> AUTOMEZZI | F23: =IF(COPIA!C19=0,"",COPIA!C19) -> E | G23: =IF(COPIA!D19=0,"",COPIA!D19) -> D | H23: =IF(COPIA!E19=0,"",IF(COPIA!B19="FONDO SVALUTAZIONE CREDITI","RETTIFICA CREDITI",COPIA!E19)) -> COSTI PLURIENNALI | I23: =IF(COPIA!F19=0,"",COPIA!F19) -> SP DARE
A24: x | B24: x | C24: x | D24: =IF(COPIA!A20=0,"",COPIA!A20) -> 02.08 | E24: =IF(COPIA!B20=0,"",COPIA!B20) -> IMBALLAGGI DUREVOLI | F24: =IF(COPIA!C20=0,"",COPIA!C20) -> E | G24: =IF(COPIA!D20=0,"",COPIA!D20) -> D | H24: =IF(COPIA!E20=0,"",IF(COPIA!B20="FONDO SVALUTAZIONE CREDITI","RETTIFICA CREDITI",COPIA!E20)) -> COSTI PLURIENNALI | I24: =IF(COPIA!F20=0,"",COPIA!F20) -> SP DARE
B25: x | C25: x | D25: =IF(COPIA!A21=0,"",COPIA!A21) -> 02.11 | E25: =IF(COPIA!B21=0,"",COPIA!B21) -> FONDO AMMORTAMENTO FABBRICATI | F25: =IF(COPIA!C21=0,"",COPIA!C21) -> E | G25: =IF(COPIA!D21=0,"",COPIA!D21) -> A | H25: =IF(COPIA!E21=0,"",IF(COPIA!B21="FONDO SVALUTAZIONE CREDITI","RETTIFICA CREDITI",COPIA!E21)) -> RETTIFICHE COSTI PLURIENNALI | I25: =IF(COPIA!F21=0,"",COPIA!F21) -> SP AVERE
B26: x | C26: x | D26: =IF(COPIA!A22=0,"",COPIA!A22) -> 02.12 | E26: =IF(COPIA!B22=0,"",COPIA!B22) -> FONDO AMMORT. IMPIANTI E MACCHINARI | F26: =IF(COPIA!C22=0,"",COPIA!C22) -> E | G26: =IF(COPIA!D22=0,"",COPIA!D22) -> A | H26: =IF(COPIA!E22=0,"",IF(COPIA!B22="FONDO SVALUTAZIONE CREDITI","RETTIFICA CREDITI",COPIA!E22)) -> RETTIFICHE COSTI PLURIENNALI | I26: =IF(COPIA!F22=0,"",COPIA!F22) -> SP AVERE
B27: x | C27: x | D27: =IF(COPIA!A23=0,"",COPIA!A23) -> 02.14 | E27: =IF(COPIA!B23=0,"",COPIA!B23) -> FONDO AMMORT. ATTREZZATURE COMMERCIALI | F27: =IF(COPIA!C23=0,"",COPIA!C23) -> E | G27: =IF(COPIA!D23=0,"",COPIA!D23) -> A | H27: =IF(COPIA!E23=0,"",IF(COPIA!B23="FONDO SVALUTAZIONE CREDITI","RETTIFICA CREDITI",COPIA!E23)) -> RETTIFICHE COSTI PLURIENNALI | I27: =IF(COPIA!F23=0,"",COPIA!F23) -> SP AVERE
B28: x | C28: x | D28: =IF(COPIA!A24=0,"",COPIA!A24) -> 02.15 | E28: =IF(COPIA!B24=0,"",COPIA!B24) -> FONDO AMMORT. MACCHINE D'UFFICIO | F28: =IF(COPIA!C24=0,"",COPIA!C24) -> E | G28: =IF(COPIA!D24=0,"",COPIA!D24) -> A | H28: =IF(COPIA!E24=0,"",IF(COPIA!B24="FONDO SVALUTAZIONE CREDITI","RETTIFICA CREDITI",COPIA!E24)) -> RETTIFICHE COSTI PLURIENNALI | I28: =IF(COPIA!F24=0,"",COPIA!F24) -> SP AVERE
B29: x | C29: x | D29: =IF(COPIA!A25=0,"",COPIA!A25) -> 02.16 | E29: =IF(COPIA!B25=0,"",COPIA!B25) -> FONDO AMMORT. ARREDAMENTO | F29: =IF(COPIA!C25=0,"",COPIA!C25) -> E | G29: =IF(COPIA!D25=0,"",COPIA!D25) -> A | H29: =IF(COPIA!E25=0,"",IF(COPIA!B25="FONDO SVALUTAZIONE CREDITI","RETTIFICA CREDITI",COPIA!E25)) -> RETTIFICHE COSTI PLURIENNALI | I29: =IF(COPIA!F25=0,"",COPIA!F25) -> SP AVERE
B30: x | C30: x | D30: =IF(COPIA!A26=0,"",COPIA!A26) -> 02.17 | E30: =IF(COPIA!B26=0,"",COPIA!B26) -> FONDO AMMORT. AUTOMEZZI | F30: =IF(COPIA!C26=0,"",COPIA!C26) -> E | G30: =IF(COPIA!D26=0,"",COPIA!D26) -> A | H30: =IF(COPIA!E26=0,"",IF(COPIA!B26="FONDO SVALUTAZIONE CREDITI","RETTIFICA CREDITI",COPIA!E26)) -> RETTIFICHE COSTI PLURIENNALI | I30: =IF(COPIA!F26=0,"",COPIA!F26) -> SP AVERE
B31: x | C31: x | D31: =IF(COPIA!A27=0,"",COPIA!A27) -> 02.18 | E31: =IF(COPIA!B27=0,"",COPIA!B27) -> FONDO AMMORT. IMBALLAGGI DUREVOLI | F31: =IF(COPIA!C27=0,"",COPIA!C27) -> E | G31: =IF(COPIA!D27=0,"",COPIA!D27) -> A | H31: =IF(COPIA!E27=0,"",IF(COPIA!B27="FONDO SVALUTAZIONE CREDITI","RETTIFICA CREDITI",COPIA!E27)) -> RETTIFICHE COSTI PLURIENNALI | I31: =IF(COPIA!F27=0,"",COPIA!F27) -> SP AVERE
A32: x | B32: x | C32: x | D32: =IF(COPIA!A28=0,"",COPIA!A28) -> 02.30 | E32: =IF(COPIA!B28=0,"",COPIA!B28) -> FORNITORI IMMOBILIZZ. MATERIALI C/ACCONTI | F32: =IF(COPIA!C28=0,"",COPIA!C28) -> F | G32: =IF(COPIA!D28=0,"",COPIA!D28) -> D | H32: =IF(COPIA!E28=0,"",IF(COPIA!B28="FONDO SVALUTAZIONE CREDITI","RETTIFICA CREDITI",COPIA!E28)) -> CREDITI | I32: =IF(COPIA!F28=0,"",COPIA!F28) -> SP DARE
D33: =IF(COPIA!A29=0,"",COPIA!A29) -> 03.00 | E33: =IF(COPIA!B29=0,"",COPIA!B29) -> IMMOBILIZZAZIONI FINANZIARIE | F33: =IF(COPIA!C29=0,"",COPIA!C29) | G33: =IF(COPIA!D29=0,"",COPIA!D29) | H33: =IF(COPIA!E29=0,"",IF(COPIA!B29="FONDO SVALUTAZIONE CREDITI","RETTIFICA CREDITI",COPIA!E29)) | I33: =IF(COPIA!F29=0,"",COPIA!F29)
A34: x | B34: x | C34: x | D34: =IF(COPIA!A30=0,"",COPIA!A30) -> 03.01 | E34: =IF(COPIA!B30=0,"",COPIA!B30) -> MUTUI ATTIVI | F34: =IF(COPIA!C30=0,"",COPIA!C30) -> F | G34: =IF(COPIA!D30=0,"",COPIA!D30) -> D | H34: =IF(COPIA!E30=0,"",IF(COPIA!B30="FONDO SVALUTAZIONE CREDITI","RETTIFICA CREDITI",COPIA!E30)) -> CREDITI | I34: =IF(COPIA!F30=0,"",COPIA!F30) -> SP DARE
D35: =IF(COPIA!A31=0,"",COPIA!A31) -> 04.00 | E35: =IF(COPIA!B31=0,"",COPIA!B31) -> RIMANENZE | F35: =IF(COPIA!C31=0,"",COPIA!C31) | G35: =IF(COPIA!D31=0,"",COPIA!D31) | H35: =IF(COPIA!E31=0,"",IF(COPIA!B31="FONDO SVALUTAZIONE CREDITI","RETTIFICA CREDITI",COPIA!E31)) | I35: =IF(COPIA!F31=0,"",COPIA!F31)
A36: x | B36: x | C36: x | D36: =IF(COPIA!A32=0,"",COPIA!A32) -> 04.01 | E36: =IF(COPIA!B32=0,"",COPIA!B32) -> MATERIE DI CONSUMO | F36: =IF(COPIA!C32=0,"",COPIA!C32) -> E | G36: =IF(COPIA!D32=0,"",COPIA!D32) -> D | H36: =IF(COPIA!E32=0,"",IF(COPIA!B32="FONDO SVALUTAZIONE CREDITI","RETTIFICA CREDITI",COPIA!E32)) -> COSTI SOSPESI | I36: =IF(COPIA!F32=0,"",COPIA!F32) -> SP DARE
A37: x | B37: x | C37: x | D37: =IF(COPIA!A33=0,"",COPIA!A33) -> 04.04 | E37: =IF(COPIA!B33=0,"",COPIA!B33) -> MERCI | F37: =IF(COPIA!C33=0,"",COPIA!C33) -> E | G37: =IF(COPIA!D33=0,"",COPIA!D33) -> D | H37: =IF(COPIA!E33=0,"",IF(COPIA!B33="FONDO SVALUTAZIONE CREDITI","RETTIFICA CREDITI",COPIA!E33)) -> COSTI SOSPESI | I37: =IF(COPIA!F33=0,"",COPIA!F33) -> SP DARE
A38: x | B38: x | C38: x | D38: =IF(COPIA!A34=0,"",COPIA!A34) -> 04.10 | E38: =IF(COPIA!B34=0,"",COPIA!B34) -> FORNITORI C/ACCONTI | F38: =IF(COPIA!C34=0,"",COPIA!C34) -> F | G38: =IF(COPIA!D34=0,"",COPIA!D34) -> D | H38: =IF(COPIA!E34=0,"",IF(COPIA!B34="FONDO SVALUTAZIONE CREDITI","RETTIFICA CREDITI",COPIA!E34)) -> CREDITI | I38: =IF(COPIA!F34=0,"",COPIA!F34) -> SP DARE
D39: =IF(COPIA!A35=0,"",COPIA!A35) -> 05.00 | E39: =IF(COPIA!B35=0,"",COPIA!B35) -> CREDITI COMMERCIALI | F39: =IF(COPIA!C35=0,"",COPIA!C35) | G39: =IF(COPIA!D35=0,"",COPIA!D35) | H39: =IF(COPIA!E35=0,"",IF(COPIA!B35="FONDO SVALUTAZIONE CREDITI","RETTIFICA CREDITI",COPIA!E35)) | I39: =IF(COPIA!F35=0,"",COPIA!F35)
A40: x | B40: x | C40: x | D40: =IF(COPIA!A36=0,"",COPIA!A36) -> 05.01 | E40: =IF(COPIA!B36=0,"",COPIA!B36) -> CREDITI V/CLIENTI | F40: =IF(COPIA!C36=0,"",COPIA!C36) -> F | G40: =IF(COPIA!D36=0,"",COPIA!D36) -> D | H40: =IF(COPIA!E36=0,"",IF(COPIA!B36="FONDO SVALUTAZIONE CREDITI","RETTIFICA CREDITI",COPIA!E36)) -> CREDITI | I40: =IF(COPIA!F36=0,"",COPIA!F36) -> SP DARE
C41: x | D41: =IF(COPIA!A37=0,"",COPIA!A37) -> 05.02 | E41: =IF(COPIA!B37=0,"",COPIA!B37) -> FATTURE DA EMETTERE | F41: =IF(COPIA!C37=0,"",COPIA!C37) -> F | G41: =IF(COPIA!D37=0,"",COPIA!D37) -> D | H41: =IF(COPIA!E37=0,"",IF(COPIA!B37="FONDO SVALUTAZIONE CREDITI","RETTIFICA CREDITI",COPIA!E37)) -> CREDITI | I41: =IF(COPIA!F37=0,"",COPIA!F37) -> SP DARE
...

Sheet LIBRO_GIORNALE
B1: LIBRO GIORNALE
B2: SCEGLI VERSIONE | E2: CONTI SUDDIVISI PER RAGGRUPPAMENTO | F2: =IF(COPIA!CH1=0,"",CONCATENATE("Articoli registrati: ",COUNTIFS(K11:K308,"="&0))) | G2: TOT. DARE | H2: TOT. AVERE
A3: =IF(INDIRECT(ADDRESS(3,2,,,))="Cloud: Office 365",2,1) -> 1 | B3: Desktop: Office | E3: =IF(A3=2,"VERSIONE OFFICE 365","") | F3: =COPIA!JM1 | G3: =$L$4 -> esercizio n
B4: Periodo di riferimento dei prospetti | F4: =I4 | G4: =IFERROR(ROUND(SUMIFS(COPIA!$FB$103:$FB$400,COPIA!$EW$103:$EW$400,1,COPIA!$EY$103:$EY$400,">="&INIZIO_AC,COPIA!$EY$103:$EY$400,"<="&FINE_AC),2),0) -> 0 | H4: =IFERROR(ROUND(SUMIFS(COPIA!$FC$103:$FC$400,COPIA!$EW$103:$EW$400,1,COPIA!$EY$103:$EY$400,">="&INIZIO_AC,COPIA!$EY$103:$EY$400,"<="&FINE_AC),2),0) -> 0 | I4: =IF(VALORI_INIZIALI!H3<>VALORI_INIZIALI!I3,"I valori iniziali non bilanciano.",IF(AND(VALORI_INIZIALI!H3=VALORI_INIZIALI!I3,VALORI_INIZIALI!H3>0,VALORI_INIZIALI!I3>0),"Sono presenti valori iniziali.","")) | J4: =COPIA!CW1 -> 2026 | K4: =J4+1 -> 2027 | L4: =CONCATENATE("esercizio ",COPIA!EW1) -> esercizio n | P4: =INDEX($L$11:$M$308,MATCH(MAX($L$11:$L$308),$L$11:$L$308,0),2) -> 0
B6: 31 | C6: 12 | D6: N | E6: =IF(B3="desktop: Office - Libre office","ATTIVA LA VERSIONE ONLINE","") | F6: DELIMITAZIONE ARTICOLO ATTIVATA | G6: Nascondi righe dalla n. | H6: ATTIVA
B7: GG | C7: MM | D7: AA | F7: STUDENTE | G7: ESERCIZIO
E9: .
A10: =COPIA!EX3 -> 0 | B10: Codice | C10: Nr. riga | D10: DATA | E10: DENOMINAZIONE DEI CONTI | F10: DESCRIZIONE | G10: DARE | H10: AVERE | P10: =IFERROR(INDEX($L$11:$M$308,MATCH(MAX($L$11:$L$308)-1,$L$11:$L$308,0),2),0) -> 0
B11: =IF(D11<>"",IFERROR(IF(C11<>"",INDEX(PIANO_DEI_CONTI,MATCH(INDIRECT(ADDRESS(ROW(),5,,,)),DENOMINAZIONE,0),1),""),""),"") | C11: =IF(D11<>"",IF(INDIRECT(ADDRESS(ROW(),5,,,))<>"",ROW()-10,""),"") | K11: =IF(IF(COPIA!$J$3=TRUE,IF(OR(G11<>0,H11<>0),ROUND(SUM(COPIA!$FB$103:FB103),2)-ROUND(SUM(COPIA!$FC$103:FC103),2),""),"")<>0,"",0) | L11: =IFERROR(IF(AND(INDIRECT(ADDRESS(ROW(),4,,,))<=COPIA!$DA$1,K11=0,COPIA!$EX$1>1,ROW()<=COPIA!$EX$1),MAX($L$10:L10)+1,IF(AND(INDIRECT(ADDRESS(ROW(),4,,,))<=COPIA!$DA$1,K11=0,COPIA!$EX$1=1),MAX($L$10:L10)+1,0)),0) -> 0 | M11: =IF(AND(COPIA!$EX$1=1,L11<>0),ROW()-10,IF(AND(COPIA!$EX$1>1,ROW()>COPIA!$EX$1,L11<>0),0,IF(AND(COPIA!$EX$1>1,ROW()<=COPIA!$EX$1,L11<>0),ROW()-10,0))) -> 0 | N11: =IF(AND($P$4=0,ROW()-10<=$P$10),MAX($N$10:N10)+1,IF(AND(ROW()-10>$P$10,ROW()-10<=$P$4),ROW()-10,0)) -> 0 | O11: =IF(N11>0,MAX($O$10:O10)+1,0) -> 0
B12: =IF(D12<>"",IFERROR(IF(C12<>"",INDEX(PIANO_DEI_CONTI,MATCH(INDIRECT(ADDRESS(ROW(),5,,,)),DENOMINAZIONE,0),1),""),""),"") | C12: =IF(D12<>"",IF(INDIRECT(ADDRESS(ROW(),5,,,))<>"",ROW()-10,""),"") | K12: =IF(IF(COPIA!$J$3=TRUE,IF(OR(G12<>0,H12<>0),ROUND(SUM(COPIA!$FB$103:FB104),2)-ROUND(SUM(COPIA!$FC$103:FC104),2),""),"")<>0,"",0) | L12: =IFERROR(IF(AND(INDIRECT(ADDRESS(ROW(),4,,,))<=COPIA!$DA$1,K12=0,COPIA!$EX$1>1,ROW()<=COPIA!$EX$1),MAX($L$10:L11)+1,IF(AND(INDIRECT(ADDRESS(ROW(),4,,,))<=COPIA!$DA$1,K12=0,COPIA!$EX$1=1),MAX($L$10:L11)+1,0)),0) -> 0 | M12: =IF(AND(COPIA!$EX$1=1,L12<>0),ROW()-10,IF(AND(COPIA!$EX$1>1,ROW()>COPIA!$EX$1,L12<>0),0,IF(AND(COPIA!$EX$1>1,ROW()<=COPIA!$EX$1,L12<>0),ROW()-10,0))) -> 0 | N12: =IF(AND($P$4=0,ROW()-10<=$P$10),MAX($N$10:N11)+1,IF(AND(ROW()-10>$P$10,ROW()-10<=$P$4),ROW()-10,0)) -> 0 | O12: =IF(N12>0,MAX($O$10:O11)+1,0) -> 0
B13: =IF(D13<>"",IFERROR(IF(C13<>"",INDEX(PIANO_DEI_CONTI,MATCH(INDIRECT(ADDRESS(ROW(),5,,,)),DENOMINAZIONE,0),1),""),""),"") | C13: =IF(D13<>"",IF(INDIRECT(ADDRESS(ROW(),5,,,))<>"",ROW()-10,""),"") | K13: =IF(IF(COPIA!$J$3=TRUE,IF(OR(G13<>0,H13<>0),ROUND(SUM(COPIA!$FB$103:FB105),2)-ROUND(SUM(COPIA!$FC$103:FC105),2),""),"")<>0,"",0) | L13: =IFERROR(IF(AND(INDIRECT(ADDRESS(ROW(),4,,,))<=COPIA!$DA$1,K13=0,COPIA!$EX$1>1,ROW()<=COPIA!$EX$1),MAX($L$10:L12)+1,IF(AND(INDIRECT(ADDRESS(ROW(),4,,,))<=COPIA!$DA$1,K13=0,COPIA!$EX$1=1),MAX($L$10:L12)+1,0)),0) -> 0 | M13: =IF(AND(COPIA!$EX$1=1,L13<>0),ROW()-10,IF(AND(COPIA!$EX$1>1,ROW()>COPIA!$EX$1,L13<>0),0,IF(AND(COPIA!$EX$1>1,ROW()<=COPIA!$EX$1,L13<>0),ROW()-10,0))) -> 0 | N13: =IF(AND($P$4=0,ROW()-10<=$P$10),MAX($N$10:N12)+1,IF(AND(ROW()-10>$P$10,ROW()-10<=$P$4),ROW()-10,0)) -> 0 | O13: =IF(N13>0,MAX($O$10:O12)+1,0) -> 0
B14: =IF(D14<>"",IFERROR(IF(C14<>"",INDEX(PIANO_DEI_CONTI,MATCH(INDIRECT(ADDRESS(ROW(),5,,,)),DENOMINAZIONE,0),1),""),""),"") | C14: =IF(D14<>"",IF(INDIRECT(ADDRESS(ROW(),5,,,))<>"",ROW()-10,""),"") | K14: =IF(IF(COPIA!$J$3=TRUE,IF(OR(G14<>0,H14<>0),ROUND(SUM(COPIA!$FB$103:FB106),2)-ROUND(SUM(COPIA!$FC$103:FC106),2),""),"")<>0,"",0) | L14: =IFERROR(IF(AND(INDIRECT(ADDRESS(ROW(),4,,,))<=COPIA!$DA$1,K14=0,COPIA!$EX$1>1,ROW()<=COPIA!$EX$1),MAX($L$10:L13)+1,IF(AND(INDIRECT(ADDRESS(ROW(),4,,,))<=COPIA!$DA$1,K14=0,COPIA!$EX$1=1),MAX($L$10:L13)+1,0)),0) -> 0 | M14: =IF(AND(COPIA!$EX$1=1,L14<>0),ROW()-10,IF(AND(COPIA!$EX$1>1,ROW()>COPIA!$EX$1,L14<>0),0,IF(AND(COPIA!$EX$1>1,ROW()<=COPIA!$EX$1,L14<>0),ROW()-10,0))) -> 0 | N14: =IF(AND($P$4=0,ROW()-10<=$P$10),MAX($N$10:N13)+1,IF(AND(ROW()-10>$P$10,ROW()-10<=$P$4),ROW()-10,0)) -> 0 | O14: =IF(N14>0,MAX($O$10:O13)+1,0) -> 0
B15: =IF(D15<>"",IFERROR(IF(C15<>"",INDEX(PIANO_DEI_CONTI,MATCH(INDIRECT(ADDRESS(ROW(),5,,,)),DENOMINAZIONE,0),1),""),""),"") | C15: =IF(D15<>"",IF(INDIRECT(ADDRESS(ROW(),5,,,))<>"",ROW()-10,""),"") | K15: =IF(IF(COPIA!$J$3=TRUE,IF(OR(G15<>0,H15<>0),ROUND(SUM(COPIA!$FB$103:FB107),2)-ROUND(SUM(COPIA!$FC$103:FC107),2),""),"")<>0,"",0) | L15: =IFERROR(IF(AND(INDIRECT(ADDRESS(ROW(),4,,,))<=COPIA!$DA$1,K15=0,COPIA!$EX$1>1,ROW()<=COPIA!$EX$1),MAX($L$10:L14)+1,IF(AND(INDIRECT(ADDRESS(ROW(),4,,,))<=COPIA!$DA$1,K15=0,COPIA!$EX$1=1),MAX($L$10:L14)+1,0)),0) -> 0 | M15: =IF(AND(COPIA!$EX$1=1,L15<>0),ROW()-10,IF(AND(COPIA!$EX$1>1,ROW()>COPIA!$EX$1,L15<>0),0,IF(AND(COPIA!$EX$1>1,ROW()<=COPIA!$EX$1,L15<>0),ROW()-10,0))) -> 0 | N15: =IF(AND($P$4=0,ROW()-10<=$P$10),MAX($N$10:N14)+1,IF(AND(ROW()-10>$P$10,ROW()-10<=$P$4),ROW()-10,0)) -> 0 | O15: =IF(N15>0,MAX($O$10:O14)+1,0) -> 0
B16: =IF(D16<>"",IFERROR(IF(C16<>"",INDEX(PIANO_DEI_CONTI,MATCH(INDIRECT(ADDRESS(ROW(),5,,,)),DENOMINAZIONE,0),1),""),""),"") | C16: =IF(D16<>"",IF(INDIRECT(ADDRESS(ROW(),5,,,))<>"",ROW()-10,""),"") | K16: =IF(IF(COPIA!$J$3=TRUE,IF(OR(G16<>0,H16<>0),ROUND(SUM(COPIA!$FB$103:FB108),2)-ROUND(SUM(COPIA!$FC$103:FC108),2),""),"")<>0,"",0) | L16: =IFERROR(IF(AND(INDIRECT(ADDRESS(ROW(),4,,,))<=COPIA!$DA$1,K16=0,COPIA!$EX$1>1,ROW()<=COPIA!$EX$1),MAX($L$10:L15)+1,IF(AND(INDIRECT(ADDRESS(ROW(),4,,,))<=COPIA!$DA$1,K16=0,COPIA!$EX$1=1),MAX($L$10:L15)+1,0)),0) -> 0 | M16: =IF(AND(COPIA!$EX$1=1,L16<>0),ROW()-10,IF(AND(COPIA!$EX$1>1,ROW()>COPIA!$EX$1,L16<>0),0,IF(AND(COPIA!$EX$1>1,ROW()<=COPIA!$EX$1,L16<>0),ROW()-10,0))) -> 0 | N16: =IF(AND($P$4=0,ROW()-10<=$P$10),MAX($N$10:N15)+1,IF(AND(ROW()-10>$P$10,ROW()-10<=$P$4),ROW()-10,0)) -> 0 | O16: =IF(N16>0,MAX($O$10:O15)+1,0) -> 0
B17: =IF(D17<>"",IFERROR(IF(C17<>"",INDEX(PIANO_DEI_CONTI,MATCH(INDIRECT(ADDRESS(ROW(),5,,,)),DENOMINAZIONE,0),1),""),""),"") | C17: =IF(D17<>"",IF(INDIRECT(ADDRESS(ROW(),5,,,))<>"",ROW()-10,""),"") | K17: =IF(IF(COPIA!$J$3=TRUE,IF(OR(G17<>0,H17<>0),ROUND(SUM(COPIA!$FB$103:FB109),2)-ROUND(SUM(COPIA!$FC$103:FC109),2),""),"")<>0,"",0) | L17: =IFERROR(IF(AND(INDIRECT(ADDRESS(ROW(),4,,,))<=COPIA!$DA$1,K17=0,COPIA!$EX$1>1,ROW()<=COPIA!$EX$1),MAX($L$10:L16)+1,IF(AND(INDIRECT(ADDRESS(ROW(),4,,,))<=COPIA!$DA$1,K17=0,COPIA!$EX$1=1),MAX($L$10:L16)+1,0)),0) -> 0 | M17: =IF(AND(COPIA!$EX$1=1,L17<>0),ROW()-10,IF(AND(COPIA!$EX$1>1,ROW()>COPIA!$EX$1,L17<>0),0,IF(AND(COPIA!$EX$1>1,ROW()<=COPIA!$EX$1,L17<>0),ROW()-10,0))) -> 0 | N17: =IF(AND($P$4=0,ROW()-10<=$P$10),MAX($N$10:N16)+1,IF(AND(ROW()-10>$P$10,ROW()-10<=$P$4),ROW()-10,0)) -> 0 | O17: =IF(N17>0,MAX($O$10:O16)+1,0) -> 0
B18: =IF(D18<>"",IFERROR(IF(C18<>"",INDEX(PIANO_DEI_CONTI,MATCH(INDIRECT(ADDRESS(ROW(),5,,,)),DENOMINAZIONE,0),1),""),""),"") | C18: =IF(D18<>"",IF(INDIRECT(ADDRESS(ROW(),5,,,))<>"",ROW()-10,""),"") | K18: =IF(IF(COPIA!$J$3=TRUE,IF(OR(G18<>0,H18<>0),ROUND(SUM(COPIA!$FB$103:FB110),2)-ROUND(SUM(COPIA!$FC$103:FC110),2),""),"")<>0,"",0) | L18: =IFERROR(IF(AND(INDIRECT(ADDRESS(ROW(),4,,,))<=COPIA!$DA$1,K18=0,COPIA!$EX$1>1,ROW()<=COPIA!$EX$1),MAX($L$10:L17)+1,IF(AND(INDIRECT(ADDRESS(ROW(),4,,,))<=COPIA!$DA$1,K18=0,COPIA!$EX$1=1),MAX($L$10:L17)+1,0)),0) -> 0 | M18: =IF(AND(COPIA!$EX$1=1,L18<>0),ROW()-10,IF(AND(COPIA!$EX$1>1,ROW()>COPIA!$EX$1,L18<>0),0,IF(AND(COPIA!$EX$1>1,ROW()<=COPIA!$EX$1,L18<>0),ROW()-10,0))) -> 0 | N18: =IF(AND($P$4=0,ROW()-10<=$P$10),MAX($N$10:N17)+1,IF(AND(ROW()-10>$P$10,ROW()-10<=$P$4),ROW()-10,0)) -> 0 | O18: =IF(N18>0,MAX($O$10:O17)+1,0) -> 0
B19: =IF(D19<>"",IFERROR(IF(C19<>"",INDEX(PIANO_DEI_CONTI,MATCH(INDIRECT(ADDRESS(ROW(),5,,,)),DENOMINAZIONE,0),1),""),""),"") | C19: =IF(D19<>"",IF(INDIRECT(ADDRESS(ROW(),5,,,))<>"",ROW()-10,""),"") | K19: =IF(IF(COPIA!$J$3=TRUE,IF(OR(G19<>0,H19<>0),ROUND(SUM(COPIA!$FB$103:FB111),2)-ROUND(SUM(COPIA!$FC$103:FC111),2),""),"")<>0,"",0) | L19: =IFERROR(IF(AND(INDIRECT(ADDRESS(ROW(),4,,,))<=COPIA!$DA$1,K19=0,COPIA!$EX$1>1,ROW()<=COPIA!$EX$1),MAX($L$10:L18)+1,IF(AND(INDIRECT(ADDRESS(ROW(),4,,,))<=COPIA!$DA$1,K19=0,COPIA!$EX$1=1),MAX($L$10:L18)+1,0)),0) -> 0 | M19: =IF(AND(COPIA!$EX$1=1,L19<>0),ROW()-10,IF(AND(COPIA!$EX$1>1,ROW()>COPIA!$EX$1,L19<>0),0,IF(AND(COPIA!$EX$1>1,ROW()<=COPIA!$EX$1,L19<>0),ROW()-10,0))) -> 0 | N19: =IF(AND($P$4=0,ROW()-10<=$P$10),MAX($N$10:N18)+1,IF(AND(ROW()-10>$P$10,ROW()-10<=$P$4),ROW()-10,0)) -> 0 | O19: =IF(N19>0,MAX($O$10:O18)+1,0) -> 0
B20: =IF(D20<>"",IFERROR(IF(C20<>"",INDEX(PIANO_DEI_CONTI,MATCH(INDIRECT(ADDRESS(ROW(),5,,,)),DENOMINAZIONE,0),1),""),""),"") | C20: =IF(D20<>"",IF(INDIRECT(ADDRESS(ROW(),5,,,))<>"",ROW()-10,""),"") | K20: =IF(IF(COPIA!$J$3=TRUE,IF(OR(G20<>0,H20<>0),ROUND(SUM(COPIA!$FB$103:FB112),2)-ROUND(SUM(COPIA!$FC$103:FC112),2),""),"")<>0,"",0) | L20: =IFERROR(IF(AND(INDIRECT(ADDRESS(ROW(),4,,,))<=COPIA!$DA$1,K20=0,COPIA!$EX$1>1,ROW()<=COPIA!$EX$1),MAX($L$10:L19)+1,IF(AND(INDIRECT(ADDRESS(ROW(),4,,,))<=COPIA!$DA$1,K20=0,COPIA!$EX$1=1),MAX($L$10:L19)+1,0)),0) -> 0 | M20: =IF(AND(COPIA!$EX$1=1,L20<>0),ROW()-10,IF(AND(COPIA!$EX$1>1,ROW()>COPIA!$EX$1,L20<>0),0,IF(AND(COPIA!$EX$1>1,ROW()<=COPIA!$EX$1,L20<>0),ROW()-10,0))) -> 0 | N20: =IF(AND($P$4=0,ROW()-10<=$P$10),MAX($N$10:N19)+1,IF(AND(ROW()-10>$P$10,ROW()-10<=$P$4),ROW()-10,0)) -> 0 | O20: =IF(N20>0,MAX($O$10:O19)+1,0) -> 0
B21: =IF(D21<>"",IFERROR(IF(C21<>"",INDEX(PIANO_DEI_CONTI,MATCH(INDIRECT(ADDRESS(ROW(),5,,,)),DENOMINAZIONE,0),1),""),""),"") | C21: =IF(D21<>"",IF(INDIRECT(ADDRESS(ROW(),5,,,))<>"",ROW()-10,""),"") | K21: =IF(IF(COPIA!$J$3=TRUE,IF(OR(G21<>0,H21<>0),ROUND(SUM(COPIA!$FB$103:FB113),2)-ROUND(SUM(COPIA!$FC$103:FC113),2),""),"")<>0,"",0) | L21: =IFERROR(IF(AND(INDIRECT(ADDRESS(ROW(),4,,,))<=COPIA!$DA$1,K21=0,COPIA!$EX$1>1,ROW()<=COPIA!$EX$1),MAX($L$10:L20)+1,IF(AND(INDIRECT(ADDRESS(ROW(),4,,,))<=COPIA!$DA$1,K21=0,COPIA!$EX$1=1),MAX($L$10:L20)+1,0)),0) -> 0 | M21: =IF(AND(COPIA!$EX$1=1,L21<>0),ROW()-10,IF(AND(COPIA!$EX$1>1,ROW()>COPIA!$EX$1,L21<>0),0,IF(AND(COPIA!$EX$1>1,ROW()<=COPIA!$EX$1,L21<>0),ROW()-10,0))) -> 0 | N21: =IF(AND($P$4=0,ROW()-10<=$P$10),MAX($N$10:N20)+1,IF(AND(ROW()-10>$P$10,ROW()-10<=$P$4),ROW()-10,0)) -> 0 | O21: =IF(N21>0,MAX($O$10:O20)+1,0) -> 0
B22: =IF(D22<>"",IFERROR(IF(C22<>"",INDEX(PIANO_DEI_CONTI,MATCH(INDIRECT(ADDRESS(ROW(),5,,,)),DENOMINAZIONE,0),1),""),""),"") | C22: =IF(D22<>"",IF(INDIRECT(ADDRESS(ROW(),5,,,))<>"",ROW()-10,""),"") | K22: =IF(IF(COPIA!$J$3=TRUE,IF(OR(G22<>0,H22<>0),ROUND(SUM(COPIA!$FB$103:FB114),2)-ROUND(SUM(COPIA!$FC$103:FC114),2),""),"")<>0,"",0) | L22: =IFERROR(IF(AND(INDIRECT(ADDRESS(ROW(),4,,,))<=COPIA!$DA$1,K22=0,COPIA!$EX$1>1,ROW()<=COPIA!$EX$1),MAX($L$10:L21)+1,IF(AND(INDIRECT(ADDRESS(ROW(),4,,,))<=COPIA!$DA$1,K22=0,COPIA!$EX$1=1),MAX($L$10:L21)+1,0)),0) -> 0 | M22: =IF(AND(COPIA!$EX$1=1,L22<>0),ROW()-10,IF(AND(COPIA!$EX$1>1,ROW()>COPIA!$EX$1,L22<>0),0,IF(AND(COPIA!$EX$1>1,ROW()<=COPIA!$EX$1,L22<>0),ROW()-10,0))) -> 0 | N22: =IF(AND($P$4=0,ROW()-10<=$P$10),MAX($N$10:N21)+1,IF(AND(ROW()-10>$P$10,ROW()-10<=$P$4),ROW()-10,0)) -> 0 | O22: =IF(N22>0,MAX($O$10:O21)+1,0) -> 0
... B308: =IF(D308<>"",IFERROR(IF(C308<>"",INDEX(PIANO_DEI_CONTI,MATCH(INDIRECT(ADDRESS(ROW(),5,,,)),DENOMINAZIONE,0),1),""),""),"") | C308: =IF(D308<>"",IF(INDIRECT(ADDRESS(ROW(),5,,,))<>"",ROW()-10,""),"") | K308: =IF(IF(COPIA!$J$3=TRUE,IF(OR(G308<>0,H308<>0),ROUND(SUM(COPIA!$FB$103:FB400),2)-ROUND(SUM(COPIA!$FC$103:FC400),2),""),"")<>0,"",0) | L308: =IFERROR(IF(AND(INDIRECT(ADDRESS(ROW(),4,,,))<=COPIA!$DA$1,K308=0,COPIA!$EX$1>1,ROW()<=COPIA!$EX$1),MAX($L$10:L307)+1,IF(AND(INDIRECT(ADDRESS(ROW(),4,,,))<=COPIA!$DA$1,K308=0,COPIA!$EX$1=1),MAX($L$10:L307)+1,0)),0) -> 0 | M308: =IF(AND(COPIA!$EX$1=1,L308<>0),ROW()-10,IF(AND(COPIA!$EX$1>1,ROW()>COPIA!$EX$1,L308<>0),0,IF(AND(COPIA!$EX$1>1,ROW()<=COPIA!$EX$1,L308<>0),ROW()-10,0))) -> 0 | N308: =IF(AND($P$4=0,ROW()-10<=$P$10),MAX($N$10:N307)+1,IF(AND(ROW()-10>$P$10,ROW()-10<=$P$4),ROW()-10,0)) -> 0 | O308: =IF(N308>0,MAX($O$10:O307)+1,0) -> 0

Sheet CONTI_DI_MASTRO
B1: CONTI DI MASTRO
B2: =COPIA!JL1 -> Nessun conto visualizzato | E2: Riquadro dI controllo: DENOMINAZIONE dei conti | I2: Riquadro di controllo: ECCEDENZA dei conti
D3: =IF(COPIA!CH1=0,"",CONCATENATE("Numero dei conti con eccedenza errata: ",COPIA!FM1," Numero dei conti con denominazione errata: ",COPIA!EQ2)) | E3: =COPIA!ET3 | I3: =COPIA!FP3
B5: Opzioni di visualizzazione | D5: VISUALIZZA UN CONTO IN EVIDENZA | E5: VISUALIZZA I CONTI SECONDO L'ORDINE DEL PIANO DEI CONTI | I5: VISUALIZZA I MOVIMENTI DEI CONTI E IL SALDO
B7: =IF(INDIRECT(ADDRESS(8,7,,,"LIBRO_GIORNALE"))="","",INDIRECT(ADDRESS(8,7,,,"LIBRO_GIORNALE"))) | D7: =IF(COPIA!CH1=0,"",CONCATENATE("CONTI DI MASTRO al ",COPIA!DS2,"/",COPIA!DT2,"/",COPIA!DU2)) | E7: =IF(INDIRECT(ADDRESS(8,6,,,"LIBRO_GIORNALE"))="","",INDIRECT(ADDRESS(8,6,,,"LIBRO_GIORNALE")))
B8: =IF(IFERROR(INDEX((COPIA!$DA$3:$DE$2300),MATCH(ROWS(B$8:B8),COPIA!$DF$3:$DF$2300,0),COLUMN()-1),"")>=1,IFERROR(INDEX((COPIA!$DA$3:$DE$2300),MATCH(ROWS(B$8:B8),COPIA!$DF$3:$DF$2300,0),COLUMN()-1),""),"") | C8: =SUBSTITUTE(IFERROR(INDEX((COPIA!$DA$3:$DE$2300),MATCH(ROWS(C$8:C8),COPIA!$DF$3:$DF$2300,0),COLUMN()-1),""),"MASTRO","") | D8: =IF(IFERROR(INDEX((COPIA!$DA$3:$DE$2300),MATCH(ROWS(D$8:D8),COPIA!$DF$3:$DF$2300,0),COLUMN()-1),"")=0,"",IFERROR(INDEX((COPIA!$DA$3:$DE$2300),MATCH(ROWS(D$8:D8),COPIA!$DF$3:$DF$2300,0),COLUMN()-1),"")) | E8: =IF(IFERROR(INDEX((COPIA!$DA$3:$DE$2300),MATCH(ROWS(E$8:E8),COPIA!$DF$3:$DF$2300,0),COLUMN()-1),"")=0,"",IFERROR(INDEX((COPIA!$DA$3:$DE$2300),MATCH(ROWS(E$8:E8),COPIA!$DF$3:$DF$2300,0),COLUMN()-1),"")) | F8: =IF(IFERROR(INDEX((COPIA!$DA$3:$DE$2300),MATCH(ROWS(F$8:F8),COPIA!$DF$3:$DF$2300,0),COLUMN()-1),"")=0,"",IFERROR(INDEX((COPIA!$DA$3:$DE$2300),MATCH(ROWS(F$8:F8),COPIA!$DF$3:$DF$2300,0),COLUMN()-1),""))
B9: =IF(IFERROR(INDEX((COPIA!$DA$3:$DE$2300),MATCH(ROWS(B$8:B9),COPIA!$DF$3:$DF$2300,0),COLUMN()-1),"")>=1,IFERROR(INDEX((COPIA!$DA$3:$DE$2300),MATCH(ROWS(B$8:B9),COPIA!$DF$3:$DF$2300,0),COLUMN()-1),""),"") | C9: =SUBSTITUTE(IFERROR(INDEX((COPIA!$DA$3:$DE$2300),MATCH(ROWS(C$8:C9),COPIA!$DF$3:$DF$2300,0),COLUMN()-1),""),"MASTRO","") | D9: =IF(IFERROR(INDEX((COPIA!$DA$3:$DE$2300),MATCH(ROWS(D$8:D9),COPIA!$DF$3:$DF$2300,0),COLUMN()-1),"")=0,"",IFERROR(INDEX((COPIA!$DA$3:$DE$2300),MATCH(ROWS(D$8:D9),COPIA!$DF$3:$DF$2300,0),COLUMN()-1),"")) | E9: =IF(IFERROR(INDEX((COPIA!$DA$3:$DE$2300),MATCH(ROWS(E$8:E9),COPIA!$DF$3:$DF$2300,0),COLUMN()-1),"")=0,"",IFERROR(INDEX((COPIA!$DA$3:$DE$2300),MATCH(ROWS(E$8:E9),COPIA!$DF$3:$DF$2300,0),COLUMN()-1),"")) | F9: =IF(IFERROR(INDEX((COPIA!$DA$3:$DE$2300),MATCH(ROWS(F$8:F9),COPIA!$DF$3:$DF$2300,0),COLUMN()-1),"")=0,"",IFERROR(INDEX((COPIA!$DA$3:$DE$2300),MATCH(ROWS(F$8:F9),COPIA!$DF$3:$DF$2300,0),COLUMN()-1),""))
B10: =IF(IFERROR(INDEX((COPIA!$DA$3:$DE$2300),MATCH(ROWS(B$8:B10),COPIA!$DF$3:$DF$2300,0),COLUMN()-1),"")>=1,IFERROR(INDEX((COPIA!$DA$3:$DE$2300),MATCH(ROWS(B$8:B10),COPIA!$DF$3:$DF$2300,0),COLUMN()-1),""),"") | C10: =SUBSTITUTE(IFERROR(INDEX((COPIA!$DA$3:$DE$2300),MATCH(ROWS(C$8:C10),COPIA!$DF$3:$DF$2300,0),COLUMN()-1),""),"MASTRO","") | D10: =IF(IFERROR(INDEX((COPIA!$DA$3:$DE$2300),MATCH(ROWS(D$8:D10),COPIA!$DF$3:$DF$2300,0),COLUMN()-1),"")=0,"",IFERROR(INDEX((COPIA!$DA$3:$DE$2300),MATCH(ROWS(D$8:D10),COPIA!$DF$3:$DF$2300,0),COLUMN()-1),"")) | E10: =IF(IFERROR(INDEX((COPIA!$DA$3:$DE$2300),MATCH(ROWS(E$8:E10),COPIA!$DF$3:$DF$2300,0),COLUMN()-1),"")=0,"",IFERROR(INDEX((COPIA!$DA$3:$DE$2300),MATCH(ROWS(E$8:E10),COPIA!$DF$3:$DF$2300,0),COLUMN()-1),"")) | F10: =IF(IFERROR(INDEX((COPIA!$DA$3:$DE$2300),MATCH(ROWS(F$8:F10),COPIA!$DF$3:$DF$2300,0),COLUMN()-1),"")=0,"",IFERROR(INDEX((COPIA!$DA$3:$DE$2300),MATCH(ROWS(F$8:F10),COPIA!$DF$3:$DF$2300,0),COLUMN()-1),""))
B11: =IF(IFERROR(INDEX((COPIA!$DA$3:$DE$2300),MATCH(ROWS(B$8:B11),COPIA!$DF$3:$DF$2300,0),COLUMN()-1),"")>=1,IFERROR(INDEX((COPIA!$DA$3:$DE$2300),MATCH(ROWS(B$8:B11),COPIA!$DF$3:$DF$2300,0),COLUMN()-1),""),"") | C11: =SUBSTITUTE(IFERROR(INDEX((COPIA!$DA$3:$DE$2300),MATCH(ROWS(C$8:C11),COPIA!$DF$3:$DF$2300,0),COLUMN()-1),""),"MASTRO","") | D11: =IF(IFERROR(INDEX((COPIA!$DA$3:$DE$2300),MATCH(ROWS(D$8:D11),COPIA!$DF$3:$DF$2300,0),COLUMN()-1),"")=0,"",IFERROR(INDEX((COPIA!$DA$3:$DE$2300),MATCH(ROWS(D$8:D11),COPIA!$DF$3:$DF$2300,0),COLUMN()-1),"")) | E11: =IF(IFERROR(INDEX((COPIA!$DA$3:$DE$2300),MATCH(ROWS(E$8:E11),COPIA!$DF$3:$DF$2300,0),COLUMN()-1),"")=0,"",IFERROR(INDEX((COPIA!$DA$3:$DE$2300),MATCH(ROWS(E$8:E11),COPIA!$DF$3:$DF$2300,0),COLUMN()-1),"")) | F11: =IF(IFERROR(INDEX((COPIA!$DA$3:$DE$2300),MATCH(ROWS(F$8:F11),COPIA!$DF$3:$DF$2300,0),COLUMN()-1),"")=0,"",IFERROR(INDEX((COPIA!$DA$3:$DE$2300),MATCH(ROWS(F$8:F11),COPIA!$DF$3:$DF$2300,0),COLUMN()-1),""))
B12: =IF(IFERROR(INDEX((COPIA!$DA$3:$DE$2300),MATCH(ROWS(B$8:B12),COPIA!$DF$3:$DF$2300,0),COLUMN()-1),"")>=1,IFERROR(INDEX((COPIA!$DA$3:$DE$2300),MATCH(ROWS(B$8:B12),COPIA!$DF$3:$DF$2300,0),COLUMN()-1),""),"") | C12: =SUBSTITUTE(IFERROR(INDEX((COPIA!$DA$3:$DE$2300),MATCH(ROWS(C$8:C12),COPIA!$DF$3:$DF$2300,0),COLUMN()-1),""),"MASTRO","") | D12: =IF(IFERROR(INDEX((COPIA!$DA$3:$DE$2300),MATCH(ROWS(D$8:D12),COPIA!$DF$3:$DF$2300,0),COLUMN()-1),"")=0,"",IFERROR(INDEX((COPIA!$DA$3:$DE$2300),MATCH(ROWS(D$8:D12),COPIA!$DF$3:$DF$2300,0),COLUMN()-1),"")) | E12: =IF(IFERROR(INDEX((COPIA!$DA$3:$DE$2300),MATCH(ROWS(E$8:E12),COPIA!$DF$3:$DF$2300,0),COLUMN()-1),"")=0,"",IFERROR(INDEX((COPIA!$DA$3:$DE$2300),MATCH(ROWS(E$8:E12),COPIA!$DF$3:$DF$2300,0),COLUMN()-1),"")) | F12: =IF(IFERROR(INDEX((COPIA!$DA$3:$DE$2300),MATCH(ROWS(F$8:F12),COPIA!$DF$3:$DF$2300,0),COLUMN()-1),"")=0,"",IFERROR(INDEX((COPIA!$DA$3:$DE$2300),MATCH(ROWS(F$8:F12),COPIA!$DF$3:$DF$2300,0),COLUMN()-1),""))
B13: =IF(IFERROR(INDEX((COPIA!$DA$3:$DE$2300),MATCH(ROWS(B$8:B13),COPIA!$DF$3:$DF$2300,0),COLUMN()-1),"")>=1,IFERROR(INDEX((COPIA!$DA$3:$DE$2300),MATCH(ROWS(B$8:B13),COPIA!$DF$3:$DF$2300,0),COLUMN()-1),""),"") | C13: =SUBSTITUTE(IFERROR(INDEX((COPIA!$DA$3:$DE$2300),MATCH(ROWS(C$8:C13),COPIA!$DF$3:$DF$2300,0),COLUMN()-1),""),"MASTRO","") | D13: =IF(IFERROR(INDEX((COPIA!$DA$3:$DE$2300),MATCH(ROWS(D$8:D13),COPIA!$DF$3:$DF$2300,0),COLUMN()-1),"")=0,"",IFERROR(INDEX((COPIA!$DA$3:$DE$2300),MATCH(ROWS(D$8:D13),COPIA!$DF$3:$DF$2300,0),COLUMN()-1),"")) | E13: =IF(IFERROR(INDEX((COPIA!$DA$3:$DE$2300),MATCH(ROWS(E$8:E13),COPIA!$DF$3:$DF$2300,0),COLUMN()-1),"")=0,"",IFERROR(INDEX((COPIA!$DA$3:$DE$2300),MATCH(ROWS(E$8:E13),COPIA!$DF$3:$DF$2300,0),COLUMN()-1),"")) | F13: =IF(IFERROR(INDEX((COPIA!$DA$3:$DE$2300),MATCH(ROWS(F$8:F13),COPIA!$DF$3:$DF$2300,0),COLUMN()-1),"")=0,"",IFERROR(INDEX((COPIA!$DA$3:$DE$2300),MATCH(ROWS(F$8:F13),COPIA!$DF$3:$DF$2300,0),COLUMN()-1),""))
B14: =IF(IFERROR(INDEX((COPIA!$DA$3:$DE$2300),MATCH(ROWS(B$8:B14),COPIA!$DF$3:$DF$2300,0),COLUMN()-1),"")>=1,IFERROR(INDEX((COPIA!$DA$3:$DE$2300),MATCH(ROWS(B$8:B14),COPIA!$DF$3:$DF$2300,0),COLUMN()-1),""),"") | C14: =SUBSTITUTE(IFERROR(INDEX((COPIA!$DA$3:$DE$2300),MATCH(ROWS(C$8:C14),COPIA!$DF$3:$DF$2300,0),COLUMN()-1),""),"MASTRO","") | D14: =IF(IFERROR(INDEX((COPIA!$DA$3:$DE$2300),MATCH(ROWS(D$8:D14),COPIA!$DF$3:$DF$2300,0),COLUMN()-1),"")=0,"",IFERROR(INDEX((COPIA!$DA$3:$DE$2300),MATCH(ROWS(D$8:D14),COPIA!$DF$3:$DF$2300,0),COLUMN()-1),"")) | E14: =IF(IFERROR(INDEX((COPIA!$DA$3:$DE$2300),MATCH(ROWS(E$8:E14),COPIA!$DF$3:$DF$2300,0),COLUMN()-1),"")=0,"",IFERROR(INDEX((COPIA!$DA$3:$DE$2300),MATCH(ROWS(E$8:E14),COPIA!$DF$3:$DF$2300,0),COLUMN()-1),"")) | F14: =IF(IFERROR(INDEX((COPIA!$DA$3:$DE$2300),MATCH(ROWS(F$8:F14),COPIA!$DF$3:$DF$2300,0),COLUMN()-1),"")=0,"",IFERROR(INDEX((COPIA!$DA$3:$DE$2300),MATCH(ROWS(F$8:F14),COPIA!$DF$3:$DF$2300,0),COLUMN()-1),""))
B15: =IF(IFERROR(INDEX((COPIA!$DA$3:$DE$2300),MATCH(ROWS(B$8:B15),COPIA!$DF$3:$DF$2300,0),COLUMN()-1),"")>=1,IFERROR(INDEX((COPIA!$DA$3:$DE$2300),MATCH(ROWS(B$8:B15),COPIA!$DF$3:$DF$2300,0),COLUMN()-1),""),"") | C15: =SUBSTITUTE(IFERROR(INDEX((COPIA!$DA$3:$DE$2300),MATCH(ROWS(C$8:C15),COPIA!$DF$3:$DF$2300,0),COLUMN()-1),""),"MASTRO","") | D15: =IF(IFERROR(INDEX((COPIA!$DA$3:$DE$2300),MATCH(ROWS(D$8:D15),COPIA!$DF$3:$DF$2300,0),COLUMN()-1),"")=0,"",IFERROR(INDEX((COPIA!$DA$3:$DE$2300),MATCH(ROWS(D$8:D15),COPIA!$DF$3:$DF$2300,0),COLUMN()-1),"")) | E15: =IF(IFERROR(INDEX((COPIA!$DA$3:$DE$2300),MATCH(ROWS(E$8:E15),COPIA!$DF$3:$DF$2300,0),COLUMN()-1),"")=0,"",IFERROR(INDEX((COPIA!$DA$3:$DE$2300),MATCH(ROWS(E$8:E15),COPIA!$DF$3:$DF$2300,0),COLUMN()-1),"")) | F15: =IF(IFERROR(INDEX((COPIA!$DA$3:$DE$2300),MATCH(ROWS(F$8:F15),COPIA!$DF$3:$DF$2300,0),COLUMN()-1),"")=0,"",IFERROR(INDEX((COPIA!$DA$3:$DE$2300),MATCH(ROWS(F$8:F15),COPIA!$DF$3:$DF$2300,0),COLUMN()-1),""))
B16: =IF(IFERROR(INDEX((COPIA!$DA$3:$DE$2300),MATCH(ROWS(B$8:B16),COPIA!$DF$3:$DF$2300,0),COLUMN()-1),"")>=1,IFERROR(INDEX((COPIA!$DA$3:$DE$2300),MATCH(ROWS(B$8:B16),COPIA!$DF$3:$DF$2300,0),COLUMN()-1),""),"") | C16: =SUBSTITUTE(IFERROR(INDEX((COPIA!$DA$3:$DE$2300),MATCH(ROWS(C$8:C16),COPIA!$DF$3:$DF$2300,0),COLUMN()-1),""),"MASTRO","") | D16: =IF(IFERROR(INDEX((COPIA!$DA$3:$DE$2300),MATCH(ROWS(D$8:D16),COPIA!$DF$3:$DF$2300,0),COLUMN()-1),"")=0,"",IFERROR(INDEX((COPIA!$DA$3:$DE$2300),MATCH(ROWS(D$8:D16),COPIA!$DF$3:$DF$2300,0),COLUMN()-1),"")) | E16: =IF(IFERROR(INDEX((COPIA!$DA$3:$DE$2300),MATCH(ROWS(E$8:E16),COPIA!$DF$3:$DF$2300,0),COLUMN()-1),"")=0,"",IFERROR(INDEX((COPIA!$DA$3:$DE$2300),MATCH(ROWS(E$8:E16),COPIA!$DF$3:$DF$2300,0),COLUMN()-1),"")) | F16: =IF(IFERROR(INDEX((COPIA!$DA$3:$DE$2300),MATCH(ROWS(F$8:F16),COPIA!$DF$3:$DF$2300,0),COLUMN()-1),"")=0,"",IFERROR(INDEX((COPIA!$DA$3:$DE$2300),MATCH(ROWS(F$8:F16),COPIA!$DF$3:$DF$2300,0),COLUMN()-1),""))
B17: =IF(IFERROR(INDEX((COPIA!$DA$3:$DE$2300),MATCH(ROWS(B$8:B17),COPIA!$DF$3:$DF$2300,0),COLUMN()-1),"")>=1,IFERROR(INDEX((COPIA!$DA$3:$DE$2300),MATCH(ROWS(B$8:B17),COPIA!$DF$3:$DF$2300,0),COLUMN()-1),""),"") | C17: =SUBSTITUTE(IFERROR(INDEX((COPIA!$DA$3:$DE$2300),MATCH(ROWS(C$8:C17),COPIA!$DF$3:$DF$2300,0),COLUMN()-1),""),"MASTRO","") | D17: =IF(IFERROR(INDEX((COPIA!$DA$3:$DE$2300),MATCH(ROWS(D$8:D17),COPIA!$DF$3:$DF$2300,0),COLUMN()-1),"")=0,"",IFERROR(INDEX((COPIA!$DA$3:$DE$2300),MATCH(ROWS(D$8:D17),COPIA!$DF$3:$DF$2300,0),COLUMN()-1),"")) | E17: =IF(IFERROR(INDEX((COPIA!$DA$3:$DE$2300),MATCH(ROWS(E$8:E17),COPIA!$DF$3:$DF$2300,0),COLUMN()-1),"")=0,"",IFERROR(INDEX((COPIA!$DA$3:$DE$2300),MATCH(ROWS(E$8:E17),COPIA!$DF$3:$DF$2300,0),COLUMN()-1),"")) | F17: =IF(IFERROR(INDEX((COPIA!$DA$3:$DE$2300),MATCH(ROWS(F$8:F17),COPIA!$DF$3:$DF$2300,0),COLUMN()-1),"")=0,"",IFERROR(INDEX((COPIA!$DA$3:$DE$2300),MATCH(ROWS(F$8:F17),COPIA!$DF$3:$DF$2300,0),COLUMN()-1),""))
B18: =IF(IFERROR(INDEX((COPIA!$DA$3:$DE$2300),MATCH(ROWS(B$8:B18),COPIA!$DF$3:$DF$2300,0),COLUMN()-1),"")>=1,IFERROR(INDEX((COPIA!$DA$3:$DE$2300),MATCH(ROWS(B$8:B18),COPIA!$DF$3:$DF$2300,0),COLUMN()-1),""),"") | C18: =SUBSTITUTE(IFERROR(INDEX((COPIA!$DA$3:$DE$2300),MATCH(ROWS(C$8:C18),COPIA!$DF$3:$DF$2300,0),COLUMN()-1),""),"MASTRO","") | D18: =IF(IFERROR(INDEX((COPIA!$DA$3:$DE$2300),MATCH(ROWS(D$8:D18),COPIA!$DF$3:$DF$2300,0),COLUMN()-1),"")=0,"",IFERROR(INDEX((COPIA!$DA$3:$DE$2300),MATCH(ROWS(D$8:D18),COPIA!$DF$3:$DF$2300,0),COLUMN()-1),"")) | E18: =IF(IFERROR(INDEX((COPIA!$DA$3:$DE$2300),MATCH(ROWS(E$8:E18),COPIA!$DF$3:$DF$2300,0),COLUMN()-1),"")=0,"",IFERROR(INDEX((COPIA!$DA$3:$DE$2300),MATCH(ROWS(E$8:E18),COPIA!$DF$3:$DF$2300,0),COLUMN()-1),"")) | F18: =IF(IFERROR(INDEX((COPIA!$DA$3:$DE$2300),MATCH(ROWS(F$8:F18),COPIA!$DF$3:$DF$2300,0),COLUMN()-1),"")=0,"",IFERROR(INDEX((COPIA!$DA$3:$DE$2300),MATCH(ROWS(F$8:F18),COPIA!$DF$3:$DF$2300,0),COLUMN()-1),""))
B19: =IF(IFERROR(INDEX((COPIA!$DA$3:$DE$2300),MATCH(ROWS(B$8:B19),COPIA!$DF$3:$DF$2300,0),COLUMN()-1),"")>=1,IFERROR(INDEX((COPIA!$DA$3:$DE$2300),MATCH(ROWS(B$8:B19),COPIA!$DF$3:$DF$2300,0),COLUMN()-1),""),"") | C19: =SUBSTITUTE(IFERROR(INDEX((COPIA!$DA$3:$DE$2300),MATCH(ROWS(C$8:C19),COPIA!$DF$3:$DF$2300,0),COLUMN()-1),""),"MASTRO","") | D19: =IF(IFERROR(INDEX((COPIA!$DA$3:$DE$2300),MATCH(ROWS(D$8:D19),COPIA!$DF$3:$DF$2300,0),COLUMN()-1),"")=0,"",IFERROR(INDEX((COPIA!$DA$3:$DE$2300),MATCH(ROWS(D$8:D19),COPIA!$DF$3:$DF$2300,0),COLUMN()-1),"")) | E19: =IF(IFERROR(INDEX((COPIA!$DA$3:$DE$2300),MATCH(ROWS(E$8:E19),COPIA!$DF$3:$DF$2300,0),COLUMN()-1),"")=0,"",IFERROR(INDEX((COPIA!$DA$3:$DE$2300),MATCH(ROWS(E$8:E19),COPIA!$DF$3:$DF$2300,0),COLUMN()-1),"")) | F19: =IF(IFERROR(INDEX((COPIA!$DA$3:$DE$2300),MATCH(ROWS(F$8:F19),COPIA!$DF$3:$DF$2300,0),COLUMN()-1),"")=0,"",IFERROR(INDEX((COPIA!$DA$3:$DE$2300),MATCH(ROWS(F$8:F19),COPIA!$DF$3:$DF$2300,0),COLUMN()-1),""))
... B604: =IF(IFERROR(INDEX((COPIA!$DA$3:$DE$2300),MATCH(ROWS(B$8:B604),COPIA!$DF$3:$DF$2300,0),COLUMN()-1),"")>=1,IFERROR(INDEX((COPIA!$DA$3:$DE$2300),MATCH(ROWS(B$8:B604),COPIA!$DF$3:$DF$2300,0),COLUMN()-1),""),"") | C604: =SUBSTITUTE(IFERROR(INDEX((COPIA!$DA$3:$DE$2300),MATCH(ROWS(C$8:C604),COPIA!$DF$3:$DF$2300,0),COLUMN()-1),""),"MASTRO","") | D604: =IF(IFERROR(INDEX((COPIA!$DA$3:$DE$2300),MATCH(ROWS(D$8:D604),COPIA!$DF$3:$DF$2300,0),COLUMN()-1),"")=0,"",IFERROR(INDEX((COPIA!$DA$3:$DE$2300),MATCH(ROWS(D$8:D604),COPIA!$DF$3:$DF$2300,0),COLUMN()-1),"")) | E604: =IF(IFERROR(INDEX((COPIA!$DA$3:$DE$2300),MATCH(ROWS(E$8:E604),COPIA!$DF$3:$DF$2300,0),COLUMN()-1),"")=0,"",IFERROR(INDEX((COPIA!$DA$3:$DE$2300),MATCH(ROWS(E$8:E604),COPIA!$DF$3:$DF$2300,0),COLUMN()-1),"")) | F604: =IF(IFERROR(INDEX((COPIA!$DA$3:$DE$2300),MATCH(ROWS(F$8:F604),COPIA!$DF$3:$DF$2300,0),COLUMN()-1),"")=0,"",IFERROR(INDEX((COPIA!$DA$3:$DE$2300),MATCH(ROWS(F$8:F604),COPIA!$DF$3:$DF$2300,0),COLUMN()-1),""))

Sheet SIT._CONTABILE
B1: SITUAZIONE CONTABILE
B2: OPZIONI DI VISUALIZZAZIONE | D2: =IF(COPIA!CH1=0,"",IF(COPIA!EV1=0,"I TOTALI SONO CORRETTAMENTE VISUALIZZATI",COPIA!ES1))
B3: PER TOTALI ED ECCEDENZE
A6: =COPIA!DU1 -> 3 | C6: =IF(INDIRECT(ADDRESS(8,6,,,"LIBRO_GIORNALE"))="","",INDIRECT(ADDRESS(8,6,,,"LIBRO_GIORNALE"))) | D6: =IF(INDIRECT(ADDRESS(8,7,,,"LIBRO_GIORNALE"))="","",INDIRECT(ADDRESS(8,7,,,"LIBRO_GIORNALE")))
A7: =MAX(COPIA!DQ3:DQ220)+5 -> 5 | C7: =IF(COPIA!CH1=0,"",IFERROR(CONCATENATE("Situazione contabile per ",LOWER(COPIA!$DQ$1)," al ",COPIA!DS2,"/",COPIA!DT2,"/",COPIA!DU2),""))
A8: =IF(A6=3,6,4) -> 6 | B8: =IF(COPIA!CH1=0,"","CODICI") | C8: =IF(COPIA!CH1=0,"","DENOMINAZIONE DEI CONTI") | D8: =IF(COPIA!CH1=0,"",IF(COPIA!$DU$1=3,MID(COPIA!$DQ$1,1,6),COPIA!$DQ$1)) | F8: =IF(COPIA!CH1=0,"",MID(COPIA!DQ1,11,10))
D9: =IF(COPIA!CH1=0,"","DARE") | E9: =IF(COPIA!CH1=0,"","AVERE") | F9: =IF(COPIA!CH1=0,"",IF(COPIA!$DQ$1="Totali ed eccedenze","DARE","")) | G9: =IF(COPIA!CH1=0,"",IF(COPIA!$DQ$1="Totali ed eccedenze","AVERE",""))
B10: =IFERROR(INDEX(PIANO_DEI_CONTI,MATCH(C10,DENOMINAZIONE,0),1),"") | C10: =IFERROR(CONCATENATE(COPIA!DR3,COPIA!DX3),"") | D10: =IF(IFERROR(IF(COPIA!DS3=0,"",VALUE(CONCATENATE(COPIA!DS3,COPIA!$DY3))),"")=0,"",IFERROR(IF(COPIA!DS3=0,"",VALUE(CONCATENATE(COPIA!DS3,COPIA!$DY3))),"")) | E10: =IF(IFERROR(IF(COPIA!DT3=0,"",VALUE(CONCATENATE(COPIA!DT3,COPIA!$DY3))),"")=0,"",IFERROR(IF(COPIA!DT3=0,"",VALUE(CONCATENATE(COPIA!DT3,COPIA!$DY3))),"")) | F10: =IF(IFERROR(IF(COPIA!DU3=0,"",VALUE(CONCATENATE(COPIA!DU3,COPIA!$DZ3))),"")=0,"",IFERROR(IF(COPIA!DU3=0,"",VALUE(CONCATENATE(COPIA!DU3,COPIA!$DZ3))),"")) | G10: =IF(IFERROR(IF(COPIA!DV3=0,"",VALUE(CONCATENATE(COPIA!DV3,COPIA!$DZ3))),"")=0,"",IFERROR(IF(COPIA!DV3=0,"",VALUE(CONCATENATE(COPIA!DV3,COPIA!$DZ3))),"")) | H10: =IFERROR(COPIA!DW3,"") -> 0
B11: =IFERROR(INDEX(PIANO_DEI_CONTI,MATCH(C11,DENOMINAZIONE,0),1),"") | C11: =IFERROR(CONCATENATE(COPIA!DR4,COPIA!DX4),"") | D11: =IF(IFERROR(IF(COPIA!DS4=0,"",VALUE(CONCATENATE(COPIA!DS4,COPIA!$DY4))),"")=0,"",IFERROR(IF(COPIA!DS4=0,"",VALUE(CONCATENATE(COPIA!DS4,COPIA!$DY4))),"")) | E11: =IF(IFERROR(IF(COPIA!DT4=0,"",VALUE(CONCATENATE(COPIA!DT4,COPIA!$DY4))),"")=0,"",IFERROR(IF(COPIA!DT4=0,"",VALUE(CONCATENATE(COPIA!DT4,COPIA!$DY4))),"")) | F11: =IF(IFERROR(IF(COPIA!DU4=0,"",VALUE(CONCATENATE(COPIA!DU4,COPIA!$DZ4))),"")=0,"",IFERROR(IF(COPIA!DU4=0,"",VALUE(CONCATENATE(COPIA!DU4,COPIA!$DZ4))),"")) | G11: =IF(IFERROR(IF(COPIA!DV4=0,"",VALUE(CONCATENATE(COPIA!DV4,COPIA!$DZ4))),"")=0,"",IFERROR(IF(COPIA!DV4=0,"",VALUE(CONCATENATE(COPIA!DV4,COPIA!$DZ4))),"")) | H11: =IFERROR(COPIA!DW4,"") -> 0
B12: =IFERROR(INDEX(PIANO_DEI_CONTI,MATCH(C12,DENOMINAZIONE,0),1),"") | C12: =IFERROR(CONCATENATE(COPIA!DR5,COPIA!DX5),"") | D12: =IF(IFERROR(IF(COPIA!DS5=0,"",VALUE(CONCATENATE(COPIA!DS5,COPIA!$DY5))),"")=0,"",IFERROR(IF(COPIA!DS5=0,"",VALUE(CONCATENATE(COPIA!DS5,COPIA!$DY5))),"")) | E12: =IF(IFERROR(IF(COPIA!DT5=0,"",VALUE(CONCATENATE(COPIA!DT5,COPIA!$DY5))),"")=0,"",IFERROR(IF(COPIA!DT5=0,"",VALUE(CONCATENATE(COPIA!DT5,COPIA!$DY5))),"")) | F12: =IF(IFERROR(IF(COPIA!DU5=0,"",VALUE(CONCATENATE(COPIA!DU5,COPIA!$DZ5))),"")=0,"",IFERROR(IF(COPIA!DU5=0,"",VALUE(CONCATENATE(COPIA!DU5,COPIA!$DZ5))),"")) | G12: =IF(IFERROR(IF(COPIA!DV5=0,"",VALUE(CONCATENATE(COPIA!DV5,COPIA!$DZ5))),"")=0,"",IFERROR(IF(COPIA!DV5=0,"",VALUE(CONCATENATE(COPIA!DV5,COPIA!$DZ5))),"")) | H12: =IFERROR(COPIA!DW5,"") -> 0
B13: =IFERROR(INDEX(PIANO_DEI_CONTI,MATCH(C13,DENOMINAZIONE,0),1),"") | C13: =IFERROR(CONCATENATE(COPIA!DR6,COPIA!DX6),"") | D13: =IF(IFERROR(IF(COPIA!DS6=0,"",VALUE(CONCATENATE(COPIA!DS6,COPIA!$DY6))),"")=0,"",IFERROR(IF(COPIA!DS6=0,"",VALUE(CONCATENATE(COPIA!DS6,COPIA!$DY6))),"")) | E13: =IF(IFERROR(IF(COPIA!DT6=0,"",VALUE(CONCATENATE(COPIA!DT6,COPIA!$DY6))),"")=0,"",IFERROR(IF(COPIA!DT6=0,"",VALUE(CONCATENATE(COPIA!DT6,COPIA!$DY6))),"")) | F13: =IF(IFERROR(IF(COPIA!DU6=0,"",VALUE(CONCATENATE(COPIA!DU6,COPIA!$DZ6))),"")=0,"",IFERROR(IF(COPIA!DU6=0,"",VALUE(CONCATENATE(COPIA!DU6,COPIA!$DZ6))),"")) | G13: =IF(IFERROR(IF(COPIA!DV6=0,"",VALUE(CONCATENATE(COPIA!DV6,COPIA!$DZ6))),"")=0,"",IFERROR(IF(COPIA!DV6=0,"",VALUE(CONCATENATE(COPIA!DV6,COPIA!$DZ6))),"")) | H13: =IFERROR(COPIA!DW6,"") -> 0
B14: =IFERROR(INDEX(PIANO_DEI_CONTI,MATCH(C14,DENOMINAZIONE,0),1),"") | C14: =IFERROR(CONCATENATE(COPIA!DR7,COPIA!DX7),"") | D14: =IF(IFERROR(IF(COPIA!DS7=0,"",VALUE(CONCATENATE(COPIA!DS7,COPIA!$DY7))),"")=0,"",IFERROR(IF(COPIA!DS7=0,"",VALUE(CONCATENATE(COPIA!DS7,COPIA!$DY7))),"")) | E14: =IF(IFERROR(IF(COPIA!DT7=0,"",VALUE(CONCATENATE(COPIA!DT7,COPIA!$DY7))),"")=0,"",IFERROR(IF(COPIA!DT7=0,"",VALUE(CONCATENATE(COPIA!DT7,COPIA!$DY7))),"")) | F14: =IF(IFERROR(IF(COPIA!DU7=0,"",VALUE(CONCATENATE(COPIA!DU7,COPIA!$DZ7))),"")=0,"",IFERROR(IF(COPIA!DU7=0,"",VALUE(CONCATENATE(COPIA!DU7,COPIA!$DZ7))),"")) | G14: =IF(IFERROR(IF(COPIA!DV7=0,"",VALUE(CONCATENATE(COPIA!DV7,COPIA!$DZ7))),"")=0,"",IFERROR(IF(COPIA!DV7=0,"",VALUE(CONCATENATE(COPIA!DV7,COPIA!$DZ7))),"")) | H14: =IFERROR(COPIA!DW7,"") -> 0
B15: =IFERROR(INDEX(PIANO_DEI_CONTI,MATCH(C15,DENOMINAZIONE,0),1),"") | C15: =IFERROR(CONCATENATE(COPIA!DR8,COPIA!DX8),"") | D15: =IF(IFERROR(IF(COPIA!DS8=0,"",VALUE(CONCATENATE(COPIA!DS8,COPIA!$DY8))),"")=0,"",IFERROR(IF(COPIA!DS8=0,"",VALUE(CONCATENATE(COPIA!DS8,COPIA!$DY8))),"")) | E15: =IF(IFERROR(IF(COPIA!DT8=0,"",VALUE(CONCATENATE(COPIA!DT8,COPIA!$DY8))),"")=0,"",IFERROR(IF(COPIA!DT8=0,"",VALUE(CONCATENATE(COPIA!DT8,COPIA!$DY8))),"")) | F15: =IF(IFERROR(IF(COPIA!DU8=0,"",VALUE(CONCATENATE(COPIA!DU8,COPIA!$DZ8))),"")=0,"",IFERROR(IF(COPIA!DU8=0,"",VALUE(CONCATENATE(COPIA!DU8,COPIA!$DZ8))),"")) | G15: =IF(IFERROR(IF(COPIA!DV8=0,"",VALUE(CONCATENATE(COPIA!DV8,COPIA!$DZ8))),"")=0,"",IFERROR(IF(COPIA!DV8=0,"",VALUE(CONCATENATE(COPIA!DV8,COPIA!$DZ8))),"")) | H15: =IFERROR(COPIA!DW8,"") -> 0
B16: =IFERROR(INDEX(PIANO_DEI_CONTI,MATCH(C16,DENOMINAZIONE,0),1),"") | C16: =IFERROR(CONCATENATE(COPIA!DR9,COPIA!DX9),"") | D16: =IF(IFERROR(IF(COPIA!DS9=0,"",VALUE(CONCATENATE(COPIA!DS9,COPIA!$DY9))),"")=0,"",IFERROR(IF(COPIA!DS9=0,"",VALUE(CONCATENATE(COPIA!DS9,COPIA!$DY9))),"")) | E16: =IF(IFERROR(IF(COPIA!DT9=0,"",VALUE(CONCATENATE(COPIA!DT9,COPIA!$DY9))),"")=0,"",IFERROR(IF(COPIA!DT9=0,"",VALUE(CONCATENATE(COPIA!DT9,COPIA!$DY9))),"")) | F16: =IF(IFERROR(IF(COPIA!DU9=0,"",VALUE(CONCATENATE(COPIA!DU9,COPIA!$DZ9))),"")=0,"",IFERROR(IF(COPIA!DU9=0,"",VALUE(CONCATENATE(COPIA!DU9,COPIA!$DZ9))),"")) | G16: =IF(IFERROR(IF(COPIA!DV9=0,"",VALUE(CONCATENATE(COPIA!DV9,COPIA!$DZ9))),"")=0,"",IFERROR(IF(COPIA!DV9=0,"",VALUE(CONCATENATE(COPIA!DV9,COPIA!$DZ9))),"")) | H16: =IFERROR(COPIA!DW9,"") -> 0
B17: =IFERROR(INDEX(PIANO_DEI_CONTI,MATCH(C17,DENOMINAZIONE,0),1),"") | C17: =IFERROR(CONCATENATE(COPIA!DR10,COPIA!DX10),"") | D17: =IF(IFERROR(IF(COPIA!DS10=0,"",VALUE(CONCATENATE(COPIA!DS10,COPIA!$DY10))),"")=0,"",IFERROR(IF(COPIA!DS10=0,"",VALUE(CONCATENATE(COPIA!DS10,COPIA!$DY10))),"")) | E17: =IF(IFERROR(IF(COPIA!DT10=0,"",VALUE(CONCATENATE(COPIA!DT10,COPIA!$DY10))),"")=0,"",IFERROR(IF(COPIA!DT10=0,"",VALUE(CONCATENATE(COPIA!DT10,COPIA!$DY10))),"")) | F17: =IF(IFERROR(IF(COPIA!DU10=0,"",VALUE(CONCATENATE(COPIA!DU10,COPIA!$DZ10))),"")=0,"",IFERROR(IF(COPIA!DU10=0,"",VALUE(CONCATENATE(COPIA!DU10,COPIA!$DZ10))),"")) | G17: =IF(IFERROR(IF(COPIA!DV10=0,"",VALUE(CONCATENATE(COPIA!DV10,COPIA!$DZ10))),"")=0,"",IFERROR(IF(COPIA!DV10=0,"",VALUE(CONCATENATE(COPIA!DV10,COPIA!$DZ10))),"")) | H17: =IFERROR(COPIA!DW10,"") -> 0
B18: =IFERROR(INDEX(PIANO_DEI_CONTI,MATCH(C18,DENOMINAZIONE,0),1),"") | C18: =IFERROR(CONCATENATE(COPIA!DR11,COPIA!DX11),"") | D18: =IF(IFERROR(IF(COPIA!DS11=0,"",VALUE(CONCATENATE(COPIA!DS11,COPIA!$DY11))),"")=0,"",IFERROR(IF(COPIA!DS11=0,"",VALUE(CONCATENATE(COPIA!DS11,COPIA!$DY11))),"")) | E18: =IF(IFERROR(IF(COPIA!DT11=0,"",VALUE(CONCATENATE(COPIA!DT11,COPIA!$DY11))),"")=0,"",IFERROR(IF(COPIA!DT11=0,"",VALUE(CONCATENATE(COPIA!DT11,COPIA!$DY11))),"")) | F18: =IF(IFERROR(IF(COPIA!DU11=0,"",VALUE(CONCATENATE(COPIA!DU11,COPIA!$DZ11))),"")=0,"",IFERROR(IF(COPIA!DU11=0,"",VALUE(CONCATENATE(COPIA!DU11,COPIA!$DZ11))),"")) | G18: =IF(IFERROR(IF(COPIA!DV11=0,"",VALUE(CONCATENATE(COPIA!DV11,COPIA!$DZ11))),"")=0,"",IFERROR(IF(COPIA!DV11=0,"",VALUE(CONCATENATE(COPIA!DV11,COPIA!$DZ11))),"")) | H18: =IFERROR(COPIA!DW11,"") -> 0
B19: =IFERROR(INDEX(PIANO_DEI_CONTI,MATCH(C19,DENOMINAZIONE,0),1),"") | C19: =IFERROR(CONCATENATE(COPIA!DR12,COPIA!DX12),"") | D19: =IF(IFERROR(IF(COPIA!DS12=0,"",VALUE(CONCATENATE(COPIA!DS12,COPIA!$DY12))),"")=0,"",IFERROR(IF(COPIA!DS12=0,"",VALUE(CONCATENATE(COPIA!DS12,COPIA!$DY12))),"")) | E19: =IF(IFERROR(IF(COPIA!DT12=0,"",VALUE(CONCATENATE(COPIA!DT12,COPIA!$DY12))),"")=0,"",IFERROR(IF(COPIA!DT12=0,"",VALUE(CONCATENATE(COPIA!DT12,COPIA!$DY12))),"")) | F19: =IF(IFERROR(IF(COPIA!DU12=0,"",VALUE(CONCATENATE(COPIA!DU12,COPIA!$DZ12))),"")=0,"",IFERROR(IF(COPIA!DU12=0,"",VALUE(CONCATENATE(COPIA!DU12,COPIA!$DZ12))),"")) | G19: =IF(IFERROR(IF(COPIA!DV12=0,"",VALUE(CONCATENATE(COPIA!DV12,COPIA!$DZ12))),"")=0,"",IFERROR(IF(COPIA!DV12=0,"",VALUE(CONCATENATE(COPIA!DV12,COPIA!$DZ12))),"")) | H19: =IFERROR(COPIA!DW12,"") -> 0
B20: =IFERROR(INDEX(PIANO_DEI_CONTI,MATCH(C20,DENOMINAZIONE,0),1),"") | C20: =IFERROR(CONCATENATE(COPIA!DR13,COPIA!DX13),"") | D20: =IF(IFERROR(IF(COPIA!DS13=0,"",VALUE(CONCATENATE(COPIA!DS13,COPIA!$DY13))),"")=0,"",IFERROR(IF(COPIA!DS13=0,"",VALUE(CONCATENATE(COPIA!DS13,COPIA!$DY13))),"")) | E20: =IF(IFERROR(IF(COPIA!DT13=0,"",VALUE(CONCATENATE(COPIA!DT13,COPIA!$DY13))),"")=0,"",IFERROR(IF(COPIA!DT13=0,"",VALUE(CONCATENATE(COPIA!DT13,COPIA!$DY13))),"")) | F20: =IF(IFERROR(IF(COPIA!DU13=0,"",VALUE(CONCATENATE(COPIA!DU13,COPIA!$DZ13))),"")=0,"",IFERROR(IF(COPIA!DU13=0,"",VALUE(CONCATENATE(COPIA!DU13,COPIA!$DZ13))),"")) | G20: =IF(IFERROR(IF(COPIA!DV13=0,"",VALUE(CONCATENATE(COPIA!DV13,COPIA!$DZ13))),"")=0,"",IFERROR(IF(COPIA!DV13=0,"",VALUE(CONCATENATE(COPIA!DV13,COPIA!$DZ13))),"")) | H20: =IFERROR(COPIA!DW13,"") -> 0
B21: =IFERROR(INDEX(PIANO_DEI_CONTI,MATCH(C21,DENOMINAZIONE,0),1),"") | C21: =IFERROR(CONCATENATE(COPIA!DR14,COPIA!DX14),"") | D21: =IF(IFERROR(IF(COPIA!DS14=0,"",VALUE(CONCATENATE(COPIA!DS14,COPIA!$DY14))),"")=0,"",IFERROR(IF(COPIA!DS14=0,"",VALUE(CONCATENATE(COPIA!DS14,COPIA!$DY14))),"")) | E21: =IF(IFERROR(IF(COPIA!DT14=0,"",VALUE(CONCATENATE(COPIA!DT14,COPIA!$DY14))),"")=0,"",IFERROR(IF(COPIA!DT14=0,"",VALUE(CONCATENATE(COPIA!DT14,COPIA!$DY14))),"")) | F21: =IF(IFERROR(IF(COPIA!DU14=0,"",VALUE(CONCATENATE(COPIA!DU14,COPIA!$DZ14))),"")=0,"",IFERROR(IF(COPIA!DU14=0,"",VALUE(CONCATENATE(COPIA!DU14,COPIA!$DZ14))),"")) | G21: =IF(IFERROR(IF(COPIA!DV14=0,"",VALUE(CONCATENATE(COPIA!DV14,COPIA!$DZ14))),"")=0,"",IFERROR(IF(COPIA!DV14=0,"",VALUE(CONCATENATE(COPIA!DV14,COPIA!$DZ14))),"")) | H21: =IFERROR(COPIA!DW14,"") -> 0
... B227: =IFERROR(INDEX(PIANO_DEI_CONTI,MATCH(C227,DENOMINAZIONE,0),1),"") | C227: =IFERROR(CONCATENATE(COPIA!DR220,COPIA!DX220),"") | D227: =IF(IFERROR(IF(COPIA!DS220=0,"",VALUE(CONCATENATE(COPIA!DS220,COPIA!$DY220))),"")=0,"",IFERROR(IF(COPIA!DS220=0,"",VALUE(CONCATENATE(COPIA!DS220,COPIA!$DY220))),"")) | E227: =IF(IFERROR(IF(COPIA!DT220=0,"",VALUE(CONCATENATE(COPIA!DT220,COPIA!$DY220))),"")=0,"",IFERROR(IF(COPIA!DT220=0,"",VALUE(CONCATENATE(COPIA!DT220,COPIA!$DY220))),"")) | F227: =IF(IFERROR(IF(COPIA!DU220=0,"",VALUE(CONCATENATE(COPIA!DU220,COPIA!$DZ220))),"")=0,"",IFERROR(IF(COPIA!DU220=0,"",VALUE(CONCATENATE(COPIA!DU220,COPIA!$DZ220))),"")) | G227: =IF(IFERROR(IF(COPIA!DV220=0,"",VALUE(CONCATENATE(COPIA!DV220,COPIA!$DZ220))),"")=0,"",IFERROR(IF(COPIA!DV220=0,"",VALUE(CONCATENATE(COPIA!DV220,COPIA!$DZ220))),"")) | H227: =IFERROR(COPIA!DW220,"") -> 0

Sheet SIT.PATR._SIT.ECON.
B1: SITUAZIONE CONTABILE PER DESTINAZIONE
B2: VISUALIZZA IL RISULTATO ECONOMICO | D2: =IF(COPIA!CH1=0,"",COPIA!ES1) | H2: OPZIONI DI STAMPA
B3: =IF(COPIA!CH1=0,"",COPIA!EU37) | H3: RIGHE TRA I PROSPETTI
B4: =IF(INDIRECT(ADDRESS(8,6,,,"LIBRO_GIORNALE"))="","",INDIRECT(ADDRESS(8,6,,,"LIBRO_GIORNALE"))) | D4: =IF(INDIRECT(ADDRESS(8,7,,,"LIBRO_GIORNALE"))="","",INDIRECT(ADDRESS(8,7,,,"LIBRO_GIORNALE")))
B5: =IF(COPIA!CH1=0,"",CONCATENATE("Situazione contabile per destinazione ","al", " ",COPIA!DS2,"/",COPIA!DT2,"/",COPIA!DU2))
B6: =IF(COPIA!CH1=0,"","SITUAZIONE PATRIMONIALE")
B7: =IF(COPIA!CH1=0,"","ATTIVITÀ") | D7: =IF(COPIA!CH1=0,"","PASSIVITÀ E NETTO")
B8: =IF((ROW())>=MAX(COPIA!$BV$2,COPIA!$BW$2)+COPIA!$CB$2,CONCATENATE((INDIRECT(ADDRESS(ROW()-MAX(COPIA!$BV$2,COPIA!$BW$2)-COPIA!$CC$2,87,4,,"COPIA"))),INDIRECT(ADDRESS(ROW()-MAX(COPIA!$BV$2,COPIA!$BW$2)-COPIA!$CC$2,96,4,,"COPIA"))),IF(AND(COPIA!$EO$1=TRUE,UPPER(COPIA!BZ3)="SALDO ECONOMICO NEGATIVO"),SUBSTITUTE(COPIA!BZ3,"SALDO ECONOMICO NEGATIVO","PERDITA D'ESERCIZIO"),UPPER(COPIA!BZ3))) | C8: =IFERROR(VALUE(IF((ROW())>=MAX(COPIA!$BV$2,COPIA!$BW$2)+COPIA!$CB$2,CONCATENATE((INDIRECT(ADDRESS(ROW()-MAX(COPIA!$BV$2,COPIA!$BW$2)-COPIA!$CC$2,88,4,,"COPIA"))),INDIRECT(ADDRESS(ROW()-MAX(COPIA!$BV$2,COPIA!$BW$2)-COPIA!$CC$2,137,4,,"COPIA"))),UPPER(COPIA!CA3))),"") -> 0 | D8: =IF((ROW())>=MAX(COPIA!$BV$2,COPIA!$BW$2)+COPIA!$CB$2,CONCATENATE((INDIRECT(ADDRESS(ROW()-MAX(COPIA!$BV$2,COPIA!$BW$2)-COPIA!$CC$2,138,4,,"COPIA"))),INDIRECT(ADDRESS(ROW()-MAX(COPIA!$BV$2,COPIA!$BW$2)-COPIA!$CC$2,135,4,,"COPIA"))),IF(AND($EO$4=TRUE,UPPER(COPIA!CB3)="SALDO ECONOMICO POSITIVO"),SUBSTITUTE(COPIA!CB3,"SALDO ECONOMICO POSITIVO","UTILE D'ESERCIZIO"),UPPER(COPIA!CB3))) | E8: =IFERROR(VALUE(IF((ROW())>=MAX(COPIA!$BV$2,COPIA!$BW$2)+COPIA!$CB$2,CONCATENATE((INDIRECT(ADDRESS(ROW()-MAX(COPIA!$BV$2,COPIA!$BW$2)-COPIA!$CC$2,136,4,,"COPIA"))),INDIRECT(ADDRESS(ROW()-MAX(COPIA!$BV$2,COPIA!$BW$2)-COPIA!$CC$2,95,4,,"COPIA"))),UPPER(COPIA!CC3))),"")
B9: =IF((ROW())>=MAX(COPIA!$BV$2,COPIA!$BW$2)+COPIA!$CB$2,CONCATENATE((INDIRECT(ADDRESS(ROW()-MAX(COPIA!$BV$2,COPIA!$BW$2)-COPIA!$CC$2,87,4,,"COPIA"))),INDIRECT(ADDRESS(ROW()-MAX(COPIA!$BV$2,COPIA!$BW$2)-COPIA!$CC$2,96,4,,"COPIA"))),IF(AND(COPIA!$EO$1=TRUE,UPPER(COPIA!BZ4)="SALDO ECONOMICO NEGATIVO"),SUBSTITUTE(COPIA!BZ4,"SALDO ECONOMICO NEGATIVO","PERDITA D'ESERCIZIO"),UPPER(COPIA!BZ4))) | C9: =IFERROR(VALUE(IF((ROW())>=MAX(COPIA!$BV$2,COPIA!$BW$2)+COPIA!$CB$2,CONCATENATE((INDIRECT(ADDRESS(ROW()-MAX(COPIA!$BV$2,COPIA!$BW$2)-COPIA!$CC$2,88,4,,"COPIA"))),INDIRECT(ADDRESS(ROW()-MAX(COPIA!$BV$2,COPIA!$BW$2)-COPIA!$CC$2,137,4,,"COPIA"))),UPPER(COPIA!CA4))),"") -> 0 | D9: =IF((ROW())>=MAX(COPIA!$BV$2,COPIA!$BW$2)+COPIA!$CB$2,CONCATENATE((INDIRECT(ADDRESS(ROW()-MAX(COPIA!$BV$2,COPIA!$BW$2)-COPIA!$CC$2,138,4,,"COPIA"))),INDIRECT(ADDRESS(ROW()-MAX(COPIA!$BV$2,COPIA!$BW$2)-COPIA!$CC$2,135,4,,"COPIA"))),IF(AND($EO$4=TRUE,UPPER(COPIA!CB4)="SALDO ECONOMICO POSITIVO"),SUBSTITUTE(COPIA!CB4,"SALDO ECONOMICO POSITIVO","UTILE D'ESERCIZIO"),UPPER(COPIA!CB4))) | E9: =IFERROR(VALUE(IF((ROW())>=MAX(COPIA!$BV$2,COPIA!$BW$2)+COPIA!$CB$2,CONCATENATE((INDIRECT(ADDRESS(ROW()-MAX(COPIA!$BV$2,COPIA!$BW$2)-COPIA!$CC$2,136,4,,"COPIA"))),INDIRECT(ADDRESS(ROW()-MAX(COPIA!$BV$2,COPIA!$BW$2)-COPIA!$CC$2,95,4,,"COPIA"))),UPPER(COPIA!CC4))),"")
B10: =IF((ROW())>=MAX(COPIA!$BV$2,COPIA!$BW$2)+COPIA!$CB$2,CONCATENATE((INDIRECT(ADDRESS(ROW()-MAX(COPIA!$BV$2,COPIA!$BW$2)-COPIA!$CC$2,87,4,,"COPIA"))),INDIRECT(ADDRESS(ROW()-MAX(COPIA!$BV$2,COPIA!$BW$2)-COPIA!$CC$2,96,4,,"COPIA"))),IF(AND(COPIA!$EO$1=TRUE,UPPER(COPIA!BZ5)="SALDO ECONOMICO NEGATIVO"),SUBSTITUTE(COPIA!BZ5,"SALDO ECONOMICO NEGATIVO","PERDITA D'ESERCIZIO"),UPPER(COPIA!BZ5))) | C10: =IFERROR(VALUE(IF((ROW())>=MAX(COPIA!$BV$2,COPIA!$BW$2)+COPIA!$CB$2,CONCATENATE((INDIRECT(ADDRESS(ROW()-MAX(COPIA!$BV$2,COPIA!$BW$2)-COPIA!$CC$2,88,4,,"COPIA"))),INDIRECT(ADDRESS(ROW()-MAX(COPIA!$BV$2,COPIA!$BW$2)-COPIA!$CC$2,137,4,,"COPIA"))),UPPER(COPIA!CA5))),"") -> 0 | D10: =IF((ROW())>=MAX(COPIA!$BV$2,COPIA!$BW$2)+COPIA!$CB$2,CONCATENATE((INDIRECT(ADDRESS(ROW()-MAX(COPIA!$BV$2,COPIA!$BW$2)-COPIA!$CC$2,138,4,,"COPIA"))),INDIRECT(ADDRESS(ROW()-MAX(COPIA!$BV$2,COPIA!$BW$2)-COPIA!$CC$2,135,4,,"COPIA"))),IF(AND($EO$4=TRUE,UPPER(COPIA!CB5)="SALDO ECONOMICO POSITIVO"),SUBSTITUTE(COPIA!CB5,"SALDO ECONOMICO POSITIVO","UTILE D'ESERCIZIO"),UPPER(COPIA!CB5))) | E10: =IFERROR(VALUE(IF((ROW())>=MAX(COPIA!$BV$2,COPIA!$BW$2)+COPIA!$CB$2,CONCATENATE((INDIRECT(ADDRESS(ROW()-MAX(COPIA!$BV$2,COPIA!$BW$2)-COPIA!$CC$2,136,4,,"COPIA"))),INDIRECT(ADDRESS(ROW()-MAX(COPIA!$BV$2,COPIA!$BW$2)-COPIA!$CC$2,95,4,,"COPIA"))),UPPER(COPIA!CC5))),"")
B11: =IF((ROW())>=MAX(COPIA!$BV$2,COPIA!$BW$2)+COPIA!$CB$2,CONCATENATE((INDIRECT(ADDRESS(ROW()-MAX(COPIA!$BV$2,COPIA!$BW$2)-COPIA!$CC$2,87,4,,"COPIA"))),INDIRECT(ADDRESS(ROW()-MAX(COPIA!$BV$2,COPIA!$BW$2)-COPIA!$CC$2,96,4,,"COPIA"))),IF(AND(COPIA!$EO$1=TRUE,UPPER(COPIA!BZ6)="SALDO ECONOMICO NEGATIVO"),SUBSTITUTE(COPIA!BZ6,"SALDO ECONOMICO NEGATIVO","PERDITA D'ESERCIZIO"),UPPER(COPIA!BZ6))) | C11: =IFERROR(VALUE(IF((ROW())>=MAX(COPIA!$BV$2,COPIA!$BW$2)+COPIA!$CB$2,CONCATENATE((INDIRECT(ADDRESS(ROW()-MAX(COPIA!$BV$2,COPIA!$BW$2)-COPIA!$CC$2,88,4,,"COPIA"))),INDIRECT(ADDRESS(ROW()-MAX(COPIA!$BV$2,COPIA!$BW$2)-COPIA!$CC$2,137,4,,"COPIA"))),UPPER(COPIA!CA6))),"") -> 0 | D11: =IF((ROW())>=MAX(COPIA!$BV$2,COPIA!$BW$2)+COPIA!$CB$2,CONCATENATE((INDIRECT(ADDRESS(ROW()-MAX(COPIA!$BV$2,COPIA!$BW$2)-COPIA!$CC$2,138,4,,"COPIA"))),INDIRECT(ADDRESS(ROW()-MAX(COPIA!$BV$2,COPIA!$BW$2)-COPIA!$CC$2,135,4,,"COPIA"))),IF(AND($EO$4=TRUE,UPPER(COPIA!CB6)="SALDO ECONOMICO POSITIVO"),SUBSTITUTE(COPIA!CB6,"SALDO ECONOMICO POSITIVO","UTILE D'ESERCIZIO"),UPPER(COPIA!CB6))) | E11: =IFERROR(VALUE(IF((ROW())>=MAX(COPIA!$BV$2,COPIA!$BW$2)+COPIA!$CB$2,CONCATENATE((INDIRECT(ADDRESS(ROW()-MAX(COPIA!$BV$2,COPIA!$BW$2)-COPIA!$CC$2,136,4,,"COPIA"))),INDIRECT(ADDRESS(ROW()-MAX(COPIA!$BV$2,COPIA!$BW$2)-COPIA!$CC$2,95,4,,"COPIA"))),UPPER(COPIA!CC6))),"")
