Workbook
Name anno_CORRENTE: COPIA!$AP$1
Name anno_inizio: COPIA!$AP$1
Name ANNO_SELEZIONATO: COPIA!$AR$1
Name ATTIVO: COPIA!$CD$3:$CI$103
Name AVERE: COPIA!$BE$3:$BE$400
Name avere_grezzo: COPIA!$AP$3:$AP$400
Name bilancio: COPIA!$AJ$3:$AJ$400
Name CLASSIFICAZIONE: COPIA!$AF$3:$AF$400
Name CODICE: COPIA!$AB$3:$AB$400
Name CODICE_BILANCIO: COPIA!$DY$3:$DY$400
Name CONTI_APERTI: COPIA!$CV$2:$CV$401
Name DARE: COPIA!$BD$3:$BD$400
Name dare_grezzo: COPIA!$AO$3:$AO$400
Name DATA: COPIA!$BA$3:$BA$400
Name data_grezzo: COPIA!$AL$3:$AL$400
Name DEN_G: COPIA!$BB$3:$BB$400
Name den_grezzo: COPIA!$AM$3:$AM$400
Name DEN_PDC: COPIA!$AC$3:$AC$400
Name DESCRIZIONE: COPIA!$BC$3:$BC$400
Name dest_grezzo: COPIA!$AK$3:$AK$400
Name DESTINAZIONE: COPIA!$AG$3:$AG$400
Name ECCEDENZA: COPIA!$AE$3:$AE$400
Name ECONOMICO: COPIA!$CD$191:$CI$247
Name ELENCO_CONTI: COPIA!$U$3:$U$401
Name FINE_A_PC: COPIA!$AM$2
Name FINE_AC: COPIA!$AR$2
Name FINE_ANNO_PREC: COPIA!$AJ$2
Name FINE_PERIODO: COPIA!$AP$2
Name FOCUS: OFFSET(COPIA!$CV$2,,,COPIA!$DB$1+1,1)
Name giornale_grezzo: COPIA!$AL$3:$AP$400
Name GIORNI: COPIA!$BF$15:$BF$45
Name INIZIO_A_PC: COPIA!$AO$2
Name INIZIO_AC: COPIA!$AQ$2
Name INIZIO_ANNO_PREC: COPIA!$AI$2
Name LIBRO_GIORNALE: COPIA!$AZ$3:$BE$400
Name MESI: COPIA!$BF$15:$BF$26
Name NASCONDI_RIGHE: COPIA!$BF$200:$BF$400
Name NATURA: COPIA!$AD$3:$AD$400
Name Num._riga: COPIA!$AZ$3:$AZ$400
Name PASSIVO: COPIA!$CD$105:$CI$189
Name PATRIMONIO_REDDITO: COPIA!$AH$3:$AH$400
Name PDC: COPIA!$AB$3:$AJ$400
Name progressivo: COPIA!$EP$3:$EP$400
Name RAGRUPPAMENTO: COPIA!$AI$3:$AI$400
Name RIGHE_TRA_I_PROSPETTI: COPIA!$BF$102:$BF$142
Name TENDINA_GIORNALE: OFFSET(COPIA!$U$3,,,COPIA!$V$1)
Name VALORI_INIZIALI: VALORI_INIZIALI!$B$9:$I$108

Sheet PIANO_DEI_CONTI
D1: PIANO DEI CONTI
D3: FORMA SOCIETARIA | F3: MODALITÀ DI CALCOLO DEL RISULTATO ECONOMICO | I3: RINOMINA I CONTI CON DENOMINAZIONE GENERICA
D4: SOCIETÀ PER AZIONI | F4: CALCOLO AUTOMATICO | I4: =IF(COPIA!A1=1,"1.BANCA X C/C - 2.BANCA Y C/C - 3.BANCA Z C/C","1.BANCA X C/C - 2.BANCA Y C/C - 3.BANCA Z C/C - 4.BANCA X C/VINCOLATO") -> 1.BANCA X C/C - 2.BANCA Y C/C - 3.BANCA Z C/C - 4.BANCA X C/VINCOLATO
D7: =CONCATENATE(B8," - DAL FASCICOLO ALLEGATO AL LIBRO DI TESTO Futuro impresa smart 4 - TE214FA TRAMONTANA") -> QUADRO DEI CONTI DI UN'IMPRESA INDUSTRIALE IN FORMA DI SPA - DAL FASCICOLO ALLEGATO AL LIBRO DI TESTO Futuro impresa smart 4 - TE214FA TRAMONTANA
B8: =IF(COPIA!A1=1," QUADRO DEI CONTI DI UN'IMPRESA COMMERCIALE IN FORMA DI SNC "," QUADRO DEI CONTI DI UN'IMPRESA INDUSTRIALE IN FORMA DI SPA ") -> QUADRO DEI CONTI DI UN'IMPRESA INDUSTRIALE IN FORMA DI SPA | D8: CODICE | E8: DENOMINANZIONE DEL CONTO | F8: NATURA | G8: ECCEDENZA | H8: CLASSIFICAZIONE | I8: DESTINAZIONE | J8: 1
D9: =IFERROR(IF(COPIA!A3<>0,COPIA!A3,""),"") -> 00.00 | E9: =IFERROR(IF(COPIA!B3<>0,COPIA!B3,""),"") -> CREDITI V/SOCI | F9: =IFERROR(IF(COPIA!C3<>0,COPIA!C3,""),"") | G9: =IFERROR(IF(COPIA!D3<>0,COPIA!D3,""),"") | H9: =IF(E9="FONDO SVALUTAZIONE CREDITI","RETTIFICA CREDITI",IFERROR(IF(COPIA!E3<>0,COPIA!E3,""),"")) | I9: =IFERROR(IF(COPIA!F3<>0,COPIA!F3,""),"") | J9: 2
D10: =IFERROR(IF(COPIA!A4<>0,COPIA!A4,""),"") -> 00.01 | E10: =IFERROR(IF(COPIA!B4<>0,COPIA!B4,""),"") -> AZIONISTI C/SOTTOSCRIZIONE | F10: =IFERROR(IF(COPIA!C4<>0,COPIA!C4,""),"") -> F | G10: =IFERROR(IF(COPIA!D4<>0,COPIA!D4,""),"") -> D | H10: =IF(E10="FONDO SVALUTAZIONE CREDITI","RETTIFICA CREDITI",IFERROR(IF(COPIA!E4<>0,COPIA!E4,""),"")) -> CREDITI | I10: =IFERROR(IF(COPIA!F4<>0,COPIA!F4,""),"") -> SP DARE | J10: 3
D11: =IFERROR(IF(COPIA!A5<>0,COPIA!A5,""),"") -> 00.02 | E11: =IFERROR(IF(COPIA!B5<>0,COPIA!B5,""),"") -> AZIONISTI C/VERSAMENTI RICHIAMATI | F11: =IFERROR(IF(COPIA!C5<>0,COPIA!C5,""),"") -> F | G11: =IFERROR(IF(COPIA!D5<>0,COPIA!D5,""),"") -> D | H11: =IF(E11="FONDO SVALUTAZIONE CREDITI","RETTIFICA CREDITI",IFERROR(IF(COPIA!E5<>0,COPIA!E5,""),"")) -> CREDITI | I11: =IFERROR(IF(COPIA!F5<>0,COPIA!F5,""),"") -> SP DARE | J11: =IF(COPIA!A1=1,"",4) -> 4
D12: =IFERROR(IF(COPIA!A6<>0,COPIA!A6,""),"") -> 00.03 | E12: =IFERROR(IF(COPIA!B6<>0,COPIA!B6,""),"") -> AZIONISTI C/REINTEGRO | F12: =IFERROR(IF(COPIA!C6<>0,COPIA!C6,""),"") -> F | G12: =IFERROR(IF(COPIA!D6<>0,COPIA!D6,""),"") -> D | H12: =IF(E12="FONDO SVALUTAZIONE CREDITI","RETTIFICA CREDITI",IFERROR(IF(COPIA!E6<>0,COPIA!E6,""),"")) -> CREDITI | I12: =IFERROR(IF(COPIA!F6<>0,COPIA!F6,""),"") -> SP DARE | K12: NOME DEI SOCI
D13: =IFERROR(IF(COPIA!A7<>0,COPIA!A7,""),"") -> 01.00 | E13: =IFERROR(IF(COPIA!B7<>0,COPIA!B7,""),"") -> IMMOBILIZZAZIONI IMMATERIALI | F13: =IFERROR(IF(COPIA!C7<>0,COPIA!C7,""),"") | G13: =IFERROR(IF(COPIA!D7<>0,COPIA!D7,""),"") | H13: =IF(E13="FONDO SVALUTAZIONE CREDITI","RETTIFICA CREDITI",IFERROR(IF(COPIA!E7<>0,COPIA!E7,""),"")) | I13: =IFERROR(IF(COPIA!F7<>0,COPIA!F7,""),"") | J13: A
D14: =IFERROR(IF(COPIA!A8<>0,COPIA!A8,""),"") -> 01.01 | E14: =IFERROR(IF(COPIA!B8<>0,COPIA!B8,""),"") -> COSTI DI IMPIANTO | F14: =IFERROR(IF(COPIA!C8<>0,COPIA!C8,""),"") -> E | G14: =IFERROR(IF(COPIA!D8<>0,COPIA!D8,""),"") -> D | H14: =IF(E14="FONDO SVALUTAZIONE CREDITI","RETTIFICA CREDITI",IFERROR(IF(COPIA!E8<>0,COPIA!E8,""),"")) -> COSTI PLURIENNALI | I14: =IFERROR(IF(COPIA!F8<>0,COPIA!F8,""),"") -> SP DARE | J14: B
D15: =IFERROR(IF(COPIA!A9<>0,COPIA!A9,""),"") -> 01.02 | E15: =IFERROR(IF(COPIA!B9<>0,COPIA!B9,""),"") -> COSTI DI AMPLIAMENTO | F15: =IFERROR(IF(COPIA!C9<>0,COPIA!C9,""),"") -> E | G15: =IFERROR(IF(COPIA!D9<>0,COPIA!D9,""),"") -> D | H15: =IF(E15="FONDO SVALUTAZIONE CREDITI","RETTIFICA CREDITI",IFERROR(IF(COPIA!E9<>0,COPIA!E9,""),"")) -> COSTI PLURIENNALI | I15: =IFERROR(IF(COPIA!F9<>0,COPIA!F9,""),"") -> SP DARE | J15: C
D16: =IFERROR(IF(COPIA!A10<>0,COPIA!A10,""),"") -> 01.03 | E16: =IFERROR(IF(COPIA!B10<>0,COPIA!B10,""),"") -> COSTI DI SVILUPPO | F16: =IFERROR(IF(COPIA!C10<>0,COPIA!C10,""),"") -> E | G16: =IFERROR(IF(COPIA!D10<>0,COPIA!D10,""),"") -> D | H16: =IF(E16="FONDO SVALUTAZIONE CREDITI","RETTIFICA CREDITI",IFERROR(IF(COPIA!E10<>0,COPIA!E10,""),"")) -> COSTI PLURIENNALI | I16: =IFERROR(IF(COPIA!F10<>0,COPIA!F10,""),"") -> SP DARE | J16: D
D17: =IFERROR(IF(COPIA!A11<>0,COPIA!A11,""),"") -> 01.04 | E17: =IFERROR(IF(COPIA!B11<>0,COPIA!B11,""),"") -> BREVETTI | F17: =IFERROR(IF(COPIA!C11<>0,COPIA!C11,""),"") -> E | G17: =IFERROR(IF(COPIA!D11<>0,COPIA!D11,""),"") -> D | H17: =IF(E17="FONDO SVALUTAZIONE CREDITI","RETTIFICA CREDITI",IFERROR(IF(COPIA!E11<>0,COPIA!E11,""),"")) -> COSTI PLURIENNALI | I17: =IFERROR(IF(COPIA!F11<>0,COPIA!F11,""),"") -> SP DARE
D18: =IFERROR(IF(COPIA!A12<>0,COPIA!A12,""),"") -> 01.05 | E18: =IFERROR(IF(COPIA!B12<>0,COPIA!B12,""),"") -> SOFTWARE | F18: =IFERROR(IF(COPIA!C12<>0,COPIA!C12,""),"") -> E | G18: =IFERROR(IF(COPIA!D12<>0,COPIA!D12,""),"") -> D | H18: =IF(E18="FONDO SVALUTAZIONE CREDITI","RETTIFICA CREDITI",IFERROR(IF(COPIA!E12<>0,COPIA!E12,""),"")) -> COSTI PLURIENNALI | I18: =IFERROR(IF(COPIA!F12<>0,COPIA!F12,""),"") -> SP DARE
D19: =IFERROR(IF(COPIA!A13<>0,COPIA!A13,""),"") -> 01.06 | E19: =IFERROR(IF(COPIA!B13<>0,COPIA!B13,""),"") -> AVVIAMENTO | F19: =IFERROR(IF(COPIA!C13<>0,COPIA!C13,""),"") -> E | G19: =IFERROR(IF(COPIA!D13<>0,COPIA!D13,""),"") -> D | H19: =IF(E19="FONDO SVALUTAZIONE CREDITI","RETTIFICA CREDITI",IFERROR(IF(COPIA!E13<>0,COPIA!E13,""),"")) -> COSTI PLURIENNALI | I19: =IFERROR(IF(COPIA!F13<>0,COPIA!F13,""),"") -> SP DARE
D20: =IFERROR(IF(COPIA!A14<>0,COPIA!A14,""),"") -> 01.11 | E20: =IFERROR(IF(COPIA!B14<>0,COPIA!B14,""),"") -> FONDO AMMORTAMENTO COSTI DI IMPIANTO | F20: =IFERROR(IF(COPIA!C14<>0,COPIA!C14,""),"") -> E | G20: =IFERROR(IF(COPIA!D14<>0,COPIA!D14,""),"") -> A | H20: =IF(E20="FONDO SVALUTAZIONE CREDITI","RETTIFICA CREDITI",IFERROR(IF(COPIA!E14<>0,COPIA!E14,""),"")) -> RETTIFICHE COSTI PLURIENNALI | I20: =IFERROR(IF(COPIA!F14<>0,COPIA!F14,""),"") -> SP AVERE
D21: =IFERROR(IF(COPIA!A15<>0,COPIA!A15,""),"") -> 01.12 | E21: =IFERROR(IF(COPIA!B15<>0,COPIA!B15,""),"") -> FONDO AMMORTAMENTO COSTI DI AMPLIAMENTO | F21: =IFERROR(IF(COPIA!C15<>0,COPIA!C15,""),"") -> E | G21: =IFERROR(IF(COPIA!D15<>0,COPIA!D15,""),"") -> A | H21: =IF(E21="FONDO SVALUTAZIONE CREDITI","RETTIFICA CREDITI",IFERROR(IF(COPIA!E15<>0,COPIA!E15,""),"")) -> RETTIFICHE COSTI PLURIENNALI | I21: =IFERROR(IF(COPIA!F15<>0,COPIA!F15,""),"") -> SP AVERE
D22: =IFERROR(IF(COPIA!A16<>0,COPIA!A16,""),"") -> 01.13 | E22: =IFERROR(IF(COPIA!B16<>0,COPIA!B16,""),"") -> FONDO AMMORTAMENTO COSTI DI SVILUPPO | F22: =IFERROR(IF(COPIA!C16<>0,COPIA!C16,""),"") -> E | G22: =IFERROR(IF(COPIA!D16<>0,COPIA!D16,""),"") -> A | H22: =IF(E22="FONDO SVALUTAZIONE CREDITI","RETTIFICA CREDITI",IFERROR(IF(COPIA!E16<>0,COPIA!E16,""),"")) -> RETTIFICHE COSTI PLURIENNALI | I22: =IFERROR(IF(COPIA!F16<>0,COPIA!F16,""),"") -> SP AVERE
D23: =IFERROR(IF(COPIA!A17<>0,COPIA!A17,""),"") -> 01.14 | E23: =IFERROR(IF(COPIA!B17<>0,COPIA!B17,""),"") -> FONDO AMMORTAMENTO BREVETTI | F23: =IFERROR(IF(COPIA!C17<>0,COPIA!C17,""),"") -> E | G23: =IFERROR(IF(COPIA!D17<>0,COPIA!D17,""),"") -> A | H23: =IF(E23="FONDO SVALUTAZIONE CREDITI","RETTIFICA CREDITI",IFERROR(IF(COPIA!E17<>0,COPIA!E17,""),"")) -> RETTIFICHE COSTI PLURIENNALI | I23: =IFERROR(IF(COPIA!F17<>0,COPIA!F17,""),"") -> SP AVERE
D24: =IFERROR(IF(COPIA!A18<>0,COPIA!A18,""),"") -> 01.15 | E24: =IFERROR(IF(COPIA!B18<>0,COPIA!B18,""),"") -> FONDO AMMORTAMENTO SOFTWARE | F24: =IFERROR(IF(COPIA!C18<>0,COPIA!C18,""),"") -> E | G24: =IFERROR(IF(COPIA!D18<>0,COPIA!D18,""),"") -> A | H24: =IF(E24="FONDO SVALUTAZIONE CREDITI","RETTIFICA CREDITI",IFERROR(IF(COPIA!E18<>0,COPIA!E18,""),"")) -> RETTIFICHE COSTI PLURIENNALI | I24: =IFERROR(IF(COPIA!F18<>0,COPIA!F18,""),"") -> SP AVERE
D25: =IFERROR(IF(COPIA!A19<>0,COPIA!A19,""),"") -> 01.16 | E25: =IFERROR(IF(COPIA!B19<>0,COPIA!B19,""),"") -> FONDO AMMORTAMENTO AVVIAMENTO | F25: =IFERROR(IF(COPIA!C19<>0,COPIA!C19,""),"") -> E | G25: =IFERROR(IF(COPIA!D19<>0,COPIA!D19,""),"") -> A | H25: =IF(E25="FONDO SVALUTAZIONE CREDITI","RETTIFICA CREDITI",IFERROR(IF(COPIA!E19<>0,COPIA!E19,""),"")) -> RETTIFICHE COSTI PLURIENNALI | I25: =IFERROR(IF(COPIA!F19<>0,COPIA!F19,""),"") -> SP AVERE
D26: =IFERROR(IF(COPIA!A20<>0,COPIA!A20,""),"") -> 01.30 | E26: =IFERROR(IF(COPIA!B20<>0,COPIA!B20,""),"") -> IMMOBILIZZAZIONI IMMATERIALI IN CORSO | F26: =IFERROR(IF(COPIA!C20<>0,COPIA!C20,""),"") -> E | G26: =IFERROR(IF(COPIA!D20<>0,COPIA!D20,""),"") -> D | H26: =IF(E26="FONDO SVALUTAZIONE CREDITI","RETTIFICA CREDITI",IFERROR(IF(COPIA!E20<>0,COPIA!E20,""),"")) -> COSTI PLURIENNALI | I26: =IFERROR(IF(COPIA!F20<>0,COPIA!F20,""),"") -> SP DARE
D27: =IFERROR(IF(COPIA!A21<>0,COPIA!A21,""),"") -> 01.31 | E27: =IFERROR(IF(COPIA!B21<>0,COPIA!B21,""),"") -> FORNITORI IMMOBILIZZAZIONI IMMATERIALI C/ACCONTI | F27: =IFERROR(IF(COPIA!C21<>0,COPIA!C21,""),"") -> F | G27: =IFERROR(IF(COPIA!D21<>0,COPIA!D21,""),"") -> D | H27: =IF(E27="FONDO SVALUTAZIONE CREDITI","RETTIFICA CREDITI",IFERROR(IF(COPIA!E21<>0,COPIA!E21,""),"")) -> CREDITI | I27: =IFERROR(IF(COPIA!F21<>0,COPIA!F21,""),"") -> SP DARE
D28: =IFERROR(IF(COPIA!A22<>0,COPIA!A22,""),"") -> 02.00 | E28: =IFERROR(IF(COPIA!B22<>0,COPIA!B22,""),"") -> IMMOBILIZZAZIONI MATERIALI | F28: =IFERROR(IF(COPIA!C22<>0,COPIA!C22,""),"") | G28: =IFERROR(IF(COPIA!D22<>0,COPIA!D22,""),"") | H28: =IF(E28="FONDO SVALUTAZIONE CREDITI","RETTIFICA CREDITI",IFERROR(IF(COPIA!E22<>0,COPIA!E22,""),"")) | I28: =IFERROR(IF(COPIA!F22<>0,COPIA!F22,""),"")
... D220: =IFERROR(IF(COPIA!A214<>0,COPIA!A214,""),"") -> 21.12 | E220: =IFERROR(IF(COPIA!B214<>0,COPIA!B214,""),"") -> PRODOTTI FINITI C/RIMANENZE FINALI | F220: =IFERROR(IF(COPIA!C214<>0,COPIA!C214,""),"") -> E | G220: =IFERROR(IF(COPIA!D214<>0,COPIA!D214,""),"") -> A | H220: =IF(E220="FONDO SVALUTAZIONE CREDITI","RETTIFICA CREDITI",IFERROR(IF(COPIA!E214<>0,COPIA!E214,""),"")) -> RETTIFICHE COSTI D'ESERCIZIO | I220: =IFERROR(IF(COPIA!F214<>0,COPIA!F214,""),"") -> SE AVERE
D221: =IFERROR(IF(COPIA!A215<>0,COPIA!A215,""),"") -> 30.00 | E221: =IFERROR(IF(COPIA!B215<>0,COPIA!B215,""),"") -> COSTI DELLE MATERIE | F221: =IFERROR(IF(COPIA!C215<>0,COPIA!C215,""),"") | G221: =IFERROR(IF(COPIA!D215<>0,COPIA!D215,""),"") | H221: =IF(E221="FONDO SVALUTAZIONE CREDITI","RETTIFICA CREDITI",IFERROR(IF(COPIA!E215<>0,COPIA!E215,""),"")) | I221: =IFERROR(IF(COPIA!F215<>0,COPIA!F215,""),"") | K221: 3
D222: =IFERROR(IF(COPIA!A216<>0,COPIA!A216,""),"") -> 30.01 | E222: =IFERROR(IF(COPIA!B216<>0,COPIA!B216,""),"") -> MATERIE PRIME C/ACQUISTI | F222: =IFERROR(IF(COPIA!C216<>0,COPIA!C216,""),"") -> E | G222: =IFERROR(IF(COPIA!D216<>0,COPIA!D216,""),"") -> D | H222: =IF(E222="FONDO SVALUTAZIONE CREDITI","RETTIFICA CREDITI",IFERROR(IF(COPIA!E216<>0,COPIA!E216,""),"")) -> COSTI D'ESERCIZIO | I222: =IFERROR(IF(COPIA!F216<>0,COPIA!F216,""),"") -> SE DARE
D223: =IFERROR(IF(COPIA!A217<>0,COPIA!A217,""),"") -> 30.02 | E223: =IFERROR(IF(COPIA!B217<>0,COPIA!B217,""),"") -> MATERIE SUSSIDIARIE C/ACQUISTI | F223: =IFERROR(IF(COPIA!C217<>0,COPIA!C217,""),"") -> E | G223: =IFERROR(IF(COPIA!D217<>0,COPIA!D217,""),"") -> D | H223: =IF(E223="FONDO SVALUTAZIONE CREDITI","RETTIFICA CREDITI",IFERROR(IF(COPIA!E217<>0,COPIA!E217,""),"")) -> COSTI D'ESERCIZIO | I223: =IFERROR(IF(COPIA!F217<>0,COPIA!F217,""),"") -> SE DARE
D224: =IFERROR(IF(COPIA!A218<>0,COPIA!A218,""),"") -> 30.03 | E224: =IFERROR(IF(COPIA!B218<>0,COPIA!B218,""),"") -> MATERIE DI CONSUMO C/ACQUISTI | F224: =IFERROR(IF(COPIA!C218<>0,COPIA!C218,""),"") -> E | G224: =IFERROR(IF(COPIA!D218<>0,COPIA!D218,""),"") -> D | H224: =IF(E224="FONDO SVALUTAZIONE CREDITI","RETTIFICA CREDITI",IFERROR(IF(COPIA!E218<>0,COPIA!E218,""),"")) -> COSTI D'ESERCIZIO | I224: =IFERROR(IF(COPIA!F218<>0,COPIA!F218,""),"") -> SE DARE
D225: =IFERROR(IF(COPIA!A219<>0,COPIA!A219,""),"") -> 30.04 | E225: =IFERROR(IF(COPIA!B219<>0,COPIA!B219,""),"") -> MATERIE C/APPORTI | F225: =IFERROR(IF(COPIA!C219<>0,COPIA!C219,""),"") -> E | G225: =IFERROR(IF(COPIA!D219<>0,COPIA!D219,""),"") -> D | H225: =IF(E225="FONDO SVALUTAZIONE CREDITI","RETTIFICA CREDITI",IFERROR(IF(COPIA!E219<>0,COPIA!E219,""),"")) -> COSTI D'ESERCIZIO | I225: =IFERROR(IF(COPIA!F219<>0,COPIA!F219,""),"") -> SE DARE
D226: =IFERROR(IF(COPIA!A220<>0,COPIA!A220,""),"") -> 30.10 | E226: =IFERROR(IF(COPIA!B220<>0,COPIA!B220,""),"") -> RESI SU ACQUISTI | F226: =IFERROR(IF(COPIA!C220<>0,COPIA!C220,""),"") -> E | G226: =IFERROR(IF(COPIA!D220<>0,COPIA!D220,""),"") -> A | H226: =IF(E226="FONDO SVALUTAZIONE CREDITI","RETTIFICA CREDITI",IFERROR(IF(COPIA!E220<>0,COPIA!E220,""),"")) -> RETTIFICHE COSTI D'ESERCIZIO | I226: =IFERROR(IF(COPIA!F220<>0,COPIA!F220,""),"") -> SE AVERE
D227: =IFERROR(IF(COPIA!A221<>0,COPIA!A221,""),"") -> 30.11 | E227: =IFERROR(IF(COPIA!B221<>0,COPIA!B221,""),"") -> RIBASSI E ABBUONI ATTIVI | F227: =IFERROR(IF(COPIA!C221<>0,COPIA!C221,""),"") -> E | G227: =IFERROR(IF(COPIA!D221<>0,COPIA!D221,""),"") -> A | H227: =IF(E227="FONDO SVALUTAZIONE CREDITI","RETTIFICA CREDITI",IFERROR(IF(COPIA!E221<>0,COPIA!E221,""),"")) -> RETTIFICHE COSTI D'ESERCIZIO | I227: =IFERROR(IF(COPIA!F221<>0,COPIA!F221,""),"") -> SE AVERE
D228: =IFERROR(IF(COPIA!A222<>0,COPIA!A222,""),"") -> 30.12 | E228: =IFERROR(IF(COPIA!B222<>0,COPIA!B222,""),"") -> PREMI SU ACQUISTI | F228: =IFERROR(IF(COPIA!C222<>0,COPIA!C222,""),"") -> E | G228: =IFERROR(IF(COPIA!D222<>0,COPIA!D222,""),"") -> A | H228: =IF(E228="FONDO SVALUTAZIONE CREDITI","RETTIFICA CREDITI",IFERROR(IF(COPIA!E222<>0,COPIA!E222,""),"")) -> RETTIFICHE COSTI D'ESERCIZIO | I228: =IFERROR(IF(COPIA!F222<>0,COPIA!F222,""),"") -> SE AVERE
D229: =IFERROR(IF(COPIA!A223<>0,COPIA!A223,""),"") -> 31.00 | E229: =IFERROR(IF(COPIA!B223<>0,COPIA!B223,""),"") -> COSTI PER SERVIZI | F229: =IFERROR(IF(COPIA!C223<>0,COPIA!C223,""),"") | G229: =IFERROR(IF(COPIA!D223<>0,COPIA!D223,""),"") | H229: =IF(E229="FONDO SVALUTAZIONE CREDITI","RETTIFICA CREDITI",IFERROR(IF(COPIA!E223<>0,COPIA!E223,""),"")) | I229: =IFERROR(IF(COPIA!F223<>0,COPIA!F223,""),"")
D230: =IFERROR(IF(COPIA!A224<>0,COPIA!A224,""),"") -> 31.01 | E230: =IFERROR(IF(COPIA!B224<>0,COPIA!B224,""),"") -> COSTI DI TRASPORTO | F230: =IFERROR(IF(COPIA!C224<>0,COPIA!C224,""),"") -> E | G230: =IFERROR(IF(COPIA!D224<>0,COPIA!D224,""),"") -> D | H230: =IF(E230="FONDO SVALUTAZIONE CREDITI","RETTIFICA CREDITI",IFERROR(IF(COPIA!E224<>0,COPIA!E224,""),"")) -> COSTI D'ESERCIZIO | I230: =IFERROR(IF(COPIA!F224<>0,COPIA!F224,""),"") -> SE DARE
D231: =IFERROR(IF(COPIA!A225<>0,COPIA!A225,""),"") -> 31.02 | E231: =IFERROR(IF(COPIA!B225<>0,COPIA!B225,""),"") -> COSTI PER ENERGIA | F231: =IFERROR(IF(COPIA!C225<>0,COPIA!C225,""),"") -> E | G231: =IFERROR(IF(COPIA!D225<>0,COPIA!D225,""),"") -> D | H231: =IF(E231="FONDO SVALUTAZIONE CREDITI","RETTIFICA CREDITI",IFERROR(IF(COPIA!E225<>0,COPIA!E225,""),"")) -> COSTI D'ESERCIZIO | I231: =IFERROR(IF(COPIA!F225<>0,COPIA!F225,""),"") -> SE DARE
D232: =IFERROR(IF(COPIA!A226<>0,COPIA!A226,""),"") -> 31.03 | E232: =IFERROR(IF(COPIA!B226<>0,COPIA!B226,""),"") -> PUBBLICITÀ | F232: =IFERROR(IF(COPIA!C226<>0,COPIA!C226,""),"") -> E | G232: =IFERROR(IF(COPIA!D226<>0,COPIA!D226,""),"") -> D | H232: =IF(E232="FONDO SVALUTAZIONE CREDITI","RETTIFICA CREDITI",IFERROR(IF(COPIA!E226<>0,COPIA!E226,""),"")) -> COSTI D'ESERCIZIO | I232: =IFERROR(IF(COPIA!F226<>0,COPIA!F226,""),"") -> SE DARE
D233: =IFERROR(IF(COPIA!A227<>0,COPIA!A227,""),"") -> 31.04 | E233: =IFERROR(IF(COPIA!B227<>0,COPIA!B227,""),"") -> CONSULENZE | F233: =IFERROR(IF(COPIA!C227<>0,COPIA!C227,""),"") -> E | G233: =IFERROR(IF(COPIA!D227<>0,COPIA!D227,""),"") -> D | H233: =IF(E233="FONDO SVALUTAZIONE CREDITI","RETTIFICA CREDITI",IFERROR(IF(COPIA!E227<>0,COPIA!E227,""),"")) -> COSTI D'ESERCIZIO | I233: =IFERROR(IF(COPIA!F227<>0,COPIA!F227,""),"") -> SE DARE
... D399: =IFERROR(IF(COPIA!A393<>0,COPIA!A393,""),"") | E399: =IFERROR(IF(COPIA!B393<>0,COPIA!B393,""),"") | F399: =IFERROR(IF(COPIA!C393<>0,COPIA!C393,""),"") | G399: =IFERROR(IF(COPIA!D393<>0,COPIA!D393,""),"") | H399: =IF(E399="FONDO SVALUTAZIONE CREDITI","RETTIFICA CREDITI",IFERROR(IF(COPIA!E393<>0,COPIA!E393,""),"")) | I399: =IFERROR(IF(COPIA!F393<>0,COPIA!F393,""),"")

Sheet LIBRO_GIORNALE
B1: LIBRO GIORNALE | K1: =IF(COPIA!AL1=1,"esercizio n",IF(COPIA!AL1=2,"esercizio n+1",IF(COPIA!AL1=3,"esercizio n+2",IF(COPIA!AL1=4,"esercizio n+3",IF(COPIA!AL1=5,"esercizio n+4",IF(COPIA!AL1=6,"esercizio n+5","")))))) -> esercizio n | O1: =INDEX($M$11:$N$210,MATCH(MAX($M$11:$M$308),$M$11:$M$210,0),2) -> 0
B2: SCEGLI LA VERSIONE | E2: CONTI SUDDIVISI PER RAGGRUPPAMENTO | F2: =IF(COPIA!CO1=0,"",CONCATENATE("Articoli registrati: ",COUNTIFS(K11:K308,"="&0))) | G2: TOT. DARE | H2: TOT.AVERE | K2: =IF(COPIA!CO1=0,"",IF(AND(COPIA!$I$1=1,VALORI_INIZIALI!H4<>VALORI_INIZIALI!I4),"I valori inziali non bilanciano.",IF(AND(COPIA!$I$1=1,VALORI_INIZIALI!H4=VALORI_INIZIALI!I4,VALORI_INIZIALI!$H$4>0,VALORI_INIZIALI!$I$4>0),"Sono presenti valori iniziali.",IF(AND(COPIA!$I$1=2,OR(VALORI_INIZIALI!$H$4>0,VALORI_INIZIALI!$I$4>0)),"Sono presenti valori iniziali.","Non sono presenti valori iniziali.")))) | O2: =IFERROR(INDEX($M$11:$N$210,MATCH(MAX($M$11:$M$308)-1,$M$11:$M$210,0),2),0) -> 0
B3: Desktop: Office | E3: =IF(INDIRECT(ADDRESS(3,2,,,))="Cloud: Office 365","VERSIONE OFFICE 365","") | F3: =COPIA!FG1 | G3: =K1 -> esercizio n
B4: Periodo di riferimento dei prospetti | F4: =K2 | G4: =ROUND(SUMIFS(INDIRECT(CONCATENATE(ADDRESS(11,7,,,),":",ADDRESS(210,7,,,))),INDIRECT(CONCATENATE(ADDRESS(11,4,,,),":",ADDRESS(210,4,,,))),"<="&FINE_AC,INDIRECT(CONCATENATE(ADDRESS(11,4,,,),":",ADDRESS(210,4,,,))),">="&INIZIO_AC),2) -> 0 | H4: =ROUND(SUMIFS(INDIRECT(CONCATENATE(ADDRESS(11,8,,,),":",ADDRESS(210,8,,,))),INDIRECT(CONCATENATE(ADDRESS(11,4,,,),":",ADDRESS(210,4,,,))),"<="&FINE_AC,INDIRECT(CONCATENATE(ADDRESS(11,4,,,),":",ADDRESS(210,4,,,))),">="&INIZIO_AC),2) -> 0
B5: 31 | C5: 12 | D5: N | E5: =IF(INDIRECT(ADDRESS(3,2,,,))<>"Cloud: Office 365","ATTIVA LA VERSIONE ONLINE","") -> ATTIVA LA VERSIONE ONLINE
B6: gg | C6: mm | D6: aa | F6: DELIMITAZIONE ARTICOLO ATTIVATA | G6: Nascondi riga dalla n. | H6: ATTIVA
B7: PIANO DEI CONTI SELEZIONATO | F7: STUDENTE | G7: ATTIVITÀ
B8: =IF(INDIRECT(ADDRESS(4,4,,,"PIANO_DEI_CONTI"))="Adatta ad una S.r.l. solo alcuni dei conti della S.p.A.","Società a responsabilità limitata",INDIRECT(ADDRESS(4,4,,,"PIANO_DEI_CONTI"))) -> SOCIETÀ PER AZIONI
E9: . | L9: =L10+5 -> 2031
B10: Codice | C10: Nr. riga | D10: DATA | E10: DENOMINAZIONE DEI CONTI | F10: DESCRIZIONE | G10: DARE | H10: AVERE | L10: =COPIA!$AP$1 -> 2026
B11: =IF(INDIRECT(ADDRESS(ROW(),4,,,))="","",IFERROR(INDEX(PDC,MATCH(INDIRECT(ADDRESS(ROW(),5,,,)),DEN_PDC,0),1),0)) | C11: =IF(INDIRECT(ADDRESS(ROW(),5,,,))<>"",ROW()-10,"") | K11: =IF(IF(COPIA!$R$1=TRUE,IF(OR(G11<>0,H11<>0),ROUND(SUM(G$11:G11),2)-ROUND(SUM(H$11:H11),2),""),"")<>0,"",0) | L11: =IF(INDIRECT(ADDRESS(ROW(),4,4,,))<>"",YEAR(INDIRECT(ADDRESS(ROW(),4,4,,))),0) -> 0 | M11: =IFERROR(IF(AND(INDIRECT(ADDRESS(ROW(),4,,,))<=COPIA!$DA$1,K11=0,COPIA!$BF$1>1,ROW()-10<COPIA!$BF$1-1),MAX($M$10:M10)+1,IF(AND(INDIRECT(ADDRESS(ROW(),4,,,))<=COPIA!$DA$1,K11=0,COPIA!$BF$1=1),MAX($M$10:M10)+1,0)),0) -> 0 | N11: =IF(AND(COPIA!$BF$1=1,M11<>0),ROW()-10,IF(AND(COPIA!$BF$1>1,ROW()-10>COPIA!$BF$1,M11<>0),0,IF(AND(COPIA!$BF$1>1,ROW()-10<=COPIA!$BF$1,M11<>0),ROW()-10,0))) -> 0 | O11: =IF(AND($O$1=0,ROW()-10<=$O$2),MAX($O$10:O10)+1,IF(AND(ROW()-10>$O$2,ROW()-10<=$O$1),ROW()-10,0)) -> 0 | P11: =IF(O11>0,MAX($P$10:P10)+1,0) -> 0
B12: =IF(INDIRECT(ADDRESS(ROW(),4,,,))="","",IFERROR(INDEX(PDC,MATCH(INDIRECT(ADDRESS(ROW(),5,,,)),DEN_PDC,0),1),0)) | C12: =IF(INDIRECT(ADDRESS(ROW(),5,,,))<>"",ROW()-10,"") | K12: =IF(IF(COPIA!$R$1=TRUE,IF(OR(G12<>0,H12<>0),ROUND(SUM(G$11:G12),2)-ROUND(SUM(H$11:H12),2),""),"")<>0,"",0) | L12: =IF(INDIRECT(ADDRESS(ROW(),4,4,,))<>"",YEAR(INDIRECT(ADDRESS(ROW(),4,4,,))),0) -> 0 | M12: =IFERROR(IF(AND(INDIRECT(ADDRESS(ROW(),4,,,))<=COPIA!$DA$1,K12=0,COPIA!$BF$1>1,ROW()-10<COPIA!$BF$1-1),MAX($M$10:M11)+1,IF(AND(INDIRECT(ADDRESS(ROW(),4,,,))<=COPIA!$DA$1,K12=0,COPIA!$BF$1=1),MAX($M$10:M11)+1,0)),0) -> 0 | N12: =IF(AND(COPIA!$BF$1=1,M12<>0),ROW()-10,IF(AND(COPIA!$BF$1>1,ROW()-10>COPIA!$BF$1,M12<>0),0,IF(AND(COPIA!$BF$1>1,ROW()-10<=COPIA!$BF$1,M12<>0),ROW()-10,0))) -> 0 | O12: =IF(AND($O$1=0,ROW()-10<=$O$2),MAX($O$10:O11)+1,IF(AND(ROW()-10>$O$2,ROW()-10<=$O$1),ROW()-10,0)) -> 0 | P12: =IF(O12>0,MAX($P$10:P11)+1,0) -> 0
B13: =IF(INDIRECT(ADDRESS(ROW(),4,,,))="","",IFERROR(INDEX(PDC,MATCH(INDIRECT(ADDRESS(ROW(),5,,,)),DEN_PDC,0),1),0)) | C13: =IF(INDIRECT(ADDRESS(ROW(),5,,,))<>"",ROW()-10,"") | K13: =IF(IF(COPIA!$R$1=TRUE,IF(OR(G13<>0,H13<>0),ROUND(SUM(G$11:G13),2)-ROUND(SUM(H$11:H13),2),""),"")<>0,"",0) | L13: =IF(INDIRECT(ADDRESS(ROW(),4,4,,))<>"",YEAR(INDIRECT(ADDRESS(ROW(),4,4,,))),0) -> 0 | M13: =IFERROR(IF(AND(INDIRECT(ADDRESS(ROW(),4,,,))<=COPIA!$DA$1,K13=0,COPIA!$BF$1>1,ROW()-10<COPIA!$BF$1-1),MAX($M$10:M12)+1,IF(AND(INDIRECT(ADDRESS(ROW(),4,,,))<=COPIA!$DA$1,K13=0,COPIA!$BF$1=1),MAX($M$10:M12)+1,0)),0) -> 0 | N13: =IF(AND(COPIA!$BF$1=1,M13<>0),ROW()-10,IF(AND(COPIA!$BF$1>1,ROW()-10>COPIA!$BF$1,M13<>0),0,IF(AND(COPIA!$BF$1>1,ROW()-10<=COPIA!$BF$1,M13<>0),ROW()-10,0))) -> 0 | O13: =IF(AND($O$1=0,ROW()-10<=$O$2),MAX($O$10:O12)+1,IF(AND(ROW()-10>$O$2,ROW()-10<=$O$1),ROW()-10,0)) -> 0 | P13: =IF(O13>0,MAX($P$10:P12)+1,0) -> 0
B14: =IF(INDIRECT(ADDRESS(ROW(),4,,,))="","",IFERROR(INDEX(PDC,MATCH(INDIRECT(ADDRESS(ROW(),5,,,)),DEN_PDC,0),1),0)) | C14: =IF(INDIRECT(ADDRESS(ROW(),5,,,))<>"",ROW()-10,"") | K14: =IF(IF(COPIA!$R$1=TRUE,IF(OR(G14<>0,H14<>0),ROUND(SUM(G$11:G14),2)-ROUND(SUM(H$11:H14),2),""),"")<>0,"",0) | L14: =IF(INDIRECT(ADDRESS(ROW(),4,4,,))<>"",YEAR(INDIRECT(ADDRESS(ROW(),4,4,,))),0) -> 0 | M14: =IFERROR(IF(AND(INDIRECT(ADDRESS(ROW(),4,,,))<=COPIA!$DA$1,K14=0,COPIA!$BF$1>1,ROW()-10<COPIA!$BF$1-1),MAX($M$10:M13)+1,IF(AND(INDIRECT(ADDRESS(ROW(),4,,,))<=COPIA!$DA$1,K14=0,COPIA!$BF$1=1),MAX($M$10:M13)+1,0)),0) -> 0 | N14: =IF(AND(COPIA!$BF$1=1,M14<>0),ROW()-10,IF(AND(COPIA!$BF$1>1,ROW()-10>COPIA!$BF$1,M14<>0),0,IF(AND(COPIA!$BF$1>1,ROW()-10<=COPIA!$BF$1,M14<>0),ROW()-10,0))) -> 0 | O14: =IF(AND($O$1=0,ROW()-10<=$O$2),MAX($O$10:O13)+1,IF(AND(ROW()-10>$O$2,ROW()-10<=$O$1),ROW()-10,0)) -> 0 | P14: =IF(O14>0,MAX($P$10:P13)+1,0) -> 0
B15: =IF(INDIRECT(ADDRESS(ROW(),4,,,))="","",IFERROR(INDEX(PDC,MATCH(INDIRECT(ADDRESS(ROW(),5,,,)),DEN_PDC,0),1),0)) | C15: =IF(INDIRECT(ADDRESS(ROW(),5,,,))<>"",ROW()-10,"") | K15: =IF(IF(COPIA!$R$1=TRUE,IF(OR(G15<>0,H15<>0),ROUND(SUM(G$11:G15),2)-ROUND(SUM(H$11:H15),2),""),"")<>0,"",0) | L15: =IF(INDIRECT(ADDRESS(ROW(),4,4,,))<>"",YEAR(INDIRECT(ADDRESS(ROW(),4,4,,))),0) -> 0 | M15: =IFERROR(IF(AND(INDIRECT(ADDRESS(ROW(),4,,,))<=COPIA!$DA$1,K15=0,COPIA!$BF$1>1,ROW()-10<COPIA!$BF$1-1),MAX($M$10:M14)+1,IF(AND(INDIRECT(ADDRESS(ROW(),4,,,))<=COPIA!$DA$1,K15=0,COPIA!$BF$1=1),MAX($M$10:M14)+1,0)),0) -> 0 | N15: =IF(AND(COPIA!$BF$1=1,M15<>0),ROW()-10,IF(AND(COPIA!$BF$1>1,ROW()-10>COPIA!$BF$1,M15<>0),0,IF(AND(COPIA!$BF$1>1,ROW()-10<=COPIA!$BF$1,M15<>0),ROW()-10,0))) -> 0 | O15: =IF(AND($O$1=0,ROW()-10<=$O$2),MAX($O$10:O14)+1,IF(AND(ROW()-10>$O$2,ROW()-10<=$O$1),ROW()-10,0)) -> 0 | P15: =IF(O15>0,MAX($P$10:P14)+1,0) -> 0
B16: =IF(INDIRECT(ADDRESS(ROW(),4,,,))="","",IFERROR(INDEX(PDC,MATCH(INDIRECT(ADDRESS(ROW(),5,,,)),DEN_PDC,0),1),0)) | C16: =IF(INDIRECT(ADDRESS(ROW(),5,,,))<>"",ROW()-10,"") | K16: =IF(IF(COPIA!$R$1=TRUE,IF(OR(G16<>0,H16<>0),ROUND(SUM(G$11:G16),2)-ROUND(SUM(H$11:H16),2),""),"")<>0,"",0) | L16: =IF(INDIRECT(ADDRESS(ROW(),4,4,,))<>"",YEAR(INDIRECT(ADDRESS(ROW(),4,4,,))),0) -> 0 | M16: =IFERROR(IF(AND(INDIRECT(ADDRESS(ROW(),4,,,))<=COPIA!$DA$1,K16=0,COPIA!$BF$1>1,ROW()-10<COPIA!$BF$1-1),MAX($M$10:M15)+1,IF(AND(INDIRECT(ADDRESS(ROW(),4,,,))<=COPIA!$DA$1,K16=0,COPIA!$BF$1=1),MAX($M$10:M15)+1,0)),0) -> 0 | N16: =IF(AND(COPIA!$BF$1=1,M16<>0),ROW()-10,IF(AND(COPIA!$BF$1>1,ROW()-10>COPIA!$BF$1,M16<>0),0,IF(AND(COPIA!$BF$1>1,ROW()-10<=COPIA!$BF$1,M16<>0),ROW()-10,0))) -> 0 | O16: =IF(AND($O$1=0,ROW()-10<=$O$2),MAX($O$10:O15)+1,IF(AND(ROW()-10>$O$2,ROW()-10<=$O$1),ROW()-10,0)) -> 0 | P16: =IF(O16>0,MAX($P$10:P15)+1,0) -> 0
B17: =IF(INDIRECT(ADDRESS(ROW(),4,,,))="","",IFERROR(INDEX(PDC,MATCH(INDIRECT(ADDRESS(ROW(),5,,,)),DEN_PDC,0),1),0)) | C17: =IF(INDIRECT(ADDRESS(ROW(),5,,,))<>"",ROW()-10,"") | K17: =IF(IF(COPIA!$R$1=TRUE,IF(OR(G17<>0,H17<>0),ROUND(SUM(G$11:G17),2)-ROUND(SUM(H$11:H17),2),""),"")<>0,"",0) | L17: =IF(INDIRECT(ADDRESS(ROW(),4,4,,))<>"",YEAR(INDIRECT(ADDRESS(ROW(),4,4,,))),0) -> 0 | M17: =IFERROR(IF(AND(INDIRECT(ADDRESS(ROW(),4,,,))<=COPIA!$DA$1,K17=0,COPIA!$BF$1>1,ROW()-10<COPIA!$BF$1-1),MAX($M$10:M16)+1,IF(AND(INDIRECT(ADDRESS(ROW(),4,,,))<=COPIA!$DA$1,K17=0,COPIA!$BF$1=1),MAX($M$10:M16)+1,0)),0) -> 0 | N17: =IF(AND(COPIA!$BF$1=1,M17<>0),ROW()-10,IF(AND(COPIA!$BF$1>1,ROW()-10>COPIA!$BF$1,M17<>0),0,IF(AND(COPIA!$BF$1>1,ROW()-10<=COPIA!$BF$1,M17<>0),ROW()-10,0))) -> 0 | O17: =IF(AND($O$1=0,ROW()-10<=$O$2),MAX($O$10:O16)+1,IF(AND(ROW()-10>$O$2,ROW()-10<=$O$1),ROW()-10,0)) -> 0 | P17: =IF(O17>0,MAX($P$10:P16)+1,0) -> 0
B18: =IF(INDIRECT(ADDRESS(ROW(),4,,,))="","",IFERROR(INDEX(PDC,MATCH(INDIRECT(ADDRESS(ROW(),5,,,)),DEN_PDC,0),1),0)) | C18: =IF(INDIRECT(ADDRESS(ROW(),5,,,))<>"",ROW()-10,"") | K18: =IF(IF(COPIA!$R$1=TRUE,IF(OR(G18<>0,H18<>0),ROUND(SUM(G$11:G18),2)-ROUND(SUM(H$11:H18),2),""),"")<>0,"",0) | L18: =IF(INDIRECT(ADDRESS(ROW(),4,4,,))<>"",YEAR(INDIRECT(ADDRESS(ROW(),4,4,,))),0) -> 0 | M18: =IFERROR(IF(AND(INDIRECT(ADDRESS(ROW(),4,,,))<=COPIA!$DA$1,K18=0,COPIA!$BF$1>1,ROW()-10<COPIA!$BF$1-1),MAX($M$10:M17)+1,IF(AND(INDIRECT(ADDRESS(ROW(),4,,,))<=COPIA!$DA$1,K18=0,COPIA!$BF$1=1),MAX($M$10:M17)+1,0)),0) -> 0 | N18: =IF(AND(COPIA!$BF$1=1,M18<>0),ROW()-10,IF(AND(COPIA!$BF$1>1,ROW()-10>COPIA!$BF$1,M18<>0),0,IF(AND(COPIA!$BF$1>1,ROW()-10<=COPIA!$BF$1,M18<>0),ROW()-10,0))) -> 0 | O18: =IF(AND($O$1=0,ROW()-10<=$O$2),MAX($O$10:O17)+1,IF(AND(ROW()-10>$O$2,ROW()-10<=$O$1),ROW()-10,0)) -> 0 | P18: =IF(O18>0,MAX($P$10:P17)+1,0) -> 0
B19: =IF(INDIRECT(ADDRESS(ROW(),4,,,))="","",IFERROR(INDEX(PDC,MATCH(INDIRECT(ADDRESS(ROW(),5,,,)),DEN_PDC,0),1),0)) | C19: =IF(INDIRECT(ADDRESS(ROW(),5,,,))<>"",ROW()-10,"") | K19: =IF(IF(COPIA!$R$1=TRUE,IF(OR(G19<>0,H19<>0),ROUND(SUM(G$11:G19),2)-ROUND(SUM(H$11:H19),2),""),"")<>0,"",0) | L19: =IF(INDIRECT(ADDRESS(ROW(),4,4,,))<>"",YEAR(INDIRECT(ADDRESS(ROW(),4,4,,))),0) -> 0 | M19: =IFERROR(IF(AND(INDIRECT(ADDRESS(ROW(),4,,,))<=COPIA!$DA$1,K19=0,COPIA!$BF$1>1,ROW()-10<COPIA!$BF$1-1),MAX($M$10:M18)+1,IF(AND(INDIRECT(ADDRESS(ROW(),4,,,))<=COPIA!$DA$1,K19=0,COPIA!$BF$1=1),MAX($M$10:M18)+1,0)),0) -> 0 | N19: =IF(AND(COPIA!$BF$1=1,M19<>0),ROW()-10,IF(AND(COPIA!$BF$1>1,ROW()-10>COPIA!$BF$1,M19<>0),0,IF(AND(COPIA!$BF$1>1,ROW()-10<=COPIA!$BF$1,M19<>0),ROW()-10,0))) -> 0 | O19: =IF(AND($O$1=0,ROW()-10<=$O$2),MAX($O$10:O18)+1,IF(AND(ROW()-10>$O$2,ROW()-10<=$O$1),ROW()-10,0)) -> 0 | P19: =IF(O19>0,MAX($P$10:P18)+1,0) -> 0
B20: =IF(INDIRECT(ADDRESS(ROW(),4,,,))="","",IFERROR(INDEX(PDC,MATCH(INDIRECT(ADDRESS(ROW(),5,,,)),DEN_PDC,0),1),0)) | C20: =IF(INDIRECT(ADDRESS(ROW(),5,,,))<>"",ROW()-10,"") | K20: =IF(IF(COPIA!$R$1=TRUE,IF(OR(G20<>0,H20<>0),ROUND(SUM(G$11:G20),2)-ROUND(SUM(H$11:H20),2),""),"")<>0,"",0) | L20: =IF(INDIRECT(ADDRESS(ROW(),4,4,,))<>"",YEAR(INDIRECT(ADDRESS(ROW(),4,4,,))),0) -> 0 | M20: =IFERROR(IF(AND(INDIRECT(ADDRESS(ROW(),4,,,))<=COPIA!$DA$1,K20=0,COPIA!$BF$1>1,ROW()-10<COPIA!$BF$1-1),MAX($M$10:M19)+1,IF(AND(INDIRECT(ADDRESS(ROW(),4,,,))<=COPIA!$DA$1,K20=0,COPIA!$BF$1=1),MAX($M$10:M19)+1,0)),0) -> 0 | N20: =IF(AND(COPIA!$BF$1=1,M20<>0),ROW()-10,IF(AND(COPIA!$BF$1>1,ROW()-10>COPIA!$BF$1,M20<>0),0,IF(AND(COPIA!$BF$1>1,ROW()-10<=COPIA!$BF$1,M20<>0),ROW()-10,0))) -> 0 | O20: =IF(AND($O$1=0,ROW()-10<=$O$2),MAX($O$10:O19)+1,IF(AND(ROW()-10>$O$2,ROW()-10<=$O$1),ROW()-10,0)) -> 0 | P20: =IF(O20>0,MAX($P$10:P19)+1,0) -> 0
B21: =IF(INDIRECT(ADDRESS(ROW(),4,,,))="","",IFERROR(INDEX(PDC,MATCH(INDIRECT(ADDRESS(ROW(),5,,,)),DEN_PDC,0),1),0)) | C21: =IF(INDIRECT(ADDRESS(ROW(),5,,,))<>"",ROW()-10,"") | K21: =IF(IF(COPIA!$R$1=TRUE,IF(OR(G21<>0,H21<>0),ROUND(SUM(G$11:G21),2)-ROUND(SUM(H$11:H21),2),""),"")<>0,"",0) | L21: =IF(INDIRECT(ADDRESS(ROW(),4,4,,))<>"",YEAR(INDIRECT(ADDRESS(ROW(),4,4,,))),0) -> 0 | M21: =IFERROR(IF(AND(INDIRECT(ADDRESS(ROW(),4,,,))<=COPIA!$DA$1,K21=0,COPIA!$BF$1>1,ROW()-10<COPIA!$BF$1-1),MAX($M$10:M20)+1,IF(AND(INDIRECT(ADDRESS(ROW(),4,,,))<=COPIA!$DA$1,K21=0,COPIA!$BF$1=1),MAX($M$10:M20)+1,0)),0) -> 0 | N21: =IF(AND(COPIA!$BF$1=1,M21<>0),ROW()-10,IF(AND(COPIA!$BF$1>1,ROW()-10>COPIA!$BF$1,M21<>0),0,IF(AND(COPIA!$BF$1>1,ROW()-10<=COPIA!$BF$1,M21<>0),ROW()-10,0))) -> 0 | O21: =IF(AND($O$1=0,ROW()-10<=$O$2),MAX($O$10:O20)+1,IF(AND(ROW()-10>$O$2,ROW()-10<=$O$1),ROW()-10,0)) -> 0 | P21: =IF(O21>0,MAX($P$10:P20)+1,0) -> 0
B22: =IF(INDIRECT(ADDRESS(ROW(),4,,,))="","",IFERROR(INDEX(PDC,MATCH(INDIRECT(ADDRESS(ROW(),5,,,)),DEN_PDC,0),1),0)) | C22: =IF(INDIRECT(ADDRESS(ROW(),5,,,))<>"",ROW()-10,"") | K22: =IF(IF(COPIA!$R$1=TRUE,IF(OR(G22<>0,H22<>0),ROUND(SUM(G$11:G22),2)-ROUND(SUM(H$11:H22),2),""),"")<>0,"",0) | L22: =IF(INDIRECT(ADDRESS(ROW(),4,4,,))<>"",YEAR(INDIRECT(ADDRESS(ROW(),4,4,,))),0) -> 0 | M22: =IFERROR(IF(AND(INDIRECT(ADDRESS(ROW(),4,,,))<=COPIA!$DA$1,K22=0,COPIA!$BF$1>1,ROW()-10<COPIA!$BF$1-1),MAX($M$10:M21)+1,IF(AND(INDIRECT(ADDRESS(ROW(),4,,,))<=COPIA!$DA$1,K22=0,COPIA!$BF$1=1),MAX($M$10:M21)+1,0)),0) -> 0 | N22: =IF(AND(COPIA!$BF$1=1,M22<>0),ROW()-10,IF(AND(COPIA!$BF$1>1,ROW()-10>COPIA!$BF$1,M22<>0),0,IF(AND(COPIA!$BF$1>1,ROW()-10<=COPIA!$BF$1,M22<>0),ROW()-10,0))) -> 0 | O22: =IF(AND($O$1=0,ROW()-10<=$O$2),MAX($O$10:O21)+1,IF(AND(ROW()-10>$O$2,ROW()-10<=$O$1),ROW()-10,0)) -> 0 | P22: =IF(O22>0,MAX($P$10:P21)+1,0) -> 0
... B210: =IF(INDIRECT(ADDRESS(ROW(),4,,,))="","",IFERROR(INDEX(PDC,MATCH(INDIRECT(ADDRESS(ROW(),5,,,)),DEN_PDC,0),1),0)) | C210: =IF(INDIRECT(ADDRESS(ROW(),5,,,))<>"",ROW()-10,"") | K210: =IF(IF(COPIA!$R$1=TRUE,IF(OR(G210<>0,H210<>0),ROUND(SUM(G$11:G210),2)-ROUND(SUM(H$11:H210),2),""),"")<>0,"",0) | L210: =IF(INDIRECT(ADDRESS(ROW(),4,4,,))<>"",YEAR(INDIRECT(ADDRESS(ROW(),4,4,,))),0) -> 0 | M210: =IFERROR(IF(AND(INDIRECT(ADDRESS(ROW(),4,,,))<=COPIA!$DA$1,K210=0,COPIA!$BF$1>1,ROW()-10<COPIA!$BF$1-1),MAX($M$10:M209)+1,IF(AND(INDIRECT(ADDRESS(ROW(),4,,,))<=COPIA!$DA$1,K210=0,COPIA!$BF$1=1),MAX($M$10:M209)+1,0)),0) -> 0 | N210: =IF(AND(COPIA!$BF$1=1,M210<>0),ROW()-10,IF(AND(COPIA!$BF$1>1,ROW()-10>COPIA!$BF$1,M210<>0),0,IF(AND(COPIA!$BF$1>1,ROW()-10<=COPIA!$BF$1,M210<>0),ROW()-10,0))) -> 0 | O210: =IF(AND($O$1=0,ROW()-10<=$O$2),MAX($O$10:O209)+1,IF(AND(ROW()-10>$O$2,ROW()-10<=$O$1),ROW()-10,0)) -> 0 | P210: =IF(O210>0,MAX($P$10:P209)+1,0) -> 0
C211: =IF(INDIRECT(ADDRESS(ROW(),5,,,))<>"",ROW()-10,"") | K211: =IF(IF(COPIA!$R$1=TRUE,IF(OR(G211<>0,H211<>0),ROUND(SUM(G$11:G211),2)-ROUND(SUM(H$11:H211),2),""),"")<>0,"",0)
C212: =IF(INDIRECT(ADDRESS(ROW(),5,,,))<>"",ROW()-10,"") | K212: =IF(IF(COPIA!$R$1=TRUE,IF(OR(G212<>0,H212<>0),ROUND(SUM(G$11:G212),2)-ROUND(SUM(H$11:H212),2),""),"")<>0,"",0) | L212: =IF(D212<>"",YEAR(D212),0) -> 0

Sheet CONTI_DI_MASTRO
B1: CONTI DI MASTRO
B2: =L7 | E2: Riquadro di controllo: DENOMINAZIONE | H2: Riquadro di controllo: ECCEDENZA
D3: =IF(COPIA!CO1=0,"",CONCATENATE("Numero dei conti con denominazione errata: ",COPIA!ES1)) | E3: =IF(COPIA!ET3<>"",COPIA!ET3,"") | H3: =IF(COPIA!EO3<>"",COPIA!EO3,"")
D4: =IF(COPIA!CO1=0,"",CONCATENATE("Numero dei conti con eccedenza errata: ",COPIA!EN2))
B6: OPZIONI DI VISUALIZZAZIONE | D6: MOSTRA UN CONTO IN EVIDENZA | E6: VISUALIZZA PRIMA I CONTI DELL'ULTIMO ARTICOLO | H6: VISUALIZZA I MOVIMENTI E IL SALDO
L7: =IF(COPIA!CO1=0,"",CONCATENATE("Numero dei conti visualizzati: ",COPIA!$DE$1))
B8: =IF(INDIRECT(ADDRESS(8,6,,,"LIBRO_GIORNALE"))="","",INDIRECT(ADDRESS(8,6,,,"LIBRO_GIORNALE"))) | E8: =IF(INDIRECT(ADDRESS(8,7,,,"LIBRO_GIORNALE"))="","",INDIRECT(ADDRESS(8,7,,,"LIBRO_GIORNALE")))
B9: =IF(COPIA!CO1=0,"",CONCATENATE("CONTI DI MASTRO dal 1/1/",COPIA!AW1," al ",COPIA!AS1,"/",COPIA!AT1,"/",COPIA!AW1)) | K9: =MAX(COPIA!DF3:DF1339)+3 -> 3
A10: =COPIA!AC3 -> AZIONISTI C/SOTTOSCRIZIONE | B10: =IF(IFERROR(INDEX((COPIA!$DA$3:$DE$1339),MATCH(ROWS(B$10:B10),COPIA!$DF$3:$DF$1339,0),COLUMN()-1),"")>=1,IFERROR(INDEX((COPIA!$DA$3:$DE$1339),MATCH(ROWS(B$10:B10),COPIA!$DF$3:$DF$1339,0),COLUMN()-1),""),"") | C10: =SUBSTITUTE(IFERROR(INDEX((COPIA!$DA$3:$DE$1339),MATCH(ROWS(C$10:C10),COPIA!$DF$3:$DF$1339,0),COLUMN()-1),""),"MASTRO","") | D10: =IF(IFERROR(INDEX((COPIA!$DA$3:$DE$1339),MATCH(ROWS(D$10:D10),COPIA!$DF$3:$DF$1339,0),COLUMN()-1),"")=0,"",IFERROR(INDEX((COPIA!$DA$3:$DE$1339),MATCH(ROWS(D$10:D10),COPIA!$DF$3:$DF$1339,0),COLUMN()-1),"")) | E10: =IF(IFERROR(INDEX((COPIA!$DA$3:$DE$1339),MATCH(ROWS(E$10:E10),COPIA!$DF$3:$DF$1339,0),COLUMN()-1),"")=0,"",IFERROR(INDEX((COPIA!$DA$3:$DE$1339),MATCH(ROWS(E$10:E10),COPIA!$DF$3:$DF$1339,0),COLUMN()-1),"")) | F10: =IF(IFERROR(INDEX((COPIA!$DA$3:$DE$1339),MATCH(ROWS(F$10:F10),COPIA!$DF$3:$DF$1339,0),COLUMN()-1),"")=0,"",IFERROR(INDEX((COPIA!$DA$3:$DE$1339),MATCH(ROWS(F$10:F10),COPIA!$DF$3:$DF$1339,0),COLUMN()-1),""))
A11: =COPIA!AC4 -> AZIONISTI C/VERSAMENTI RICHIAMATI | B11: =IF(IFERROR(INDEX((COPIA!$DA$3:$DE$1339),MATCH(ROWS(B$10:B11),COPIA!$DF$3:$DF$1339,0),COLUMN()-1),"")>=1,IFERROR(INDEX((COPIA!$DA$3:$DE$1339),MATCH(ROWS(B$10:B11),COPIA!$DF$3:$DF$1339,0),COLUMN()-1),""),"") | C11: =SUBSTITUTE(IFERROR(INDEX((COPIA!$DA$3:$DE$1339),MATCH(ROWS(C$10:C11),COPIA!$DF$3:$DF$1339,0),COLUMN()-1),""),"MASTRO","") | D11: =IF(IFERROR(INDEX((COPIA!$DA$3:$DE$1339),MATCH(ROWS(D$10:D11),COPIA!$DF$3:$DF$1339,0),COLUMN()-1),"")=0,"",IFERROR(INDEX((COPIA!$DA$3:$DE$1339),MATCH(ROWS(D$10:D11),COPIA!$DF$3:$DF$1339,0),COLUMN()-1),"")) | E11: =IF(IFERROR(INDEX((COPIA!$DA$3:$DE$1339),MATCH(ROWS(E$10:E11),COPIA!$DF$3:$DF$1339,0),COLUMN()-1),"")=0,"",IFERROR(INDEX((COPIA!$DA$3:$DE$1339),MATCH(ROWS(E$10:E11),COPIA!$DF$3:$DF$1339,0),COLUMN()-1),"")) | F11: =IF(IFERROR(INDEX((COPIA!$DA$3:$DE$1339),MATCH(ROWS(F$10:F11),COPIA!$DF$3:$DF$1339,0),COLUMN()-1),"")=0,"",IFERROR(INDEX((COPIA!$DA$3:$DE$1339),MATCH(ROWS(F$10:F11),COPIA!$DF$3:$DF$1339,0),COLUMN()-1),""))
A12: =COPIA!AC5 -> AZIONISTI C/REINTEGRO | B12: =IF(IFERROR(INDEX((COPIA!$DA$3:$DE$1339),MATCH(ROWS(B$10:B12),COPIA!$DF$3:$DF$1339,0),COLUMN()-1),"")>=1,IFERROR(INDEX((COPIA!$DA$3:$DE$1339),MATCH(ROWS(B$10:B12),COPIA!$DF$3:$DF$1339,0),COLUMN()-1),""),"") | C12: =SUBSTITUTE(IFERROR(INDEX((COPIA!$DA$3:$DE$1339),MATCH(ROWS(C$10:C12),COPIA!$DF$3:$DF$1339,0),COLUMN()-1),""),"MASTRO","") | D12: =IF(IFERROR(INDEX((COPIA!$DA$3:$DE$1339),MATCH(ROWS(D$10:D12),COPIA!$DF$3:$DF$1339,0),COLUMN()-1),"")=0,"",IFERROR(INDEX((COPIA!$DA$3:$DE$1339),MATCH(ROWS(D$10:D12),COPIA!$DF$3:$DF$1339,0),COLUMN()-1),"")) | E12: =IF(IFERROR(INDEX((COPIA!$DA$3:$DE$1339),MATCH(ROWS(E$10:E12),COPIA!$DF$3:$DF$1339,0),COLUMN()-1),"")=0,"",IFERROR(INDEX((COPIA!$DA$3:$DE$1339),MATCH(ROWS(E$10:E12),COPIA!$DF$3:$DF$1339,0),COLUMN()-1),"")) | F12: =IF(IFERROR(INDEX((COPIA!$DA$3:$DE$1339),MATCH(ROWS(F$10:F12),COPIA!$DF$3:$DF$1339,0),COLUMN()-1),"")=0,"",IFERROR(INDEX((COPIA!$DA$3:$DE$1339),MATCH(ROWS(F$10:F12),COPIA!$DF$3:$DF$1339,0),COLUMN()-1),""))
A13: =COPIA!AC6 -> COSTI DI IMPIANTO | B13: =IF(IFERROR(INDEX((COPIA!$DA$3:$DE$1339),MATCH(ROWS(B$10:B13),COPIA!$DF$3:$DF$1339,0),COLUMN()-1),"")>=1,IFERROR(INDEX((COPIA!$DA$3:$DE$1339),MATCH(ROWS(B$10:B13),COPIA!$DF$3:$DF$1339,0),COLUMN()-1),""),"") | C13: =SUBSTITUTE(IFERROR(INDEX((COPIA!$DA$3:$DE$1339),MATCH(ROWS(C$10:C13),COPIA!$DF$3:$DF$1339,0),COLUMN()-1),""),"MASTRO","") | D13: =IF(IFERROR(INDEX((COPIA!$DA$3:$DE$1339),MATCH(ROWS(D$10:D13),COPIA!$DF$3:$DF$1339,0),COLUMN()-1),"")=0,"",IFERROR(INDEX((COPIA!$DA$3:$DE$1339),MATCH(ROWS(D$10:D13),COPIA!$DF$3:$DF$1339,0),COLUMN()-1),"")) | E13: =IF(IFERROR(INDEX((COPIA!$DA$3:$DE$1339),MATCH(ROWS(E$10:E13),COPIA!$DF$3:$DF$1339,0),COLUMN()-1),"")=0,"",IFERROR(INDEX((COPIA!$DA$3:$DE$1339),MATCH(ROWS(E$10:E13),COPIA!$DF$3:$DF$1339,0),COLUMN()-1),"")) | F13: =IF(IFERROR(INDEX((COPIA!$DA$3:$DE$1339),MATCH(ROWS(F$10:F13),COPIA!$DF$3:$DF$1339,0),COLUMN()-1),"")=0,"",IFERROR(INDEX((COPIA!$DA$3:$DE$1339),MATCH(ROWS(F$10:F13),COPIA!$DF$3:$DF$1339,0),COLUMN()-1),""))
A14: =COPIA!AC7 -> COSTI DI AMPLIAMENTO | B14: =IF(IFERROR(INDEX((COPIA!$DA$3:$DE$1339),MATCH(ROWS(B$10:B14),COPIA!$DF$3:$DF$1339,0),COLUMN()-1),"")>=1,IFERROR(INDEX((COPIA!$DA$3:$DE$1339),MATCH(ROWS(B$10:B14),COPIA!$DF$3:$DF$1339,0),COLUMN()-1),""),"") | C14: =SUBSTITUTE(IFERROR(INDEX((COPIA!$DA$3:$DE$1339),MATCH(ROWS(C$10:C14),COPIA!$DF$3:$DF$1339,0),COLUMN()-1),""),"MASTRO","") | D14: =IF(IFERROR(INDEX((COPIA!$DA$3:$DE$1339),MATCH(ROWS(D$10:D14),COPIA!$DF$3:$DF$1339,0),COLUMN()-1),"")=0,"",IFERROR(INDEX((COPIA!$DA$3:$DE$1339),MATCH(ROWS(D$10:D14),COPIA!$DF$3:$DF$1339,0),COLUMN()-1),"")) | E14: =IF(IFERROR(INDEX((COPIA!$DA$3:$DE$1339),MATCH(ROWS(E$10:E14),COPIA!$DF$3:$DF$1339,0),COLUMN()-1),"")=0,"",IFERROR(INDEX((COPIA!$DA$3:$DE$1339),MATCH(ROWS(E$10:E14),COPIA!$DF$3:$DF$1339,0),COLUMN()-1),"")) | F14: =IF(IFERROR(INDEX((COPIA!$DA$3:$DE$1339),MATCH(ROWS(F$10:F14),COPIA!$DF$3:$DF$1339,0),COLUMN()-1),"")=0,"",IFERROR(INDEX((COPIA!$DA$3:$DE$1339),MATCH(ROWS(F$10:F14),COPIA!$DF$3:$DF$1339,0),COLUMN()-1),""))
A15: =COPIA!AC8 -> COSTI DI SVILUPPO | B15: =IF(IFERROR(INDEX((COPIA!$DA$3:$DE$1339),MATCH(ROWS(B$10:B15),COPIA!$DF$3:$DF$1339,0),COLUMN()-1),"")>=1,IFERROR(INDEX((COPIA!$DA$3:$DE$1339),MATCH(ROWS(B$10:B15),COPIA!$DF$3:$DF$1339,0),COLUMN()-1),""),"") | C15: =SUBSTITUTE(IFERROR(INDEX((COPIA!$DA$3:$DE$1339),MATCH(ROWS(C$10:C15),COPIA!$DF$3:$DF$1339,0),COLUMN()-1),""),"MASTRO","") | D15: =IF(IFERROR(INDEX((COPIA!$DA$3:$DE$1339),MATCH(ROWS(D$10:D15),COPIA!$DF$3:$DF$1339,0),COLUMN()-1),"")=0,"",IFERROR(INDEX((COPIA!$DA$3:$DE$1339),MATCH(ROWS(D$10:D15),COPIA!$DF$3:$DF$1339,0),COLUMN()-1),"")) | E15: =IF(IFERROR(INDEX((COPIA!$DA$3:$DE$1339),MATCH(ROWS(E$10:E15),COPIA!$DF$3:$DF$1339,0),COLUMN()-1),"")=0,"",IFERROR(INDEX((COPIA!$DA$3:$DE$1339),MATCH(ROWS(E$10:E15),COPIA!$DF$3:$DF$1339,0),COLUMN()-1),"")) | F15: =IF(IFERROR(INDEX((COPIA!$DA$3:$DE$1339),MATCH(ROWS(F$10:F15),COPIA!$DF$3:$DF$1339,0),COLUMN()-1),"")=0,"",IFERROR(INDEX((COPIA!$DA$3:$DE$1339),MATCH(ROWS(F$10:F15),COPIA!$DF$3:$DF$1339,0),COLUMN()-1),""))
A16: =COPIA!AC9 -> BREVETTI | B16: =IF(IFERROR(INDEX((COPIA!$DA$3:$DE$1339),MATCH(ROWS(B$10:B16),COPIA!$DF$3:$DF$1339,0),COLUMN()-1),"")>=1,IFERROR(INDEX((COPIA!$DA$3:$DE$1339),MATCH(ROWS(B$10:B16),COPIA!$DF$3:$DF$1339,0),COLUMN()-1),""),"") | C16: =SUBSTITUTE(IFERROR(INDEX((COPIA!$DA$3:$DE$1339),MATCH(ROWS(C$10:C16),COPIA!$DF$3:$DF$1339,0),COLUMN()-1),""),"MASTRO","") | D16: =IF(IFERROR(INDEX((COPIA!$DA$3:$DE$1339),MATCH(ROWS(D$10:D16),COPIA!$DF$3:$DF$1339,0),COLUMN()-1),"")=0,"",IFERROR(INDEX((COPIA!$DA$3:$DE$1339),MATCH(ROWS(D$10:D16),COPIA!$DF$3:$DF$1339,0),COLUMN()-1),"")) | E16: =IF(IFERROR(INDEX((COPIA!$DA$3:$DE$1339),MATCH(ROWS(E$10:E16),COPIA!$DF$3:$DF$1339,0),COLUMN()-1),"")=0,"",IFERROR(INDEX((COPIA!$DA$3:$DE$1339),MATCH(ROWS(E$10:E16),COPIA!$DF$3:$DF$1339,0),COLUMN()-1),"")) | F16: =IF(IFERROR(INDEX((COPIA!$DA$3:$DE$1339),MATCH(ROWS(F$10:F16),COPIA!$DF$3:$DF$1339,0),COLUMN()-1),"")=0,"",IFERROR(INDEX((COPIA!$DA$3:$DE$1339),MATCH(ROWS(F$10:F16),COPIA!$DF$3:$DF$1339,0),COLUMN()-1),""))
A17: =COPIA!AC10 -> SOFTWARE | B17: =IF(IFERROR(INDEX((COPIA!$DA$3:$DE$1339),MATCH(ROWS(B$10:B17),COPIA!$DF$3:$DF$1339,0),COLUMN()-1),"")>=1,IFERROR(INDEX((COPIA!$DA$3:$DE$1339),MATCH(ROWS(B$10:B17),COPIA!$DF$3:$DF$1339,0),COLUMN()-1),""),"") | C17: =SUBSTITUTE(IFERROR(INDEX((COPIA!$DA$3:$DE$1339),MATCH(ROWS(C$10:C17),COPIA!$DF$3:$DF$1339,0),COLUMN()-1),""),"MASTRO","") | D17: =IF(IFERROR(INDEX((COPIA!$DA$3:$DE$1339),MATCH(ROWS(D$10:D17),COPIA!$DF$3:$DF$1339,0),COLUMN()-1),"")=0,"",IFERROR(INDEX((COPIA!$DA$3:$DE$1339),MATCH(ROWS(D$10:D17),COPIA!$DF$3:$DF$1339,0),COLUMN()-1),"")) | E17: =IF(IFERROR(INDEX((COPIA!$DA$3:$DE$1339),MATCH(ROWS(E$10:E17),COPIA!$DF$3:$DF$1339,0),COLUMN()-1),"")=0,"",IFERROR(INDEX((COPIA!$DA$3:$DE$1339),MATCH(ROWS(E$10:E17),COPIA!$DF$3:$DF$1339,0),COLUMN()-1),"")) | F17: =IF(IFERROR(INDEX((COPIA!$DA$3:$DE$1339),MATCH(ROWS(F$10:F17),COPIA!$DF$3:$DF$1339,0),COLUMN()-1),"")=0,"",IFERROR(INDEX((COPIA!$DA$3:$DE$1339),MATCH(ROWS(F$10:F17),COPIA!$DF$3:$DF$1339,0),COLUMN()-1),""))
A18: =COPIA!AC11 -> AVVIAMENTO | B18: =IF(IFERROR(INDEX((COPIA!$DA$3:$DE$1339),MATCH(ROWS(B$10:B18),COPIA!$DF$3:$DF$1339,0),COLUMN()-1),"")>=1,IFERROR(INDEX((COPIA!$DA$3:$DE$1339),MATCH(ROWS(B$10:B18),COPIA!$DF$3:$DF$1339,0),COLUMN()-1),""),"") | C18: =SUBSTITUTE(IFERROR(INDEX((COPIA!$DA$3:$DE$1339),MATCH(ROWS(C$10:C18),COPIA!$DF$3:$DF$1339,0),COLUMN()-1),""),"MASTRO","") | D18: =IF(IFERROR(INDEX((COPIA!$DA$3:$DE$1339),MATCH(ROWS(D$10:D18),COPIA!$DF$3:$DF$1339,0),COLUMN()-1),"")=0,"",IFERROR(INDEX((COPIA!$DA$3:$DE$1339),MATCH(ROWS(D$10:D18),COPIA!$DF$3:$DF$1339,0),COLUMN()-1),"")) | E18: =IF(IFERROR(INDEX((COPIA!$DA$3:$DE$1339),MATCH(ROWS(E$10:E18),COPIA!$DF$3:$DF$1339,0),COLUMN()-1),"")=0,"",IFERROR(INDEX((COPIA!$DA$3:$DE$1339),MATCH(ROWS(E$10:E18),COPIA!$DF$3:$DF$1339,0),COLUMN()-1),"")) | F18: =IF(IFERROR(INDEX((COPIA!$DA$3:$DE$1339),MATCH(ROWS(F$10:F18),COPIA!$DF$3:$DF$1339,0),COLUMN()-1),"")=0,"",IFERROR(INDEX((COPIA!$DA$3:$DE$1339),MATCH(ROWS(F$10:F18),COPIA!$DF$3:$DF$1339,0),COLUMN()-1),""))
A19: =COPIA!AC12 -> FONDO AMMORTAMENTO COSTI DI IMPIANTO | B19: =IF(IFERROR(INDEX((COPIA!$DA$3:$DE$1339),MATCH(ROWS(B$10:B19),COPIA!$DF$3:$DF$1339,0),COLUMN()-1),"")>=1,IFERROR(INDEX((COPIA!$DA$3:$DE$1339),MATCH(ROWS(B$10:B19),COPIA!$DF$3:$DF$1339,0),COLUMN()-1),""),"") | C19: =SUBSTITUTE(IFERROR(INDEX((COPIA!$DA$3:$DE$1339),MATCH(ROWS(C$10:C19),COPIA!$DF$3:$DF$1339,0),COLUMN()-1),""),"MASTRO","") | D19: =IF(IFERROR(INDEX((COPIA!$DA$3:$DE$1339),MATCH(ROWS(D$10:D19),COPIA!$DF$3:$DF$1339,0),COLUMN()-1),"")=0,"",IFERROR(INDEX((COPIA!$DA$3:$DE$1339),MATCH(ROWS(D$10:D19),COPIA!$DF$3:$DF$1339,0),COLUMN()-1),"")) | E19: =IF(IFERROR(INDEX((COPIA!$DA$3:$DE$1339),MATCH(ROWS(E$10:E19),COPIA!$DF$3:$DF$1339,0),COLUMN()-1),"")=0,"",IFERROR(INDEX((COPIA!$DA$3:$DE$1339),MATCH(ROWS(E$10:E19),COPIA!$DF$3:$DF$1339,0),COLUMN()-1),"")) | F19: =IF(IFERROR(INDEX((COPIA!$DA$3:$DE$1339),MATCH(ROWS(F$10:F19),COPIA!$DF$3:$DF$1339,0),COLUMN()-1),"")=0,"",IFERROR(INDEX((COPIA!$DA$3:$DE$1339),MATCH(ROWS(F$10:F19),COPIA!$DF$3:$DF$1339,0),COLUMN()-1),""))
A20: =COPIA!AC13 -> FONDO AMMORTAMENTO COSTI DI AMPLIAMENTO | B20: =IF(IFERROR(INDEX((COPIA!$DA$3:$DE$1339),MATCH(ROWS(B$10:B20),COPIA!$DF$3:$DF$1339,0),COLUMN()-1),"")>=1,IFERROR(INDEX((COPIA!$DA$3:$DE$1339),MATCH(ROWS(B$10:B20),COPIA!$DF$3:$DF$1339,0),COLUMN()-1),""),"") | C20: =SUBSTITUTE(IFERROR(INDEX((COPIA!$DA$3:$DE$1339),MATCH(ROWS(C$10:C20),COPIA!$DF$3:$DF$1339,0),COLUMN()-1),""),"MASTRO","") | D20: =IF(IFERROR(INDEX((COPIA!$DA$3:$DE$1339),MATCH(ROWS(D$10:D20),COPIA!$DF$3:$DF$1339,0),COLUMN()-1),"")=0,"",IFERROR(INDEX((COPIA!$DA$3:$DE$1339),MATCH(ROWS(D$10:D20),COPIA!$DF$3:$DF$1339,0),COLUMN()-1),"")) | E20: =IF(IFERROR(INDEX((COPIA!$DA$3:$DE$1339),MATCH(ROWS(E$10:E20),COPIA!$DF$3:$DF$1339,0),COLUMN()-1),"")=0,"",IFERROR(INDEX((COPIA!$DA$3:$DE$1339),MATCH(ROWS(E$10:E20),COPIA!$DF$3:$DF$1339,0),COLUMN()-1),"")) | F20: =IF(IFERROR(INDEX((COPIA!$DA$3:$DE$1339),MATCH(ROWS(F$10:F20),COPIA!$DF$3:$DF$1339,0),COLUMN()-1),"")=0,"",IFERROR(INDEX((COPIA!$DA$3:$DE$1339),MATCH(ROWS(F$10:F20),COPIA!$DF$3:$DF$1339,0),COLUMN()-1),""))
A21: =COPIA!AC14 -> FONDO AMMORTAMENTO COSTI DI SVILUPPO | B21: =IF(IFERROR(INDEX((COPIA!$DA$3:$DE$1339),MATCH(ROWS(B$10:B21),COPIA!$DF$3:$DF$1339,0),COLUMN()-1),"")>=1,IFERROR(INDEX((COPIA!$DA$3:$DE$1339),MATCH(ROWS(B$10:B21),COPIA!$DF$3:$DF$1339,0),COLUMN()-1),""),"") | C21: =SUBSTITUTE(IFERROR(INDEX((COPIA!$DA$3:$DE$1339),MATCH(ROWS(C$10:C21),COPIA!$DF$3:$DF$1339,0),COLUMN()-1),""),"MASTRO","") | D21: =IF(IFERROR(INDEX((COPIA!$DA$3:$DE$1339),MATCH(ROWS(D$10:D21),COPIA!$DF$3:$DF$1339,0),COLUMN()-1),"")=0,"",IFERROR(INDEX((COPIA!$DA$3:$DE$1339),MATCH(ROWS(D$10:D21),COPIA!$DF$3:$DF$1339,0),COLUMN()-1),"")) | E21: =IF(IFERROR(INDEX((COPIA!$DA$3:$DE$1339),MATCH(ROWS(E$10:E21),COPIA!$DF$3:$DF$1339,0),COLUMN()-1),"")=0,"",IFERROR(INDEX((COPIA!$DA$3:$DE$1339),MATCH(ROWS(E$10:E21),COPIA!$DF$3:$DF$1339,0),COLUMN()-1),"")) | F21: =IF(IFERROR(INDEX((COPIA!$DA$3:$DE$1339),MATCH(ROWS(F$10:F21),COPIA!$DF$3:$DF$1339,0),COLUMN()-1),"")=0,"",IFERROR(INDEX((COPIA!$DA$3:$DE$1339),MATCH(ROWS(F$10:F21),COPIA!$DF$3:$DF$1339,0),COLUMN()-1),""))
... A407: =COPIA!AC400 | B407: =IF(IFERROR(INDEX((COPIA!$DA$3:$DE$1339),MATCH(ROWS(B$10:B407),COPIA!$DF$3:$DF$1339,0),COLUMN()-1),"")>=1,IFERROR(INDEX((COPIA!$DA$3:$DE$1339),MATCH(ROWS(B$10:B407),COPIA!$DF$3:$DF$1339,0),COLUMN()-1),""),"") | C407: =SUBSTITUTE(IFERROR(INDEX((COPIA!$DA$3:$DE$1339),MATCH(ROWS(C$10:C407),COPIA!$DF$3:$DF$1339,0),COLUMN()-1),""),"MASTRO","") | D407: =IF(IFERROR(INDEX((COPIA!$DA$3:$DE$1339),MATCH(ROWS(D$10:D407),COPIA!$DF$3:$DF$1339,0),COLUMN()-1),"")=0,"",IFERROR(INDEX((COPIA!$DA$3:$DE$1339),MATCH(ROWS(D$10:D407),COPIA!$DF$3:$DF$1339,0),COLUMN()-1),"")) | E407: =IF(IFERROR(INDEX((COPIA!$DA$3:$DE$1339),MATCH(ROWS(E$10:E407),COPIA!$DF$3:$DF$1339,0),COLUMN()-1),"")=0,"",IFERROR(INDEX((COPIA!$DA$3:$DE$1339),MATCH(ROWS(E$10:E407),COPIA!$DF$3:$DF$1339,0),COLUMN()-1),"")) | F407: =IF(IFERROR(INDEX((COPIA!$DA$3:$DE$1339),MATCH(ROWS(F$10:F407),COPIA!$DF$3:$DF$1339,0),COLUMN()-1),"")=0,"",IFERROR(INDEX((COPIA!$DA$3:$DE$1339),MATCH(ROWS(F$10:F407),COPIA!$DF$3:$DF$1339,0),COLUMN()-1),""))
B408: =IF(IFERROR(INDEX((COPIA!$DA$3:$DE$1339),MATCH(ROWS(B$10:B408),COPIA!$DF$3:$DF$1339,0),COLUMN()-1),"")>=1,IFERROR(INDEX((COPIA!$DA$3:$DE$1339),MATCH(ROWS(B$10:B408),COPIA!$DF$3:$DF$1339,0),COLUMN()-1),""),"") | C408: =SUBSTITUTE(IFERROR(INDEX((COPIA!$DA$3:$DE$1339),MATCH(ROWS(C$10:C408),COPIA!$DF$3:$DF$1339,0),COLUMN()-1),""),"MASTRO","") | D408: =IF(IFERROR(INDEX((COPIA!$DA$3:$DE$1339),MATCH(ROWS(D$10:D408),COPIA!$DF$3:$DF$1339,0),COLUMN()-1),"")=0,"",IFERROR(INDEX((COPIA!$DA$3:$DE$1339),MATCH(ROWS(D$10:D408),COPIA!$DF$3:$DF$1339,0),COLUMN()-1),"")) | E408: =IF(IFERROR(INDEX((COPIA!$DA$3:$DE$1339),MATCH(ROWS(E$10:E408),COPIA!$DF$3:$DF$1339,0),COLUMN()-1),"")=0,"",IFERROR(INDEX((COPIA!$DA$3:$DE$1339),MATCH(ROWS(E$10:E408),COPIA!$DF$3:$DF$1339,0),COLUMN()-1),"")) | F408: =IF(IFERROR(INDEX((COPIA!$DA$3:$DE$1339),MATCH(ROWS(F$10:F408),COPIA!$DF$3:$DF$1339,0),COLUMN()-1),"")=0,"",IFERROR(INDEX((COPIA!$DA$3:$DE$1339),MATCH(ROWS(F$10:F408),COPIA!$DF$3:$DF$1339,0),COLUMN()-1),""))
B409: =IF(IFERROR(INDEX((COPIA!$DA$3:$DE$1339),MATCH(ROWS(B$10:B409),COPIA!$DF$3:$DF$1339,0),COLUMN()-1),"")>=1,IFERROR(INDEX((COPIA!$DA$3:$DE$1339),MATCH(ROWS(B$10:B409),COPIA!$DF$3:$DF$1339,0),COLUMN()-1),""),"") | C409: =SUBSTITUTE(IFERROR(INDEX((COPIA!$DA$3:$DE$1339),MATCH(ROWS(C$10:C409),COPIA!$DF$3:$DF$1339,0),COLUMN()-1),""),"MASTRO","") | D409: =IF(IFERROR(INDEX((COPIA!$DA$3:$DE$1339),MATCH(ROWS(D$10:D409),COPIA!$DF$3:$DF$1339,0),COLUMN()-1),"")=0,"",IFERROR(INDEX((COPIA!$DA$3:$DE$1339),MATCH(ROWS(D$10:D409),COPIA!$DF$3:$DF$1339,0),COLUMN()-1),"")) | E409: =IF(IFERROR(INDEX((COPIA!$DA$3:$DE$1339),MATCH(ROWS(E$10:E409),COPIA!$DF$3:$DF$1339,0),COLUMN()-1),"")=0,"",IFERROR(INDEX((COPIA!$DA$3:$DE$1339),MATCH(ROWS(E$10:E409),COPIA!$DF$3:$DF$1339,0),COLUMN()-1),"")) | F409: =IF(IFERROR(INDEX((COPIA!$DA$3:$DE$1339),MATCH(ROWS(F$10:F409),COPIA!$DF$3:$DF$1339,0),COLUMN()-1),"")=0,"",IFERROR(INDEX((COPIA!$DA$3:$DE$1339),MATCH(ROWS(F$10:F409),COPIA!$DF$3:$DF$1339,0),COLUMN()-1),""))
B410: =IF(IFERROR(INDEX((COPIA!$DA$3:$DE$1339),MATCH(ROWS(B$10:B410),COPIA!$DF$3:$DF$1339,0),COLUMN()-1),"")>=1,IFERROR(INDEX((COPIA!$DA$3:$DE$1339),MATCH(ROWS(B$10:B410),COPIA!$DF$3:$DF$1339,0),COLUMN()-1),""),"") | C410: =SUBSTITUTE(IFERROR(INDEX((COPIA!$DA$3:$DE$1339),MATCH(ROWS(C$10:C410),COPIA!$DF$3:$DF$1339,0),COLUMN()-1),""),"MASTRO","") | D410: =IF(IFERROR(INDEX((COPIA!$DA$3:$DE$1339),MATCH(ROWS(D$10:D410),COPIA!$DF$3:$DF$1339,0),COLUMN()-1),"")=0,"",IFERROR(INDEX((COPIA!$DA$3:$DE$1339),MATCH(ROWS(D$10:D410),COPIA!$DF$3:$DF$1339,0),COLUMN()-1),"")) | E410: =IF(IFERROR(INDEX((COPIA!$DA$3:$DE$1339),MATCH(ROWS(E$10:E410),COPIA!$DF$3:$DF$1339,0),COLUMN()-1),"")=0,"",IFERROR(INDEX((COPIA!$DA$3:$DE$1339),MATCH(ROWS(E$10:E410),COPIA!$DF$3:$DF$1339,0),COLUMN()-1),"")) | F410: =IF(IFERROR(INDEX((COPIA!$DA$3:$DE$1339),MATCH(ROWS(F$10:F410),COPIA!$DF$3:$DF$1339,0),COLUMN()-1),"")=0,"",IFERROR(INDEX((COPIA!$DA$3:$DE$1339),MATCH(ROWS(F$10:F410),COPIA!$DF$3:$DF$1339,0),COLUMN()-1),""))
B411: =IF(IFERROR(INDEX((COPIA!$DA$3:$DE$1339),MATCH(ROWS(B$10:B411),COPIA!$DF$3:$DF$1339,0),COLUMN()-1),"")>=1,IFERROR(INDEX((COPIA!$DA$3:$DE$1339),MATCH(ROWS(B$10:B411),COPIA!$DF$3:$DF$1339,0),COLUMN()-1),""),"") | C411: =SUBSTITUTE(IFERROR(INDEX((COPIA!$DA$3:$DE$1339),MATCH(ROWS(C$10:C411),COPIA!$DF$3:$DF$1339,0),COLUMN()-1),""),"MASTRO","") | D411: =IF(IFERROR(INDEX((COPIA!$DA$3:$DE$1339),MATCH(ROWS(D$10:D411),COPIA!$DF$3:$DF$1339,0),COLUMN()-1),"")=0,"",IFERROR(INDEX((COPIA!$DA$3:$DE$1339),MATCH(ROWS(D$10:D411),COPIA!$DF$3:$DF$1339,0),COLUMN()-1),"")) | E411: =IF(IFERROR(INDEX((COPIA!$DA$3:$DE$1339),MATCH(ROWS(E$10:E411),COPIA!$DF$3:$DF$1339,0),COLUMN()-1),"")=0,"",IFERROR(INDEX((COPIA!$DA$3:$DE$1339),MATCH(ROWS(E$10:E411),COPIA!$DF$3:$DF$1339,0),COLUMN()-1),"")) | F411: =IF(IFERROR(INDEX((COPIA!$DA$3:$DE$1339),MATCH(ROWS(F$10:F411),COPIA!$DF$3:$DF$1339,0),COLUMN()-1),"")=0,"",IFERROR(INDEX((COPIA!$DA$3:$DE$1339),MATCH(ROWS(F$10:F411),COPIA!$DF$3:$DF$1339,0),COLUMN()-1),""))
B412: =IF(IFERROR(INDEX((COPIA!$DA$3:$DE$1339),MATCH(ROWS(B$10:B412),COPIA!$DF$3:$DF$1339,0),COLUMN()-1),"")>=1,IFERROR(INDEX((COPIA!$DA$3:$DE$1339),MATCH(ROWS(B$10:B412),COPIA!$DF$3:$DF$1339,0),COLUMN()-1),""),"") | C412: =SUBSTITUTE(IFERROR(INDEX((COPIA!$DA$3:$DE$1339),MATCH(ROWS(C$10:C412),COPIA!$DF$3:$DF$1339,0),COLUMN()-1),""),"MASTRO","") | D412: =IF(IFERROR(INDEX((COPIA!$DA$3:$DE$1339),MATCH(ROWS(D$10:D412),COPIA!$DF$3:$DF$1339,0),COLUMN()-1),"")=0,"",IFERROR(INDEX((COPIA!$DA$3:$DE$1339),MATCH(ROWS(D$10:D412),COPIA!$DF$3:$DF$1339,0),COLUMN()-1),"")) | E412: =IF(IFERROR(INDEX((COPIA!$DA$3:$DE$1339),MATCH(ROWS(E$10:E412),COPIA!$DF$3:$DF$1339,0),COLUMN()-1),"")=0,"",IFERROR(INDEX((COPIA!$DA$3:$DE$1339),MATCH(ROWS(E$10:E412),COPIA!$DF$3:$DF$1339,0),COLUMN()-1),"")) | F412: =IF(IFERROR(INDEX((COPIA!$DA$3:$DE$1339),MATCH(ROWS(F$10:F412),COPIA!$DF$3:$DF$1339,0),COLUMN()-1),"")=0,"",IFERROR(INDEX((COPIA!$DA$3:$DE$1339),MATCH(ROWS(F$10:F412),COPIA!$DF$3:$DF$1339,0),COLUMN()-1),""))
B413: =IF(IFERROR(INDEX((COPIA!$DA$3:$DE$1339),MATCH(ROWS(B$10:B413),COPIA!$DF$3:$DF$1339,0),COLUMN()-1),"")>=1,IFERROR(INDEX((COPIA!$DA$3:$DE$1339),MATCH(ROWS(B$10:B413),COPIA!$DF$3:$DF$1339,0),COLUMN()-1),""),"") | C413: =SUBSTITUTE(IFERROR(INDEX((COPIA!$DA$3:$DE$1339),MATCH(ROWS(C$10:C413),COPIA!$DF$3:$DF$1339,0),COLUMN()-1),""),"MASTRO","") | D413: =IF(IFERROR(INDEX((COPIA!$DA$3:$DE$1339),MATCH(ROWS(D$10:D413),COPIA!$DF$3:$DF$1339,0),COLUMN()-1),"")=0,"",IFERROR(INDEX((COPIA!$DA$3:$DE$1339),MATCH(ROWS(D$10:D413),COPIA!$DF$3:$DF$1339,0),COLUMN()-1),"")) | E413: =IF(IFERROR(INDEX((COPIA!$DA$3:$DE$1339),MATCH(ROWS(E$10:E413),COPIA!$DF$3:$DF$1339,0),COLUMN()-1),"")=0,"",IFERROR(INDEX((COPIA!$DA$3:$DE$1339),MATCH(ROWS(E$10:E413),COPIA!$DF$3:$DF$1339,0),COLUMN()-1),"")) | F413: =IF(IFERROR(INDEX((COPIA!$DA$3:$DE$1339),MATCH(ROWS(F$10:F413),COPIA!$DF$3:$DF$1339,0),COLUMN()-1),"")=0,"",IFERROR(INDEX((COPIA!$DA$3:$DE$1339),MATCH(ROWS(F$10:F413),COPIA!$DF$3:$DF$1339,0),COLUMN()-1),""))
B414: =IF(IFERROR(INDEX((COPIA!$DA$3:$DE$1339),MATCH(ROWS(B$10:B414),COPIA!$DF$3:$DF$1339,0),COLUMN()-1),"")>=1,IFERROR(INDEX((COPIA!$DA$3:$DE$1339),MATCH(ROWS(B$10:B414),COPIA!$DF$3:$DF$1339,0),COLUMN()-1),""),"") | C414: =SUBSTITUTE(IFERROR(INDEX((COPIA!$DA$3:$DE$1339),MATCH(ROWS(C$10:C414),COPIA!$DF$3:$DF$1339,0),COLUMN()-1),""),"MASTRO","") | D414: =IF(IFERROR(INDEX((COPIA!$DA$3:$DE$1339),MATCH(ROWS(D$10:D414),COPIA!$DF$3:$DF$1339,0),COLUMN()-1),"")=0,"",IFERROR(INDEX((COPIA!$DA$3:$DE$1339),MATCH(ROWS(D$10:D414),COPIA!$DF$3:$DF$1339,0),COLUMN()-1),"")) | E414: =IF(IFERROR(INDEX((COPIA!$DA$3:$DE$1339),MATCH(ROWS(E$10:E414),COPIA!$DF$3:$DF$1339,0),COLUMN()-1),"")=0,"",IFERROR(INDEX((COPIA!$DA$3:$DE$1339),MATCH(ROWS(E$10:E414),COPIA!$DF$3:$DF$1339,0),COLUMN()-1),"")) | F414: =IF(IFERROR(INDEX((COPIA!$DA$3:$DE$1339),MATCH(ROWS(F$10:F414),COPIA!$DF$3:$DF$1339,0),COLUMN()-1),"")=0,"",IFERROR(INDEX((COPIA!$DA$3:$DE$1339),MATCH(ROWS(F$10:F414),COPIA!$DF$3:$DF$1339,0),COLUMN()-1),""))
B415: =IF(IFERROR(INDEX((COPIA!$DA$3:$DE$1339),MATCH(ROWS(B$10:B415),COPIA!$DF$3:$DF$1339,0),COLUMN()-1),"")>=1,IFERROR(INDEX((COPIA!$DA$3:$DE$1339),MATCH(ROWS(B$10:B415),COPIA!$DF$3:$DF$1339,0),COLUMN()-1),""),"") | C415: =SUBSTITUTE(IFERROR(INDEX((COPIA!$DA$3:$DE$1339),MATCH(ROWS(C$10:C415),COPIA!$DF$3:$DF$1339,0),COLUMN()-1),""),"MASTRO","") | D415: =IF(IFERROR(INDEX((COPIA!$DA$3:$DE$1339),MATCH(ROWS(D$10:D415),COPIA!$DF$3:$DF$1339,0),COLUMN()-1),"")=0,"",IFERROR(INDEX((COPIA!$DA$3:$DE$1339),MATCH(ROWS(D$10:D415),COPIA!$DF$3:$DF$1339,0),COLUMN()-1),"")) | E415: =IF(IFERROR(INDEX((COPIA!$DA$3:$DE$1339),MATCH(ROWS(E$10:E415),COPIA!$DF$3:$DF$1339,0),COLUMN()-1),"")=0,"",IFERROR(INDEX((COPIA!$DA$3:$DE$1339),MATCH(ROWS(E$10:E415),COPIA!$DF$3:$DF$1339,0),COLUMN()-1),"")) | F415: =IF(IFERROR(INDEX((COPIA!$DA$3:$DE$1339),MATCH(ROWS(F$10:F415),COPIA!$DF$3:$DF$1339,0),COLUMN()-1),"")=0,"",IFERROR(INDEX((COPIA!$DA$3:$DE$1339),MATCH(ROWS(F$10:F415),COPIA!$DF$3:$DF$1339,0),COLUMN()-1),""))
B416: =IF(IFERROR(INDEX((COPIA!$DA$3:$DE$1339),MATCH(ROWS(B$10:B416),COPIA!$DF$3:$DF$1339,0),COLUMN()-1),"")>=1,IFERROR(INDEX((COPIA!$DA$3:$DE$1339),MATCH(ROWS(B$10:B416),COPIA!$DF$3:$DF$1339,0),COLUMN()-1),""),"") | C416: =SUBSTITUTE(IFERROR(INDEX((COPIA!$DA$3:$DE$1339),MATCH(ROWS(C$10:C416),COPIA!$DF$3:$DF$1339,0),COLUMN()-1),""),"MASTRO","") | D416: =IF(IFERROR(INDEX((COPIA!$DA$3:$DE$1339),MATCH(ROWS(D$10:D416),COPIA!$DF$3:$DF$1339,0),COLUMN()-1),"")=0,"",IFERROR(INDEX((COPIA!$DA$3:$DE$1339),MATCH(ROWS(D$10:D416),COPIA!$DF$3:$DF$1339,0),COLUMN()-1),"")) | E416: =IF(IFERROR(INDEX((COPIA!$DA$3:$DE$1339),MATCH(ROWS(E$10:E416),COPIA!$DF$3:$DF$1339,0),COLUMN()-1),"")=0,"",IFERROR(INDEX((COPIA!$DA$3:$DE$1339),MATCH(ROWS(E$10:E416),COPIA!$DF$3:$DF$1339,0),COLUMN()-1),"")) | F416: =IF(IFERROR(INDEX((COPIA!$DA$3:$DE$1339),MATCH(ROWS(F$10:F416),COPIA!$DF$3:$DF$1339,0),COLUMN()-1),"")=0,"",IFERROR(INDEX((COPIA!$DA$3:$DE$1339),MATCH(ROWS(F$10:F416),COPIA!$DF$3:$DF$1339,0),COLUMN()-1),""))
B417: =IF(IFERROR(INDEX((COPIA!$DA$3:$DE$1339),MATCH(ROWS(B$10:B417),COPIA!$DF$3:$DF$1339,0),COLUMN()-1),"")>=1,IFERROR(INDEX((COPIA!$DA$3:$DE$1339),MATCH(ROWS(B$10:B417),COPIA!$DF$3:$DF$1339,0),COLUMN()-1),""),"") | C417: =SUBSTITUTE(IFERROR(INDEX((COPIA!$DA$3:$DE$1339),MATCH(ROWS(C$10:C417),COPIA!$DF$3:$DF$1339,0),COLUMN()-1),""),"MASTRO","") | D417: =IF(IFERROR(INDEX((COPIA!$DA$3:$DE$1339),MATCH(ROWS(D$10:D417),COPIA!$DF$3:$DF$1339,0),COLUMN()-1),"")=0,"",IFERROR(INDEX((COPIA!$DA$3:$DE$1339),MATCH(ROWS(D$10:D417),COPIA!$DF$3:$DF$1339,0),COLUMN()-1),"")) | E417: =IF(IFERROR(INDEX((COPIA!$DA$3:$DE$1339),MATCH(ROWS(E$10:E417),COPIA!$DF$3:$DF$1339,0),COLUMN()-1),"")=0,"",IFERROR(INDEX((COPIA!$DA$3:$DE$1339),MATCH(ROWS(E$10:E417),COPIA!$DF$3:$DF$1339,0),COLUMN()-1),"")) | F417: =IF(IFERROR(INDEX((COPIA!$DA$3:$DE$1339),MATCH(ROWS(F$10:F417),COPIA!$DF$3:$DF$1339,0),COLUMN()-1),"")=0,"",IFERROR(INDEX((COPIA!$DA$3:$DE$1339),MATCH(ROWS(F$10:F417),COPIA!$DF$3:$DF$1339,0),COLUMN()-1),""))
B418: =IF(IFERROR(INDEX((COPIA!$DA$3:$DE$1339),MATCH(ROWS(B$10:B418),COPIA!$DF$3:$DF$1339,0),COLUMN()-1),"")>=1,IFERROR(INDEX((COPIA!$DA$3:$DE$1339),MATCH(ROWS(B$10:B418),COPIA!$DF$3:$DF$1339,0),COLUMN()-1),""),"") | C418: =SUBSTITUTE(IFERROR(INDEX((COPIA!$DA$3:$DE$1339),MATCH(ROWS(C$10:C418),COPIA!$DF$3:$DF$1339,0),COLUMN()-1),""),"MASTRO","") | D418: =IF(IFERROR(INDEX((COPIA!$DA$3:$DE$1339),MATCH(ROWS(D$10:D418),COPIA!$DF$3:$DF$1339,0),COLUMN()-1),"")=0,"",IFERROR(INDEX((COPIA!$DA$3:$DE$1339),MATCH(ROWS(D$10:D418),COPIA!$DF$3:$DF$1339,0),COLUMN()-1),"")) | E418: =IF(IFERROR(INDEX((COPIA!$DA$3:$DE$1339),MATCH(ROWS(E$10:E418),COPIA!$DF$3:$DF$1339,0),COLUMN()-1),"")=0,"",IFERROR(INDEX((COPIA!$DA$3:$DE$1339),MATCH(ROWS(E$10:E418),COPIA!$DF$3:$DF$1339,0),COLUMN()-1),"")) | F418: =IF(IFERROR(INDEX((COPIA!$DA$3:$DE$1339),MATCH(ROWS(F$10:F418),COPIA!$DF$3:$DF$1339,0),COLUMN()-1),"")=0,"",IFERROR(INDEX((COPIA!$DA$3:$DE$1339),MATCH(ROWS(F$10:F418),COPIA!$DF$3:$DF$1339,0),COLUMN()-1),""))
B419: =IF(IFERROR(INDEX((COPIA!$DA$3:$DE$1339),MATCH(ROWS(B$10:B419),COPIA!$DF$3:$DF$1339,0),COLUMN()-1),"")>=1,IFERROR(INDEX((COPIA!$DA$3:$DE$1339),MATCH(ROWS(B$10:B419),COPIA!$DF$3:$DF$1339,0),COLUMN()-1),""),"") | C419: =SUBSTITUTE(IFERROR(INDEX((COPIA!$DA$3:$DE$1339),MATCH(ROWS(C$10:C419),COPIA!$DF$3:$DF$1339,0),COLUMN()-1),""),"MASTRO","") | D419: =IF(IFERROR(INDEX((COPIA!$DA$3:$DE$1339),MATCH(ROWS(D$10:D419),COPIA!$DF$3:$DF$1339,0),COLUMN()-1),"")=0,"",IFERROR(INDEX((COPIA!$DA$3:$DE$1339),MATCH(ROWS(D$10:D419),COPIA!$DF$3:$DF$1339,0),COLUMN()-1),"")) | E419: =IF(IFERROR(INDEX((COPIA!$DA$3:$DE$1339),MATCH(ROWS(E$10:E419),COPIA!$DF$3:$DF$1339,0),COLUMN()-1),"")=0,"",IFERROR(INDEX((COPIA!$DA$3:$DE$1339),MATCH(ROWS(E$10:E419),COPIA!$DF$3:$DF$1339,0),COLUMN()-1),"")) | F419: =IF(IFERROR(INDEX((COPIA!$DA$3:$DE$1339),MATCH(ROWS(F$10:F419),COPIA!$DF$3:$DF$1339,0),COLUMN()-1),"")=0,"",IFERROR(INDEX((COPIA!$DA$3:$DE$1339),MATCH(ROWS(F$10:F419),COPIA!$DF$3:$DF$1339,0),COLUMN()-1),""))
